Workbook

Sheet HuongDan
A1: NGƯỠNG SME MAY FOB – UC01 (TRỤC W, 3 MỨC) VÀ UC02 (MILLER–ORR)
A2: Cách xây: chuẩn ngành FOB (20 DN may FOB, FiinTrade 2023–2025) → kiểm định biến điều tiết quy mô → áp cho từng DN; ngưỡng tiền UC02 theo Miller–Orr.
A4: KẾT QUẢ CHÍNH – NGƯỠNG CHO SME FOB (nhóm Nhỏ–vừa)
A5: Ngưỡng | B5: FOB nhỏ–vừa | C5: Đơn vị | D5: Mức UC01 / UC02
A6: Phải thu – tham chiếu (DSO, P50) | B6: =B3_NguongKhoanMuc!D4 -> 43.247052 | C6: ngày | D6: Trung vị ngành FOB
A7: Phải thu – CÓ NGUY CƠ (P75) | B7: =B3_NguongKhoanMuc!E4 -> 58.207139 | C7: ngày | D7: Vượt → Có nguy cơ
A8: Phải thu – TRẦM TRỌNG (P90) | B8: =B3_NguongKhoanMuc!F4 -> 66.263266 | C8: ngày | D8: Vượt → Thiếu trầm trọng
A9: Tồn kho – tham chiếu (DIO, P50) | B9: =B3_NguongKhoanMuc!G4 -> 69.751755 | C9: ngày | D9: Trung vị ngành FOB
A10: Tồn kho – CÓ NGUY CƠ (P75) | B10: =B3_NguongKhoanMuc!H4 -> 86.118055 | C10: ngày | D10: Vượt → Có nguy cơ
A11: Tồn kho – TRẦM TRỌNG (P90) | B11: =B3_NguongKhoanMuc!I4 -> 137.96515 | C11: ngày | D11: Vượt → Thiếu trầm trọng
A12: Phải trả – DPO THẤP (P10, kèm tiền mỏng) | B12: =B3_NguongKhoanMuc!L4 -> 14.892653 | C12: ngày | D12: Kèm tiền mỏng → Có nguy cơ
A13: Đệm tiền mỏng (P25) | B13: =B3_NguongKhoanMuc!M4 -> 0.083007995 | C13: % DT | D13: Điều kiện kèm R-AP-1
A14: Mức trọng yếu (vốn vượt ngưỡng / TSNH) | B14: =ThamSo!$C$9 -> 0.05 | C14: tỷ lệ | D14: Vượt → Thiếu trầm trọng
A15: UC02 – ℓ: L = ℓ × doanh thu năm | B15: =B6_MillerOrr!C17 -> 0.041798621 | C15: % DT | D15: Tiền < L → THIẾU
A16: UC02 – σ ngày dự phòng = tỷ lệ × doanh thu năm | B16: =B6_MillerOrr!C20 -> 0.0025058914 | C16: % DT / ngày | D16: Dùng khi DN < 90 ngày dữ liệu
A17: UC02 – ví dụ DT 300 tỷ: L / Z / H | B17: =TEXT(B6_MillerOrr!B30,"0.0")&" / "&TEXT(B6_MillerOrr!E30,"0.0")&" / "&TEXT(B6_MillerOrr!F30,"0.0") -> 12.5 / 14.0 / 17.0 | C17: tỷ đồng | D17: Tiền > H → THỪA
A18: Tỷ lệ khó khăn năm sau: W0 / W1 / W2 | B18: =TEXT(B5_KiemDinh!D5,"0%")&" / "&TEXT(B5_KiemDinh!D6,"0%")&" / "&TEXT(B5_KiemDinh!D7,"0%") -> 0% / 29% / 0% | D18: Kiểm định chiều hướng
A21: ĐỌC THEO THỨ TỰ
A22: MaTran_6O | B22: Ma trận 6 ô: W0 / W1 / W2 × Thiếu / Thừa; thứ tự ưu tiên giải pháp UC03 cho từng ô.
A23: ThamSo | B23: Mọi con số có thể chỉnh (phân vị, cửa sổ năm, mức trọng yếu, tham số Miller–Orr…), kèm cơ sở.
A24: HoSoDN | B24: 28 DN may, mô hình gia công / FOB, DN thuộc mẫu FOB, DN bị loại và lý do.
A25: DuLieu | B25: Số liệu FiinTrade 2023–2025 nguyên văn + cột tính toán; cột “– FOB” là mẫu tính ngưỡng.
A26: B1_ChuanNganh | B26: Bước 1: phân vị P10 / P25 / P50 / P75 / P90 của ngành FOB; đối chiếu số “Toàn ngành” FiinTrade.
A27: B2_BienDieuTiet | B27: Bước 2: hệ số quy mô, mùa vụ; chỉ áp dụng khi có ý nghĩa thống kê.
A28: B2a_KiemDinhMannWhitney | B28: Bước 2 (chi tiết): p-value bằng công thức Excel – xếp hạng, U, z, p.
A29: B3_NguongKhoanMuc | B29: Bước 3: ngưỡng từng khoản mục cho DN FOB; 7 quy tắc có mã.
A30: B4_PhanLopW | B30: Bước 4: áp cho từng năm–DN FOB → W0 An toàn / W1 Có nguy cơ / W2 Thiếu trầm trọng.
A31: B5_KiemDinh | B31: Bước 5: ba mức có phân biệt DN gặp khó năm sau không; độ nhạy.
A32: B6_MillerOrr | B32: Bước 6: ngưỡng tiền UC02 – L, Z, H theo Miller–Orr.
A33: TongHop2025 | B33: Ảnh chụp năm 2025: mức UC01, L / Z / H, trạng thái tiền, ô ma trận, ưu tiên giải pháp.
... A36: Nguong_SRS | B36: Khóa cấu hình đưa vào SRS.
A38: QUY ƯỚC MÀU
A39: Chữ xanh dương | B39: Số liệu nhập hoặc lựa chọn nhập tay.
A40: Chữ đen | B40: Công thức.
A41: Chữ xanh lá | B41: Liên kết sang sheet khác.
A42: Nền vàng | B42: Tham số được phép chỉnh.
A43: Nền xanh nhạt | B43: Ngưỡng / kết quả.
A45: GIỚI HẠN
A46: Mẫu | B46: DN may FOB đại chúng (20 DN, 60 năm–DN); rất ít năm–DN đạt chuẩn SME theo NĐ80; quy mô được kiểm định và không khác biệt có ý nghĩa.
A47: Cửa sổ 3 năm | B47: Ít quan sát hơn: P90 dựa trên ~6 năm–DN cao nhất; kiểm định biến cố chỉ có 40 năm–DN (2023, 2024).
...

Sheet MaTran_6O
A1: MA TRẬN 6 TRƯỜNG HỢP: 3 mức UC01 (trục W) × 2 trạng thái tiền UC02 (Miller–Orr)
A2: UC01 xác định HÀNG (W0 An toàn / W1 Có nguy cơ / W2 Thiếu trầm trọng). UC02 xác định CỘT: Tiền < L → Thiếu; Tiền > H → Thừa. Ô M1–M6 = 2 × chỉ số W + chỉ số tiền + 1.
A4: Hàng W | B4: Mức UC01 | C4: Điều kiện (tất định, có mã quy tắc) | D4: UC01 bàn giao cho UC02 | E4: Cột THIẾU (Tiền < L) | F4: Cột THỪA (Tiền > H) | G4: Số năm–DN FOB trong dữ liệu | H4: Tỷ lệ khó khăn năm sau
A5: W0 | B5: An toàn | C5: DSO ≤ ngưỡng có nguy cơ, DIO ≤ ngưỡng có nguy cơ, không có “DPO thấp + tiền mỏng”. | D5: Không có finding vượt ngưỡng; vẫn giao DSO, DIO, DPO và ngưỡng để UC02 dùng. | E5: M1 – Thiếu, vốn lưu động an toàn | F5: M2 – Thừa, vốn lưu động an toàn | G5: =COUNTIF(B4_PhanLopW!$AD$5:$AD$64,A5) -> 32 | H5: =IF("",IFERROR(INDEX(B5_KiemDinh!$D$5:$D$7,MATCH(A5,B5_KiemDinh!$A$5:$A$7,0)),"")) -> 0
A6: W1 | B6: Có nguy cơ | C6: Có ít nhất 1 tín hiệu R-AR-1, R-INV-1 hoặc R-AP-1, nhưng không có tín hiệu trầm trọng và vốn vượt ngưỡng < m. | D6: Finding theo khoản mục: số ngày, ngưỡng, mức “Có nguy cơ”, vốn vượt ngưỡng (đồng), mã quy tắc. | E6: M3 – Thiếu, có nguy cơ | F6: M4 – Thừa, có nguy cơ | G6: =COUNTIF(B4_PhanLopW!$AD$5:$AD$64,A6) -> 9 | H6: =IF("",IFERROR(INDEX(B5_KiemDinh!$D$5:$D$7,MATCH(A6,B5_KiemDinh!$A$5:$A$7,0)),"")) -> 0.28571429
A7: W2 | B7: Thiếu trầm trọng | C7: Có R-AR-2 hoặc R-INV-2; HOẶC có tín hiệu có nguy cơ và vốn vượt ngưỡng / TSNH ≥ mức trọng yếu (R-MAT). | D7: Finding trọng yếu: khoản mục là điểm nghẽn chính, money_at_risk (đồng), tỷ lệ / TSNH, mã quy tắc. | E7: M5 – Thiếu, nghẽn trầm trọng | F7: M6 – Thừa, nghẽn trầm trọng | G7: =COUNTIF(B4_PhanLopW!$AD$5:$AD$64,A7) -> 19 | H7: =IF("",IFERROR(INDEX(B5_KiemDinh!$D$5:$D$7,MATCH(A7,B5_KiemDinh!$A$5:$A$7,0)),"")) -> 0
G8: 0
A10: Tiền nằm giữa L và H: trong vùng kiểm soát, không gán cột THIẾU / THỪA và không đề xuất hành động (theo dõi tiếp).
A12: THỨ TỰ ƯU TIÊN GIẢI PHÁP CHO UC03 THEO TỪNG Ô
A13: Ô | B13: Mức UC01 | C13: Tiền UC02 | D13: Thứ tự ưu tiên nguồn / cách dùng tiền | E13: Lý do
A14: M1 | B14: An toàn | C14: Thiếu | D14: 1. Vay ngắn hạn (short-term financing) | E14: Vốn lưu động lành mạnh, thiếu là tạm thời; vay ngắn hạn nhanh, chi phí thấp, không ảnh hưởng quan hệ khách hàng và NCC.
A15: M2 | B15: An toàn | C15: Thừa | D15: 1. Đầu tư ngắn hạn phần (Tiền − Z) | E15: Thừa ít và không có điểm nghẽn: tiền nhàn rỗi nên sinh lời; giữ lại tối thiểu Z.
A16: M3 | B16: Có nguy cơ | C16: Thiếu | D16: 1. Thu hồi phải thu (AR) → 2. Giãn trả NCC (AP) | E16: Xử lý đúng điểm đang giữ vốn trước khi đi vay.
A17: M4 | B17: Có nguy cơ | C17: Thừa | D17: 1. Giữ làm dự trữ | E17: Có dấu hiệu nghẽn: tiền dư là đệm cho rủi ro, chưa nên đầu tư.
A18: M5 | B18: Thiếu trầm trọng | C18: Thiếu | D18: 1. AR → 2. Hàng tồn kho → 3. AP → 4. Vay (chỉ khi 3 nguồn trên chưa đủ) | E18: Vốn bị giữ trọng yếu, đi vay khó: giải phóng vốn nội bộ trước.
A19: M6 | B19: Thiếu trầm trọng | C19: Thừa | D19: 1. Giữ làm dự trữ | E19: Tồn đọng nhiều tiền nhưng vốn lưu động nghẽn trầm trọng: giữ dự trữ, xử lý điểm nghẽn.
A21: Ví dụ cách đọc: một SME FOB có DSO 70 ngày (> ngưỡng trầm trọng 66,3) → R-AR-2 → W2. Nếu UC02 dự báo tiền xuống dưới L → ô M5: ưu tiên thu hồi phải thu, rồi giảm tồn kho, rồi giãn trả NCC, cuối cùng mới vay.

Sheet ThamSo
A1: THAM SỐ (ô vàng, chữ xanh: được phép chỉnh – toàn bộ file tự tính lại)
A3: Mã | B3: Tham số | C3: Giá trị | D3: Đơn vị | E3: Cơ sở
A4: P1 | B4: Phân vị mức THAM CHIẾU (bình thường) | C4: 0.5 | D4: phân vị | E4: Trung vị ngành FOB: một nửa năm–DN FOB có số ngày thấp hơn.
A5: P2 | B5: Phân vị ngưỡng CÓ NGUY CƠ (theo dõi) | C5: 0.75 | D5: phân vị | E5: Cao hơn 75% năm–DN FOB → UC01 mức “Có nguy cơ”.
A6: P3 | B6: Phân vị ngưỡng TRẦM TRỌNG | C6: 0.9 | D6: phân vị | E6: Thập phân vị cao nhất ngành FOB → UC01 mức “Thiếu trầm trọng”.
A7: P4 | B7: Phân vị DPO THẤP (NCC gần như không cho nợ) | C7: 0.1 | D7: phân vị | E7: Chỉ là tín hiệu khi đi kèm tiền mỏng (P5) – quy tắc có điều kiện.
A8: P5 | B8: Phân vị ĐỆM TIỀN mỏng ((Tiền + ĐTNH) / Doanh thu) | C8: 0.25 | D8: phân vị | E8: Đệm tiền thấp hơn 75% năm–DN FOB.
A9: P6 | B9: Mức TRỌNG YẾU: vốn vượt ngưỡng có nguy cơ / Tài sản ngắn hạn | C9: 0.05 | D9: tỷ lệ | E9: Chính sách chủ DN duyệt (materiality_share). Độ nhạy ở B5_KiemDinh.
A10: P7 | B10: Vượt ngưỡng TRẦM TRỌNG thì xếp W2 dù chưa đạt trọng yếu (1 = có) | C10: 1 | D10: cờ | E10: Một khoản ở thập phân vị cao nhất ngành đã là điểm nghẽn.
A11: P8 | B11: Doanh thu tối thiểu để coi là đang hoạt động | C11: 50000000000 | D11: đồng | E11: Loại năm gần như ngừng hoạt động (G20, MPT, GMC, VTI trong 2023–2025): số ngày khi đó vô nghĩa.
A12: P9 | B12: Ranh giới nhóm quy mô Nhỏ–vừa / Lớn (doanh thu) | C12: 1500000000000 | D12: đồng | E12: Chia nhóm để kiểm định biến điều tiết quy mô.
A13: P10 | B13: SME theo NĐ 80/2021: doanh thu tối đa (công nghiệp) | C13: 200000000000 | D13: đồng | E13: Nghị định 80/2021/NĐ-CP, Điều 5.
A14: P11 | B14: SME theo NĐ 80/2021: tổng nguồn vốn tối đa | C14: 100000000000 | D14: đồng | E14: Như trên (chưa kiểm được tiêu chí lao động – FiinTrade không có).
A15: P12 | B15: DIO trung vị dưới mức này → mô hình GIA CÔNG (CMT), loại khỏi mẫu FOB | C15: 20 | D15: ngày | E15: Gia công dùng nguyên liệu của khách nên gần như không có tồn kho: PTG 4, THM 5, DCG 9 ngày (2023–2025); DN FOB tiếp theo ≥ 23 ngày.
... A29: P26 | B29: Miller–Orr: số ngày dữ liệu tối thiểu để dùng σ riêng của DN | C29: 90 | D29: ngày | E29: Đủ ≥ 90 ngày dòng tiền ròng (trong 3 năm gần nhất) thì dùng σ ngày của chính DN; thiếu thì dùng σ ngành × doanh thu.

Sheet HoSoDN
A1: HỒ SƠ DOANH NGHIỆP, MÔ HÌNH KINH DOANH VÀ MẪU FOB
A2: Mô hình xếp theo DIO trung vị các năm hoạt động 2023–2025 (< P12 = 20 ngày → gia công CMT). Mẫu tính ngưỡng chỉ gồm DN FOB đang hoạt động, không bị loại.
A4: Mã | B4: Tên doanh nghiệp | C4: Nhóm thu thập | D4: Doanh thu trung vị (tỷ đồng) | E4: Tổng nguồn vốn trung vị (tỷ đồng) | F4: Số năm đạt chuẩn SME (NĐ80) | G4: DIO trung vị (ngày) | H4: Mô hình | I4: DN bị loại? | J4: Lý do loại | K4: Số năm trong mẫu FOB | L4: Nhóm quy mô chủ đạo (nhiều năm hơn; hòa → Nhỏ–vừa) | M4: DSO trung vị | N4: DIO trung vị (mẫu) | O4: DPO trung vị | P4: Đệm tiền trung vị | Q4: Thuộc mẫu FOB?
A5: AG1 | B5: CTCP 28.1 | C5: Nhóm 1 – nhỏ | D5: =IFERROR(MEDIAN(DuLieu!D5:D7)/1000000000,"") -> 337.51237 | E5: =IFERROR(MEDIAN(DuLieu!F5:F7)/1000000000,"") -> 151.53955 | F5: =COUNTIF(DuLieu!W5:W7,"Có") -> 0 | G5: =IFERROR(MEDIAN(DuLieu!X5:X7),"") -> 105.53788 | H5: =IF(I5="Có","Loại",IF(G5="","Chưa rõ",IF(G5<ThamSo!$C$15,"CMT","FOB"))) -> FOB | I5: Không | K5: =SUM(DuLieu!U5:U7) -> 3 | L5: =IF(K5=0,"",IF(COUNTIFS(DuLieu!U5:U7,1,DuLieu!V5:V7,"Nhỏ–vừa")>=COUNTIFS(DuLieu!U5:U7,1,DuLieu!V5:V7,"Lớn"),"Nhỏ–vừa","Lớn")) -> Nhỏ–vừa | M5: =IFERROR(MEDIAN(DuLieu!AB5:AB7),"") -> 25.857809 | N5: =IFERROR(MEDIAN(DuLieu!AE5:AE7),"") -> 105.53788 | O5: =IFERROR(MEDIAN(DuLieu!AH5:AH7),"") -> 84.012707 | P5: =IFERROR(MEDIAN(DuLieu!Y5:Y7),"") -> 0.04477945 | Q5: =IF(AND(H5="FOB",K5>0),"Có","Không") -> Có
A6: BDG | B6: May mặc Bình Dương | C6: Nhóm 2 – lớn | D6: =IFERROR(MEDIAN(DuLieu!D8:D10)/1000000000,"") -> 1765.7867 | E6: =IFERROR(MEDIAN(DuLieu!F8:F10)/1000000000,"") -> 1132.6229 | F6: =COUNTIF(DuLieu!W8:W10,"Có") -> 0 | G6: =IFERROR(MEDIAN(DuLieu!X8:X10),"") -> 59.720353 | H6: =IF(I6="Có","Loại",IF(G6="","Chưa rõ",IF(G6<ThamSo!$C$15,"CMT","FOB"))) -> FOB | I6: Không | K6: =SUM(DuLieu!U8:U10) -> 3 | L6: =IF(K6=0,"",IF(COUNTIFS(DuLieu!U8:U10,1,DuLieu!V8:V10,"Nhỏ–vừa")>=COUNTIFS(DuLieu!U8:U10,1,DuLieu!V8:V10,"Lớn"),"Nhỏ–vừa","Lớn")) -> Lớn | M6: =IFERROR(MEDIAN(DuLieu!AB8:AB10),"") -> 47.799581 | N6: =IFERROR(MEDIAN(DuLieu!AE8:AE10),"") -> 59.720353 | O6: =IFERROR(MEDIAN(DuLieu!AH8:AH10),"") -> 32.642841 | P6: =IFERROR(MEDIAN(DuLieu!Y8:Y10),"") -> 0.15094065 | Q6: =IF(AND(H6="FOB",K6>0),"Có","Không") -> Có
A7: BMG | B7: May Bình Minh | C7: Nhóm 1 – nhỏ | D7: =IFERROR(MEDIAN(DuLieu!D11:D13)/1000000000,"") -> 295.7249 | E7: =IFERROR(MEDIAN(DuLieu!F11:F13)/1000000000,"") -> 178.46685 | F7: =COUNTIF(DuLieu!W11:W13,"Có") -> 0 | G7: =IFERROR(MEDIAN(DuLieu!X11:X13),"") -> 64.140082 | H7: =IF(I7="Có","Loại",IF(G7="","Chưa rõ",IF(G7<ThamSo!$C$15,"CMT","FOB"))) -> FOB | I7: Không | K7: =SUM(DuLieu!U11:U13) -> 3 | L7: =IF(K7=0,"",IF(COUNTIFS(DuLieu!U11:U13,1,DuLieu!V11:V13,"Nhỏ–vừa")>=COUNTIFS(DuLieu!U11:U13,1,DuLieu!V11:V13,"Lớn"),"Nhỏ–vừa","Lớn")) -> Nhỏ–vừa | M7: =IFERROR(MEDIAN(DuLieu!AB11:AB13),"") -> 31.714545 | N7: =IFERROR(MEDIAN(DuLieu!AE11:AE13),"") -> 64.140082 | O7: =IFERROR(MEDIAN(DuLieu!AH11:AH13),"") -> 34.06861 | P7: =IFERROR(MEDIAN(DuLieu!Y11:Y13),"") -> 0.11842199 | Q7: =IF(AND(H7="FOB",K7>0),"Có","Không") -> Có
A8: DCG | B8: May Đáp Cầu | C8: Nhóm 1 – nhỏ | D8: =IFERROR(MEDIAN(DuLieu!D14:D16)/1000000000,"") -> 554.87991 | E8: =IFERROR(MEDIAN(DuLieu!F14:F16)/1000000000,"") -> 421.38798 | F8: =COUNTIF(DuLieu!W14:W16,"Có") -> 0 | G8: =IFERROR(MEDIAN(DuLieu!X14:X16),"") -> 9.2933175 | H8: =IF(I8="Có","Loại",IF(G8="","Chưa rõ",IF(G8<ThamSo!$C$15,"CMT","FOB"))) -> CMT | I8: Không | K8: =SUM(DuLieu!U14:U16) -> 0 | L8: =IF(K8=0,"",IF(COUNTIFS(DuLieu!U14:U16,1,DuLieu!V14:V16,"Nhỏ–vừa")>=COUNTIFS(DuLieu!U14:U16,1,DuLieu!V14:V16,"Lớn"),"Nhỏ–vừa","Lớn")) | M8: =IFERROR(MEDIAN(DuLieu!AB14:AB16),"") | N8: =IFERROR(MEDIAN(DuLieu!AE14:AE16),"") | O8: =IFERROR(MEDIAN(DuLieu!AH14:AH16),"") | P8: =IFERROR(MEDIAN(DuLieu!Y14:Y16),"") | Q8: =IF(AND(H8="FOB",K8>0),"Có","Không") -> Không
A9: DM7 | B9: Dệt may 7 | C9: Nhóm 1 – nhỏ | D9: =IFERROR(MEDIAN(DuLieu!D17:D19)/1000000000,"") -> 741.07097 | E9: =IFERROR(MEDIAN(DuLieu!F17:F19)/1000000000,"") -> 540.04457 | F9: =COUNTIF(DuLieu!W17:W19,"Có") -> 0 | G9: =IFERROR(MEDIAN(DuLieu!X17:X19),"") -> 55.712532 | H9: =IF(I9="Có","Loại",IF(G9="","Chưa rõ",IF(G9<ThamSo!$C$15,"CMT","FOB"))) -> FOB | I9: Không | K9: =SUM(DuLieu!U17:U19) -> 3 | L9: =IF(K9=0,"",IF(COUNTIFS(DuLieu!U17:U19,1,DuLieu!V17:V19,"Nhỏ–vừa")>=COUNTIFS(DuLieu!U17:U19,1,DuLieu!V17:V19,"Lớn"),"Nhỏ–vừa","Lớn")) -> Nhỏ–vừa | M9: =IFERROR(MEDIAN(DuLieu!AB17:AB19),"") -> 83.307468 | N9: =IFERROR(MEDIAN(DuLieu!AE17:AE19),"") -> 55.712532 | O9: =IFERROR(MEDIAN(DuLieu!AH17:AH19),"") -> 46.200039 | P9: =IFERROR(MEDIAN(DuLieu!Y17:Y19),"") -> 0.07036637 | Q9: =IF(AND(H9="FOB",K9>0),"Có","Không") -> Có
A10: G20 | B10: Đầu tư Dệt may Vĩnh Phúc | C10: Nhóm 1 – nhỏ | D10: =IFERROR(MEDIAN(DuLieu!D20:D22)/1000000000,"") -> 0 | E10: =IFERROR(MEDIAN(DuLieu!F20:F22)/1000000000,"") -> 94.998554 | F10: =COUNTIF(DuLieu!W20:W22,"Có") -> 1 | G10: =IFERROR(MEDIAN(DuLieu!X20:X22),"") | H10: =IF(I10="Có","Loại",IF(G10="","Chưa rõ",IF(G10<ThamSo!$C$15,"CMT","FOB"))) -> Chưa rõ | I10: Không | K10: =SUM(DuLieu!U20:U22) -> 0 | L10: =IF(K10=0,"",IF(COUNTIFS(DuLieu!U20:U22,1,DuLieu!V20:V22,"Nhỏ–vừa")>=COUNTIFS(DuLieu!U20:U22,1,DuLieu!V20:V22,"Lớn"),"Nhỏ–vừa","Lớn")) | M10: =IFERROR(MEDIAN(DuLieu!AB20:AB22),"") | N10: =IFERROR(MEDIAN(DuLieu!AE20:AE22),"") | O10: =IFERROR(MEDIAN(DuLieu!AH20:AH22),"") | P10: =IFERROR(MEDIAN(DuLieu!Y20:Y22),"") | Q10: =IF(AND(H10="FOB",K10>0),"Có","Không") -> Không
A11: GIL | B11: SXKD XNK Bình Thạnh | C11: Nhóm 2 – lớn | D11: =IFERROR(MEDIAN(DuLieu!D23:D25)/1000000000,"") -> 713.62099 | E11: =IFERROR(MEDIAN(DuLieu!F23:F25)/1000000000,"") -> 3357.159 | F11: =COUNTIF(DuLieu!W23:W25,"Có") -> 0 | G11: =IFERROR(MEDIAN(DuLieu!X23:X25),"") | H11: =IF(I11="Có","Loại",IF(G11="","Chưa rõ",IF(G11<ThamSo!$C$15,"CMT","FOB"))) -> Loại | I11: Có | J11: DIO 546–1.180 ngày trong 2023–2025 (2020–2021: 68–75 ngày): tồn kho không phản ánh hoạt động may FOB; giữ trong DuLieu để đối chiếu. | K11: =SUM(DuLieu!U23:U25) -> 0 | L11: =IF(K11=0,"",IF(COUNTIFS(DuLieu!U23:U25,1,DuLieu!V23:V25,"Nhỏ–vừa")>=COUNTIFS(DuLieu!U23:U25,1,DuLieu!V23:V25,"Lớn"),"Nhỏ–vừa","Lớn")) | M11: =IFERROR(MEDIAN(DuLieu!AB23:AB25),"") | N11: =IFERROR(MEDIAN(DuLieu!AE23:AE25),"") | O11: =IFERROR(MEDIAN(DuLieu!AH23:AH25),"") | P11: =IFERROR(MEDIAN(DuLieu!Y23:Y25),"") | Q11: =IF(AND(H11="FOB",K11>0),"Có","Không") -> Không
A12: GMC | B12: Garmex Sài Gòn | C12: Nhóm 1 – nhỏ | D12: =IFERROR(MEDIAN(DuLieu!D26:D28)/1000000000,"") -> 2.1279437 | E12: =IFERROR(MEDIAN(DuLieu!F26:F28)/1000000000,"") -> 375.94725 | F12: =COUNTIF(DuLieu!W26:W28,"Có") -> 3 | G12: =IFERROR(MEDIAN(DuLieu!X26:X28),"") | H12: =IF(I12="Có","Loại",IF(G12="","Chưa rõ",IF(G12<ThamSo!$C$15,"CMT","FOB"))) -> Chưa rõ | I12: Không | K12: =SUM(DuLieu!U26:U28) -> 0 | L12: =IF(K12=0,"",IF(COUNTIFS(DuLieu!U26:U28,1,DuLieu!V26:V28,"Nhỏ–vừa")>=COUNTIFS(DuLieu!U26:U28,1,DuLieu!V26:V28,"Lớn"),"Nhỏ–vừa","Lớn")) | M12: =IFERROR(MEDIAN(DuLieu!AB26:AB28),"") | N12: =IFERROR(MEDIAN(DuLieu!AE26:AE28),"") | O12: =IFERROR(MEDIAN(DuLieu!AH26:AH28),"") | P12: =IFERROR(MEDIAN(DuLieu!Y26:Y28),"") | Q12: =IF(AND(H12="FOB",K12>0),"Có","Không") -> Không
A13: HLT | B13: Dệt may Hoàng Thị Loan | C13: Nhóm 1 – nhỏ | D13: =IFERROR(MEDIAN(DuLieu!D29:D31)/1000000000,"") -> 780.8241 | E13: =IFERROR(MEDIAN(DuLieu!F29:F31)/1000000000,"") -> 288.50867 | F13: =COUNTIF(DuLieu!W29:W31,"Có") -> 0 | G13: =IFERROR(MEDIAN(DuLieu!X29:X31),"") -> 87.245942 | H13: =IF(I13="Có","Loại",IF(G13="","Chưa rõ",IF(G13<ThamSo!$C$15,"CMT","FOB"))) -> FOB | I13: Không | K13: =SUM(DuLieu!U29:U31) -> 3 | L13: =IF(K13=0,"",IF(COUNTIFS(DuLieu!U29:U31,1,DuLieu!V29:V31,"Nhỏ–vừa")>=COUNTIFS(DuLieu!U29:U31,1,DuLieu!V29:V31,"Lớn"),"Nhỏ–vừa","Lớn")) -> Nhỏ–vừa | M13: =IFERROR(MEDIAN(DuLieu!AB29:AB31),"") -> 21.528217 | N13: =IFERROR(MEDIAN(DuLieu!AE29:AE31),"") -> 87.245942 | O13: =IFERROR(MEDIAN(DuLieu!AH29:AH31),"") -> 8.1371547 | P13: =IFERROR(MEDIAN(DuLieu!Y29:Y31),"") -> 0.094380675 | Q13: =IF(AND(H13="FOB",K13>0),"Có","Không") -> Có
A14: HNI | B14: May Hữu Nghị | C14: Nhóm 1 – nhỏ | D14: =IFERROR(MEDIAN(DuLieu!D32:D34)/1000000000,"") -> 980.29229 | E14: =IFERROR(MEDIAN(DuLieu!F32:F34)/1000000000,"") -> 758.72573 | F14: =COUNTIF(DuLieu!W32:W34,"Có") -> 0 | G14: =IFERROR(MEDIAN(DuLieu!X32:X34),"") -> 26.977831 | H14: =IF(I14="Có","Loại",IF(G14="","Chưa rõ",IF(G14<ThamSo!$C$15,"CMT","FOB"))) -> FOB | I14: Không | K14: =SUM(DuLieu!U32:U34) -> 3 | L14: =IF(K14=0,"",IF(COUNTIFS(DuLieu!U32:U34,1,DuLieu!V32:V34,"Nhỏ–vừa")>=COUNTIFS(DuLieu!U32:U34,1,DuLieu!V32:V34,"Lớn"),"Nhỏ–vừa","Lớn")) -> Nhỏ–vừa | M14: =IFERROR(MEDIAN(DuLieu!AB32:AB34),"") -> 41.237603 | N14: =IFERROR(MEDIAN(DuLieu!AE32:AE34),"") -> 26.977831 | O14: =IFERROR(MEDIAN(DuLieu!AH32:AH34),"") -> 12.94332 | P14: =IFERROR(MEDIAN(DuLieu!Y32:Y34),"") -> 0.29666826 | Q14: =IF(AND(H14="FOB",K14>0),"Có","Không") -> Có
A15: HTG | B15: Dệt may Hòa Thọ | C15: Nhóm 2 – lớn | D15: =IFERROR(MEDIAN(DuLieu!D35:D37)/1000000000,"") -> 5111.1533 | E15: =IFERROR(MEDIAN(DuLieu!F35:F37)/1000000000,"") -> 2922.2156 | F15: =COUNTIF(DuLieu!W35:W37,"Có") -> 0 | G15: =IFERROR(MEDIAN(DuLieu!X35:X37),"") -> 64.557923 | H15: =IF(I15="Có","Loại",IF(G15="","Chưa rõ",IF(G15<ThamSo!$C$15,"CMT","FOB"))) -> FOB | I15: Không | K15: =SUM(DuLieu!U35:U37) -> 3 | L15: =IF(K15=0,"",IF(COUNTIFS(DuLieu!U35:U37,1,DuLieu!V35:V37,"Nhỏ–vừa")>=COUNTIFS(DuLieu!U35:U37,1,DuLieu!V35:V37,"Lớn"),"Nhỏ–vừa","Lớn")) -> Lớn | M15: =IFERROR(MEDIAN(DuLieu!AB35:AB37),"") -> 38.70394 | N15: =IFERROR(MEDIAN(DuLieu!AE35:AE37),"") -> 64.557923 | O15: =IFERROR(MEDIAN(DuLieu!AH35:AH37),"") -> 20.486733 | P15: =IFERROR(MEDIAN(DuLieu!Y35:Y37),"") -> 0.14111784 | Q15: =IF(AND(H15="FOB",K15>0),"Có","Không") -> Có
A16: HUG | B16: May Hưng Yên | C16: Nhóm 2 – lớn | D16: =IFERROR(MEDIAN(DuLieu!D38:D40)/1000000000,"") -> 690.5257 | E16: =IFERROR(MEDIAN(DuLieu!F38:F40)/1000000000,"") -> 607.90763 | F16: =COUNTIF(DuLieu!W38:W40,"Có") -> 0 | G16: =IFERROR(MEDIAN(DuLieu!X38:X40),"") -> 38.479621 | H16: =IF(I16="Có","Loại",IF(G16="","Chưa rõ",IF(G16<ThamSo!$C$15,"CMT","FOB"))) -> FOB | I16: Không | K16: =SUM(DuLieu!U38:U40) -> 3 | L16: =IF(K16=0,"",IF(COUNTIFS(DuLieu!U38:U40,1,DuLieu!V38:V40,"Nhỏ–vừa")>=COUNTIFS(DuLieu!U38:U40,1,DuLieu!V38:V40,"Lớn"),"Nhỏ–vừa","Lớn")) -> Nhỏ–vừa | M16: =IFERROR(MEDIAN(DuLieu!AB38:AB40),"") -> 33.706796 | N16: =IFERROR(MEDIAN(DuLieu!AE38:AE40),"") -> 38.479621 | O16: =IFERROR(MEDIAN(DuLieu!AH38:AH40),"") -> 18.735776 | P16: =IFERROR(MEDIAN(DuLieu!Y38:Y40),"") -> 0.337957 | Q16: =IF(AND(H16="FOB",K16>0),"Có","Không") -> Có
A17: M10 | B17: Tổng Công ty May 10 | C17: Nhóm 2 – lớn | D17: =IFERROR(MEDIAN(DuLieu!D41:D43)/1000000000,"") -> 4660.1994 | E17: =IFERROR(MEDIAN(DuLieu!F41:F43)/1000000000,"") -> 2615.8332 | F17: =COUNTIF(DuLieu!W41:W43,"Có") -> 0 | G17: =IFERROR(MEDIAN(DuLieu!X41:X43),"") -> 69.538398 | H17: =IF(I17="Có","Loại",IF(G17="","Chưa rõ",IF(G17<ThamSo!$C$15,"CMT","FOB"))) -> FOB | I17: Không | K17: =SUM(DuLieu!U41:U43) -> 3 | L17: =IF(K17=0,"",IF(COUNTIFS(DuLieu!U41:U43,1,DuLieu!V41:V43,"Nhỏ–vừa")>=COUNTIFS(DuLieu!U41:U43,1,DuLieu!V41:V43,"Lớn"),"Nhỏ–vừa","Lớn")) -> Lớn | M17: =IFERROR(MEDIAN(DuLieu!AB41:AB43),"") -> 43.565853 | N17: =IFERROR(MEDIAN(DuLieu!AE41:AE43),"") -> 69.538398 | O17: =IFERROR(MEDIAN(DuLieu!AH41:AH43),"") -> 61.424684 | P17: =IFERROR(MEDIAN(DuLieu!Y41:Y43),"") -> 0.10972324 | Q17: =IF(AND(H17="FOB",K17>0),"Có","Không") -> Có
A18: MGG | B18: May Đức Giang | C18: Nhóm 2 – lớn | D18: =IFERROR(MEDIAN(DuLieu!D44:D46)/1000000000,"") -> 1660.7887 | E18: =IFERROR(MEDIAN(DuLieu!F44:F46)/1000000000,"") -> 921.92385 | F18: =COUNTIF(DuLieu!W44:W46,"Có") -> 0 | G18: =IFERROR(MEDIAN(DuLieu!X44:X46),"") -> 23.284912 | H18: =IF(I18="Có","Loại",IF(G18="","Chưa rõ",IF(G18<ThamSo!$C$15,"CMT","FOB"))) -> FOB | I18: Không | K18: =SUM(DuLieu!U44:U46) -> 3 | L18: =IF(K18=0,"",IF(COUNTIFS(DuLieu!U44:U46,1,DuLieu!V44:V46,"Nhỏ–vừa")>=COUNTIFS(DuLieu!U44:U46,1,DuLieu!V44:V46,"Lớn"),"Nhỏ–vừa","Lớn")) -> Lớn | M18: =IFERROR(MEDIAN(DuLieu!AB44:AB46),"") -> 54.737569 | N18: =IFERROR(MEDIAN(DuLieu!AE44:AE46),"") -> 23.284912 | O18: =IFERROR(MEDIAN(DuLieu!AH44:AH46),"") -> 100.84166 | P18: =IFERROR(MEDIAN(DuLieu!Y44:Y46),"") -> 0.16247451 | Q18: =IF(AND(H18="FOB",K18>0),"Có","Không") -> Có
A19: MNB | B19: May Nhà Bè | C19: Nhóm 2 – lớn | D19: =IFERROR(MEDIAN(DuLieu!D47:D49)/1000000000,"") -> 4637.3728 | E19: =IFERROR(MEDIAN(DuLieu!F47:F49)/1000000000,"") -> 3096.388 | F19: =COUNTIF(DuLieu!W47:W49,"Có") -> 0 | G19: =IFERROR(MEDIAN(DuLieu!X47:X49),"") -> 67.294538 | H19: =IF(I19="Có","Loại",IF(G19="","Chưa rõ",IF(G19<ThamSo!$C$15,"CMT","FOB"))) -> FOB | I19: Không | K19: =SUM(DuLieu!U47:U49) -> 3 | L19: =IF(K19=0,"",IF(COUNTIFS(DuLieu!U47:U49,1,DuLieu!V47:V49,"Nhỏ–vừa")>=COUNTIFS(DuLieu!U47:U49,1,DuLieu!V47:V49,"Lớn"),"Nhỏ–vừa","Lớn")) -> Lớn | M19: =IFERROR(MEDIAN(DuLieu!AB47:AB49),"") -> 61.378637 | N19: =IFERROR(MEDIAN(DuLieu!AE47:AE49),"") -> 67.294538 | O19: =IFERROR(MEDIAN(DuLieu!AH47:AH49),"") -> 24.57389 | P19: =IFERROR(MEDIAN(DuLieu!Y47:Y49),"") -> 0.10649043 | Q19: =IF(AND(H19="FOB",K19>0),"Có","Không") -> Có
A20: MPT | B20: Tập đoàn MPT | C20: Nhóm 1 – nhỏ | D20: =IFERROR(MEDIAN(DuLieu!D50:D52)/1000000000,"") -> 0 | E20: =IFERROR(MEDIAN(DuLieu!F50:F52)/1000000000,"") -> 177.58481 | F20: =COUNTIF(DuLieu!W50:W52,"Có") -> 3 | G20: =IFERROR(MEDIAN(DuLieu!X50:X52),"") | H20: =IF(I20="Có","Loại",IF(G20="","Chưa rõ",IF(G20<ThamSo!$C$15,"CMT","FOB"))) -> Chưa rõ | I20: Không | K20: =SUM(DuLieu!U50:U52) -> 0 | L20: =IF(K20=0,"",IF(COUNTIFS(DuLieu!U50:U52,1,DuLieu!V50:V52,"Nhỏ–vừa")>=COUNTIFS(DuLieu!U50:U52,1,DuLieu!V50:V52,"Lớn"),"Nhỏ–vừa","Lớn")) | M20: =IFERROR(MEDIAN(DuLieu!AB50:AB52),"") | N20: =IFERROR(MEDIAN(DuLieu!AE50:AE52),"") | O20: =IFERROR(MEDIAN(DuLieu!AH50:AH52),"") | P20: =IFERROR(MEDIAN(DuLieu!Y50:Y52),"") | Q20: =IF(AND(H20="FOB",K20>0),"Có","Không") -> Không
A21: MSH | B21: May Sông Hồng | C21: Nhóm 2 – lớn | D21: =IFERROR(MEDIAN(DuLieu!D53:D55)/1000000000,"") -> 5280.4032 | E21: =IFERROR(MEDIAN(DuLieu!F53:F55)/1000000000,"") -> 4523.1889 | F21: =COUNTIF(DuLieu!W53:W55,"Có") -> 0 | G21: =IFERROR(MEDIAN(DuLieu!X53:X55),"") -> 50.400766 | H21: =IF(I21="Có","Loại",IF(G21="","Chưa rõ",IF(G21<ThamSo!$C$15,"CMT","FOB"))) -> FOB | I21: Không | K21: =SUM(DuLieu!U53:U55) -> 3 | L21: =IF(K21=0,"",IF(COUNTIFS(DuLieu!U53:U55,1,DuLieu!V53:V55,"Nhỏ–vừa")>=COUNTIFS(DuLieu!U53:U55,1,DuLieu!V53:V55,"Lớn"),"Nhỏ–vừa","Lớn")) -> Lớn | M21: =IFERROR(MEDIAN(DuLieu!AB53:AB55),"") -> 54.083058 | N21: =IFERROR(MEDIAN(DuLieu!AE53:AE55),"") -> 50.400766 | O21: =IFERROR(MEDIAN(DuLieu!AH53:AH55),"") -> 15.363061 | P21: =IFERROR(MEDIAN(DuLieu!Y53:Y55),"") -> 0.29248052 | Q21: =IF(AND(H21="FOB",K21>0),"Có","Không") -> Có
A22: NJC | B22: May Nam Định | C22: Nhóm 1 – nhỏ | D22: =IFERROR(MEDIAN(DuLieu!D56:D58)/1000000000,"") -> 661.50828 | E22: =IFERROR(MEDIAN(DuLieu!F56:F58)/1000000000,"") -> 409.33085 | F22: =COUNTIF(DuLieu!W56:W58,"Có") -> 0 | G22: =IFERROR(MEDIAN(DuLieu!X56:X58),"") -> 86.7301 | H22: =IF(I22="Có","Loại",IF(G22="","Chưa rõ",IF(G22<ThamSo!$C$15,"CMT","FOB"))) -> FOB | I22: Không | K22: =SUM(DuLieu!U56:U58) -> 3 | L22: =IF(K22=0,"",IF(COUNTIFS(DuLieu!U56:U58,1,DuLieu!V56:V58,"Nhỏ–vừa")>=COUNTIFS(DuLieu!U56:U58,1,DuLieu!V56:V58,"Lớn"),"Nhỏ–vừa","Lớn")) -> Nhỏ–vừa | M22: =IFERROR(MEDIAN(DuLieu!AB56:AB58),"") -> 61.065652 | N22: =IFERROR(MEDIAN(DuLieu!AE56:AE58),"") -> 86.7301 | O22: =IFERROR(MEDIAN(DuLieu!AH56:AH58),"") -> 17.897413 | P22: =IFERROR(MEDIAN(DuLieu!Y56:Y58),"") -> 0.061517656 | Q22: =IF(AND(H22="FOB",K22>0),"Có","Không") -> Có
A23: NTT | B23: Dệt may Nha Trang | C23: Nhóm 1 – nhỏ | D23: =IFERROR(MEDIAN(DuLieu!D59:D61)/1000000000,"") -> 1233.6482 | E23: =IFERROR(MEDIAN(DuLieu!F59:F61)/1000000000,"") -> 1123.848 | F23: =COUNTIF(DuLieu!W59:W61,"Có") -> 0 | G23: =IFERROR(MEDIAN(DuLieu!X59:X61),"") -> 104.63331 | H23: =IF(I23="Có","Loại",IF(G23="","Chưa rõ",IF(G23<ThamSo!$C$15,"CMT","FOB"))) -> FOB | I23: Không | K23: =SUM(DuLieu!U59:U61) -> 3 | L23: =IF(K23=0,"",IF(COUNTIFS(DuLieu!U59:U61,1,DuLieu!V59:V61,"Nhỏ–vừa")>=COUNTIFS(DuLieu!U59:U61,1,DuLieu!V59:V61,"Lớn"),"Nhỏ–vừa","Lớn")) -> Nhỏ–vừa | M23: =IFERROR(MEDIAN(DuLieu!AB59:AB61),"") -> 51.667854 | N23: =IFERROR(MEDIAN(DuLieu!AE59:AE61),"") -> 104.63331 | O23: =IFERROR(MEDIAN(DuLieu!AH59:AH61),"") -> 73.679788 | P23: =IFERROR(MEDIAN(DuLieu!Y59:Y61),"") -> 0.082408586 | Q23: =IF(AND(H23="FOB",K23>0),"Có","Không") -> Có
A24: PTG | B24: May Xuất khẩu Phan Thiết | C24: Nhóm 1 – nhỏ | D24: =IFERROR(MEDIAN(DuLieu!D62:D64)/1000000000,"") -> 488.1488 | E24: =IFERROR(MEDIAN(DuLieu!F62:F64)/1000000000,"") -> 363.67921 | F24: =COUNTIF(DuLieu!W62:W64,"Có") -> 0 | G24: =IFERROR(MEDIAN(DuLieu!X62:X64),"") -> 4.3673682 | H24: =IF(I24="Có","Loại",IF(G24="","Chưa rõ",IF(G24<ThamSo!$C$15,"CMT","FOB"))) -> CMT | I24: Không | K24: =SUM(DuLieu!U62:U64) -> 0 | L24: =IF(K24=0,"",IF(COUNTIFS(DuLieu!U62:U64,1,DuLieu!V62:V64,"Nhỏ–vừa")>=COUNTIFS(DuLieu!U62:U64,1,DuLieu!V62:V64,"Lớn"),"Nhỏ–vừa","Lớn")) | M24: =IFERROR(MEDIAN(DuLieu!AB62:AB64),"") | N24: =IFERROR(MEDIAN(DuLieu!AE62:AE64),"") | O24: =IFERROR(MEDIAN(DuLieu!AH62:AH64),"") | P24: =IFERROR(MEDIAN(DuLieu!Y62:Y64),"") | Q24: =IF(AND(H24="FOB",K24>0),"Có","Không") -> Không
A25: TCM | B25: Dệt may Thành Công | C25: Nhóm 2 – lớn | D25: =IFERROR(MEDIAN(DuLieu!D65:D67)/1000000000,"") -> 3645.2522 | E25: =IFERROR(MEDIAN(DuLieu!F65:F67)/1000000000,"") -> 3895.5344 | F25: =COUNTIF(DuLieu!W65:W67,"Có") -> 0 | G25: =IFERROR(MEDIAN(DuLieu!X65:X67),"") -> 121.89984 | H25: =IF(I25="Có","Loại",IF(G25="","Chưa rõ",IF(G25<ThamSo!$C$15,"CMT","FOB"))) -> FOB | I25: Không | K25: =SUM(DuLieu!U65:U67) -> 3 | L25: =IF(K25=0,"",IF(COUNTIFS(DuLieu!U65:U67,1,DuLieu!V65:V67,"Nhỏ–vừa")>=COUNTIFS(DuLieu!U65:U67,1,DuLieu!V65:V67,"Lớn"),"Nhỏ–vừa","Lớn")) -> Lớn | M25: =IFERROR(MEDIAN(DuLieu!AB65:AB67),"") -> 44.374219 | N25: =IFERROR(MEDIAN(DuLieu!AE65:AE67),"") -> 121.89984 | O25: =IFERROR(MEDIAN(DuLieu!AH65:AH67),"") -> 42.505649 | P25: =IFERROR(MEDIAN(DuLieu!Y65:Y67),"") -> 0.28770637 | Q25: =IF(AND(H25="FOB",K25>0),"Có","Không") -> Có
A26: TDT | B26: Đầu tư Phát triển TDT | C26: Nhóm 1 – nhỏ | D26: =IFERROR(MEDIAN(DuLieu!D68:D70)/1000000000,"") -> 563.12964 | E26: =IFERROR(MEDIAN(DuLieu!F68:F70)/1000000000,"") -> 615.18187 | F26: =COUNTIF(DuLieu!W68:W70,"Có") -> 0 | G26: =IFERROR(MEDIAN(DuLieu!X68:X70),"") -> 255.11526 | H26: =IF(I26="Có","Loại",IF(G26="","Chưa rõ",IF(G26<ThamSo!$C$15,"CMT","FOB"))) -> FOB | I26: Không | K26: =SUM(DuLieu!U68:U70) -> 3 | L26: =IF(K26=0,"",IF(COUNTIFS(DuLieu!U68:U70,1,DuLieu!V68:V70,"Nhỏ–vừa")>=COUNTIFS(DuLieu!U68:U70,1,DuLieu!V68:V70,"Lớn"),"Nhỏ–vừa","Lớn")) -> Nhỏ–vừa | M26: =IFERROR(MEDIAN(DuLieu!AB68:AB70),"") -> 34.643 | N26: =IFERROR(MEDIAN(DuLieu!AE68:AE70),"") -> 255.11526 | O26: =IFERROR(MEDIAN(DuLieu!AH68:AH70),"") -> 16.787181 | P26: =IFERROR(MEDIAN(DuLieu!Y68:Y70),"") -> 0.109882 | Q26: =IF(AND(H26="FOB",K26>0),"Có","Không") -> Có
A27: THM | B27: Tứ Hải Hà Nam | C27: Nhóm 1 – nhỏ | D27: =IFERROR(MEDIAN(DuLieu!D71:D73)/1000000000,"") -> 118.42341 | E27: =IFERROR(MEDIAN(DuLieu!F71:F73)/1000000000,"") -> 174.68358 | F27: =COUNTIF(DuLieu!W71:W73,"Có") -> 3 | G27: =IFERROR(MEDIAN(DuLieu!X71:X73),"") -> 4.9003357 | H27: =IF(I27="Có","Loại",IF(G27="","Chưa rõ",IF(G27<ThamSo!$C$15,"CMT","FOB"))) -> CMT | I27: Không | K27: =SUM(DuLieu!U71:U73) -> 0 | L27: =IF(K27=0,"",IF(COUNTIFS(DuLieu!U71:U73,1,DuLieu!V71:V73,"Nhỏ–vừa")>=COUNTIFS(DuLieu!U71:U73,1,DuLieu!V71:V73,"Lớn"),"Nhỏ–vừa","Lớn")) | M27: =IFERROR(MEDIAN(DuLieu!AB71:AB73),"") | N27: =IFERROR(MEDIAN(DuLieu!AE71:AE73),"") | O27: =IFERROR(MEDIAN(DuLieu!AH71:AH73),"") | P27: =IFERROR(MEDIAN(DuLieu!Y71:Y73),"") | Q27: =IF(AND(H27="FOB",K27>0),"Có","Không") -> Không
A28: TNG | B28: Đầu tư và Thương mại TNG | C28: Nhóm 2 – lớn | D28: =IFERROR(MEDIAN(DuLieu!D74:D76)/1000000000,"") -> 7655.7528 | E28: =IFERROR(MEDIAN(DuLieu!F74:F76)/1000000000,"") -> 5816.8752 | F28: =COUNTIF(DuLieu!W74:W76,"Có") -> 0 | G28: =IFERROR(MEDIAN(DuLieu!X74:X76),"") -> 70.3822 | H28: =IF(I28="Có","Loại",IF(G28="","Chưa rõ",IF(G28<ThamSo!$C$15,"CMT","FOB"))) -> FOB | I28: Không | K28: =SUM(DuLieu!U74:U76) -> 3 | L28: =IF(K28=0,"",IF(COUNTIFS(DuLieu!U74:U76,1,DuLieu!V74:V76,"Nhỏ–vừa")>=COUNTIFS(DuLieu!U74:U76,1,DuLieu!V74:V76,"Lớn"),"Nhỏ–vừa","Lớn")) -> Lớn | M28: =IFERROR(MEDIAN(DuLieu!AB74:AB76),"") -> 33.076023 | N28: =IFERROR(MEDIAN(DuLieu!AE74:AE76),"") -> 70.3822 | O28: =IFERROR(MEDIAN(DuLieu!AH74:AH76),"") -> 35.332391 | P28: =IFERROR(MEDIAN(DuLieu!Y74:Y76),"") -> 0.090705407 | Q28: =IF(AND(H28="FOB",K28>0),"Có","Không") -> Có
A29: VGG | B29: May Việt Tiến | C29: Nhóm 2 – lớn | D29: =IFERROR(MEDIAN(DuLieu!D77:D79)/1000000000,"") -> 9756.3632 | E29: =IFERROR(MEDIAN(DuLieu!F77:F79)/1000000000,"") -> 5292.0502 | F29: =COUNTIF(DuLieu!W77:W79,"Có") -> 0 | G29: =IFERROR(MEDIAN(DuLieu!X77:X79),"") -> 57.606144 | H29: =IF(I29="Có","Loại",IF(G29="","Chưa rõ",IF(G29<ThamSo!$C$15,"CMT","FOB"))) -> FOB | I29: Không | K29: =SUM(DuLieu!U77:U79) -> 3 | L29: =IF(K29=0,"",IF(COUNTIFS(DuLieu!U77:U79,1,DuLieu!V77:V79,"Nhỏ–vừa")>=COUNTIFS(DuLieu!U77:U79,1,DuLieu!V77:V79,"Lớn"),"Nhỏ–vừa","Lớn")) -> Lớn | M29: =IFERROR(MEDIAN(DuLieu!AB77:AB79),"") -> 58.483211 | N29: =IFERROR(MEDIAN(DuLieu!AE77:AE79),"") -> 57.606144 | O29: =IFERROR(MEDIAN(DuLieu!AH77:AH79),"") -> 76.865913 | P29: =IFERROR(MEDIAN(DuLieu!Y77:Y79),"") -> 0.083207798 | Q29: =IF(AND(H29="FOB",K29>0),"Có","Không") -> Có
A30: VTI | B30: SX - XNK Dệt may | C30: Nhóm 1 – nhỏ | D30: =IFERROR(MEDIAN(DuLieu!D80:D82)/1000000000,"") -> 4.8710692 | E30: =IFERROR(MEDIAN(DuLieu!F80:F82)/1000000000,"") -> 3.4733646 | F30: =COUNTIF(DuLieu!W80:W82,"Có") -> 3 | G30: =IFERROR(MEDIAN(DuLieu!X80:X82),"") | H30: =IF(I30="Có","Loại",IF(G30="","Chưa rõ",IF(G30<ThamSo!$C$15,"CMT","FOB"))) -> Loại | I30: Có | J30: Doanh thu 5–9 tỷ, DSO hàng nghìn ngày: không còn hoạt động may thực chất. | K30: =SUM(DuLieu!U80:U82) -> 0 | L30: =IF(K30=0,"",IF(COUNTIFS(DuLieu!U80:U82,1,DuLieu!V80:V82,"Nhỏ–vừa")>=COUNTIFS(DuLieu!U80:U82,1,DuLieu!V80:V82,"Lớn"),"Nhỏ–vừa","Lớn")) | M30: =IFERROR(MEDIAN(DuLieu!AB80:AB82),"") | N30: =IFERROR(MEDIAN(DuLieu!AE80:AE82),"") | O30: =IFERROR(MEDIAN(DuLieu!AH80:AH82),"") | P30: =IFERROR(MEDIAN(DuLieu!Y80:Y82),"") | Q30: =IF(AND(H30="FOB",K30>0),"Có","Không") -> Không
A31: X20 | B31: CTCP X20 | C31: Nhóm 1 – nhỏ | D31: =IFERROR(MEDIAN(DuLieu!D83:D85)/1000000000,"") -> 1115.5455 | E31: =IFERROR(MEDIAN(DuLieu!F83:F85)/1000000000,"") -> 599.21298 | F31: =COUNTIF(DuLieu!W83:W85,"Có") -> 0 | G31: =IFERROR(MEDIAN(DuLieu!X83:X85),"") -> 69.965112 | H31: =IF(I31="Có","Loại",IF(G31="","Chưa rõ",IF(G31<ThamSo!$C$15,"CMT","FOB"))) -> FOB | I31: Không | K31: =SUM(DuLieu!U83:U85) -> 3 | L31: =IF(K31=0,"",IF(COUNTIFS(DuLieu!U83:U85,1,DuLieu!V83:V85,"Nhỏ–vừa")>=COUNTIFS(DuLieu!U83:U85,1,DuLieu!V83:V85,"Lớn"),"Nhỏ–vừa","Lớn")) -> Nhỏ–vừa | M31: =IFERROR(MEDIAN(DuLieu!AB83:AB85),"") -> 24.972029 | N31: =IFERROR(MEDIAN(DuLieu!AE83:AE85),"") -> 69.965112 | O31: =IFERROR(MEDIAN(DuLieu!AH83:AH85),"") -> 72.420394 | P31: =IFERROR(MEDIAN(DuLieu!Y83:Y85),"") -> 0.14221504 | Q31: =IF(AND(H31="FOB",K31>0),"Có","Không") -> Có
A32: X26 | B32: CTCP 26 | C32: Nhóm 1 – nhỏ | D32: =IFERROR(MEDIAN(DuLieu!D86:D88)/1000000000,"") -> 1073.0118 | E32: =IFERROR(MEDIAN(DuLieu!F86:F88)/1000000000,"") -> 711.8833 | F32: =COUNTIF(DuLieu!W86:W88,"Có") -> 0 | G32: =IFERROR(MEDIAN(DuLieu!X86:X88),"") -> 73.87967 | H32: =IF(I32="Có","Loại",IF(G32="","Chưa rõ",IF(G32<ThamSo!$C$15,"CMT","FOB"))) -> FOB | I32: Không | K32: =SUM(DuLieu!U86:U88) -> 3 | L32: =IF(K32=0,"",IF(COUNTIFS(DuLieu!U86:U88,1,DuLieu!V86:V88,"Nhỏ–vừa")>=COUNTIFS(DuLieu!U86:U88,1,DuLieu!V86:V88,"Lớn"),"Nhỏ–vừa","Lớn")) -> Nhỏ–vừa | M32: =IFERROR(MEDIAN(DuLieu!AB86:AB88),"") -> 48.098369 | N32: =IFERROR(MEDIAN(DuLieu!AE86:AE88),"") -> 73.87967 | O32: =IFERROR(MEDIAN(DuLieu!AH86:AH88),"") -> 74.86254 | P32: =IFERROR(MEDIAN(DuLieu!Y86:Y88),"") -> 0.1541313 | Q32: =IF(AND(H32="FOB",K32>0),"Có","Không") -> Có
A34: Tổng | F34: =SUM(F5:F32) -> 13 | K34: =SUM(K5:K32) -> 60 | Q34: =COUNTIF(Q5:Q32,"Có") -> 20
A36: Kết quả lọc: 20 DN FOB × 3 năm = 60 năm–DN. Không thuộc mẫu: 3 DN gia công (DCG, PTG, THM); 3 DN không còn doanh thu ≥ 50 tỷ trong 2023–2025 (G20, GMC, MPT); 2 DN bị loại (VTI, GIL).

Sheet DuLieu
A1: DỮ LIỆU NGÀNH MAY: 28 DOANH NGHIỆP × 2023–2025 (FiinTrade) – mẫu tính ngưỡng chỉ gồm DN FOB
A2: Chữ xanh: số liệu FiinTrade nhập nguyên văn (5 file “Chỉ số tài chính” xuất 18/10/2026; DSO/DIO/DPO do FiinTrade tính trên số dư bình quân, 365 ngày). Chữ đen: công thức. Cột “– FOB” chỉ lấy năm–DN thuộc mẫu FOB đang hoạt động (cột U = 1).
A4: Mã | B4: Năm | C4: File FiinTrade | D4: Doanh thu thuần (đồng) | E4: Biên LN gộp | F4: Tổng nguồn vốn (đồng) | G4: Tài sản ngắn hạn (đồng) | H4: Tiền và tương đương tiền (đồng) | I4: Đầu tư tài chính ngắn hạn (đồng) | J4: Hàng tồn kho ròng (đồng) | K4: LNST cổ đông mẹ (đồng) | L4: DSO – FiinTrade (ngày) | M4: DIO – FiinTrade (ngày) | N4: DPO – FiinTrade (ngày) | O4: Giá vốn = DT × (1 − biên gộp) (đồng) | P4: Đệm tiền = (Tiền + ĐTNH) / DT | Q4: Tiền / DT | R4: Biến động tiền = (Tiền − Tiền năm trước) / DT | S4: Mô hình | T4: DN bị loại? | U4: Thuộc mẫu FOB & đang hoạt động (1/0) | V4: Nhóm quy mô | W4: SME theo NĐ80? | X4: DIO nếu hoạt động (mọi mô hình) | Y4: Đệm tiền – FOB | Z4: Đệm tiền – FOB Nhỏ–vừa | AA4: Đệm tiền – FOB Lớn | AB4: DSO – FOB | AC4: DSO – FOB Nhỏ–vừa | AD4: DSO – FOB Lớn | AE4: DIO – FOB | AF4: DIO – FOB Nhỏ–vừa | AG4: DIO – FOB Lớn | AH4: DPO – FOB | AI4: DPO – FOB Nhỏ–vừa | AJ4: DPO – FOB Lớn | AK4: Tiền / DT – FOB | AL4: Biến động tiền / DT – FOB | AM4: Khóa Mã-Năm
A5: AG1 | B5: 2023 | C5: FiinTrade_..._AG1_20261018.xlsx | D5: 269017127126 | E5: 0.14625449 | F5: 144115422092 | G5: 128660408494 | H5: 6804199578 | I5: 0 | J5: 93402244974 | K5: 10796262054 | L5: 25.857809 | M5: 145.84777 | N5: 107.20841 | O5: =IF(OR(D5="",E5=""),"",D5*(1-E5)) -> 2.2967216e+11 | P5: =IF(OR(H5="",D5=""),"",IF(D5<=0,"",(H5+N(I5))/D5)) -> 0.025292812 | Q5: =IF(OR(H5="",D5=""),"",IF(D5<=0,"",H5/D5)) -> 0.025292812 | R5: ="" | S5: =INDEX(HoSoDN!$H$5:$H$32,MATCH(A5,HoSoDN!$A$5:$A$32,0)) -> FOB | T5: =INDEX(HoSoDN!$I$5:$I$32,MATCH(A5,HoSoDN!$A$5:$A$32,0)) -> Không | U5: =IF(AND(S5="FOB",T5<>"Có",B5>=ThamSo!$C$22,B5<=ThamSo!$C$23,D5<>"",E5<>"",G5<>"",P5<>"",L5<>"",M5<>"",N5<>""),IF(D5>=ThamSo!$C$11,1,0),0) -> 1 | V5: =IF(D5="","",IF(D5<=ThamSo!$C$12,"Nhỏ–vừa","Lớn")) -> Nhỏ–vừa | W5: =IF(D5="","",IF(OR(D5<=ThamSo!$C$13,F5<=ThamSo!$C$14),"Có","Không")) -> Không | X5: =IF(AND(T5<>"Có",M5<>"",D5<>""),IF(D5>=ThamSo!$C$11,M5,""),"") -> 145.84777 | Y5: =IF(U5=1,P5,"") -> 0.025292812 | Z5: =IF(AND(U5=1,V5="Nhỏ–vừa"),P5,"") -> 0.025292812 | AA5: =IF(AND(U5=1,V5="Lớn"),P5,"") | AB5: =IF(U5=1,L5,"") -> 25.857809 | AC5: =IF(AND(U5=1,V5="Nhỏ–vừa"),L5,"") -> 25.857809 | AD5: =IF(AND(U5=1,V5="Lớn"),L5,"") | AE5: =IF(U5=1,M5,"") -> 145.84777 | AF5: =IF(AND(U5=1,V5="Nhỏ–vừa"),M5,"") -> 145.84777 | AG5: =IF(AND(U5=1,V5="Lớn"),M5,"") | AH5: =IF(U5=1,N5,"") -> 107.20841 | AI5: =IF(AND(U5=1,V5="Nhỏ–vừa"),N5,"") -> 107.20841 | AJ5: =IF(AND(U5=1,V5="Lớn"),N5,"") | AK5: =IF(U5=1,Q5,"") -> 0.025292812 | AL5: =IF(AND(U5=1,R5<>""),R5,"") | AM5: =A5&"-"&B5 -> AG1-2023
A6: AG1 | B6: 2024 | C6: FiinTrade_..._AG1_20261018.xlsx | D6: 337512371714 | E6: 0.11758799 | F6: 151539551502 | G6: 135967622195 | H6: 40157015524 | I6: 0 | J6: 78826891496 | K6: 8630835708 | L6: 20.640644 | M6: 105.53788 | N6: 84.012707 | O6: =IF(OR(D6="",E6=""),"",D6*(1-E6)) -> 2.9782497e+11 | P6: =IF(OR(H6="",D6=""),"",IF(D6<=0,"",(H6+N(I6))/D6)) -> 0.11897939 | Q6: =IF(OR(H6="",D6=""),"",IF(D6<=0,"",H6/D6)) -> 0.11897939 | R6: =IF(OR(A5<>A6,B6<=ThamSo!$C$22,H6="",H5="",D6=""),"",IF(D6<=0,"",(H6-H5)/D6)) -> 0.098819536 | S6: =INDEX(HoSoDN!$H$5:$H$32,MATCH(A6,HoSoDN!$A$5:$A$32,0)) -> FOB | T6: =INDEX(HoSoDN!$I$5:$I$32,MATCH(A6,HoSoDN!$A$5:$A$32,0)) -> Không | U6: =IF(AND(S6="FOB",T6<>"Có",B6>=ThamSo!$C$22,B6<=ThamSo!$C$23,D6<>"",E6<>"",G6<>"",P6<>"",L6<>"",M6<>"",N6<>""),IF(D6>=ThamSo!$C$11,1,0),0) -> 1 | V6: =IF(D6="","",IF(D6<=ThamSo!$C$12,"Nhỏ–vừa","Lớn")) -> Nhỏ–vừa | W6: =IF(D6="","",IF(OR(D6<=ThamSo!$C$13,F6<=ThamSo!$C$14),"Có","Không")) -> Không | X6: =IF(AND(T6<>"Có",M6<>"",D6<>""),IF(D6>=ThamSo!$C$11,M6,""),"") -> 105.53788 | Y6: =IF(U6=1,P6,"") -> 0.11897939 | Z6: =IF(AND(U6=1,V6="Nhỏ–vừa"),P6,"") -> 0.11897939 | AA6: =IF(AND(U6=1,V6="Lớn"),P6,"") | AB6: =IF(U6=1,L6,"") -> 20.640644 | AC6: =IF(AND(U6=1,V6="Nhỏ–vừa"),L6,"") -> 20.640644 | AD6: =IF(AND(U6=1,V6="Lớn"),L6,"") | AE6: =IF(U6=1,M6,"") -> 105.53788 | AF6: =IF(AND(U6=1,V6="Nhỏ–vừa"),M6,"") -> 105.53788 | AG6: =IF(AND(U6=1,V6="Lớn"),M6,"") | AH6: =IF(U6=1,N6,"") -> 84.012707 | AI6: =IF(AND(U6=1,V6="Nhỏ–vừa"),N6,"") -> 84.012707 | AJ6: =IF(AND(U6=1,V6="Lớn"),N6,"") | AK6: =IF(U6=1,Q6,"") -> 0.11897939 | AL6: =IF(AND(U6=1,R6<>""),R6,"") -> 0.098819536 | AM6: =A6&"-"&B6 -> AG1-2024
A7: AG1 | B7: 2025 | C7: FiinTrade_..._AG1_20261018.xlsx | D7: 384757383278 | E7: 0.11571369 | F7: 160263788547 | G7: 145047321035 | H7: 17229224009 | I7: 0 | J7: 77056556959 | K7: 11160450510 | L7: 26.756938 | M7: 83.614772 | N7: 69.834385 | O7: =IF(OR(D7="",E7=""),"",D7*(1-E7)) -> 3.4023569e+11 | P7: =IF(OR(H7="",D7=""),"",IF(D7<=0,"",(H7+N(I7))/D7)) -> 0.04477945 | Q7: =IF(OR(H7="",D7=""),"",IF(D7<=0,"",H7/D7)) -> 0.04477945 | R7: =IF(OR(A6<>A7,B7<=ThamSo!$C$22,H7="",H6="",D7=""),"",IF(D7<=0,"",(H7-H6)/D7)) -> -0.059590257 | S7: =INDEX(HoSoDN!$H$5:$H$32,MATCH(A7,HoSoDN!$A$5:$A$32,0)) -> FOB | T7: =INDEX(HoSoDN!$I$5:$I$32,MATCH(A7,HoSoDN!$A$5:$A$32,0)) -> Không | U7: =IF(AND(S7="FOB",T7<>"Có",B7>=ThamSo!$C$22,B7<=ThamSo!$C$23,D7<>"",E7<>"",G7<>"",P7<>"",L7<>"",M7<>"",N7<>""),IF(D7>=ThamSo!$C$11,1,0),0) -> 1 | V7: =IF(D7="","",IF(D7<=ThamSo!$C$12,"Nhỏ–vừa","Lớn")) -> Nhỏ–vừa | W7: =IF(D7="","",IF(OR(D7<=ThamSo!$C$13,F7<=ThamSo!$C$14),"Có","Không")) -> Không | X7: =IF(AND(T7<>"Có",M7<>"",D7<>""),IF(D7>=ThamSo!$C$11,M7,""),"") -> 83.614772 | Y7: =IF(U7=1,P7,"") -> 0.04477945 | Z7: =IF(AND(U7=1,V7="Nhỏ–vừa"),P7,"") -> 0.04477945 | AA7: =IF(AND(U7=1,V7="Lớn"),P7,"") | AB7: =IF(U7=1,L7,"") -> 26.756938 | AC7: =IF(AND(U7=1,V7="Nhỏ–vừa"),L7,"") -> 26.756938 | AD7: =IF(AND(U7=1,V7="Lớn"),L7,"") | AE7: =IF(U7=1,M7,"") -> 83.614772 | AF7: =IF(AND(U7=1,V7="Nhỏ–vừa"),M7,"") -> 83.614772 | AG7: =IF(AND(U7=1,V7="Lớn"),M7,"") | AH7: =IF(U7=1,N7,"") -> 69.834385 | AI7: =IF(AND(U7=1,V7="Nhỏ–vừa"),N7,"") -> 69.834385 | AJ7: =IF(AND(U7=1,V7="Lớn"),N7,"") | AK7: =IF(U7=1,Q7,"") -> 0.04477945 | AL7: =IF(AND(U7=1,R7<>""),R7,"") -> -0.059590257 | AM7: =A7&"-"&B7 -> AG1-2025
A8: BDG | B8: 2023 | C8: FiinTrade_..._HUG_20261018.xlsx | D8: 1565802348007 | E8: 0.17063204 | F8: 1011708486937 | G8: 762014891824 | H8: 69598955414 | I8: 166744272248 | J8: 257014934641 | K8: 123382071529 | L8: 46.399479 | M8: 75.031069 | N8: 38.543819 | O8: =IF(OR(D8="",E8=""),"",D8*(1-E8)) -> 1.2986263e+12 | P8: =IF(OR(H8="",D8=""),"",IF(D8<=0,"",(H8+N(I8))/D8)) -> 0.15094065 | Q8: =IF(OR(H8="",D8=""),"",IF(D8<=0,"",H8/D8)) -> 0.044449388 | R8: =IF(OR(A7<>A8,B8<=ThamSo!$C$22,H8="",H7="",D8=""),"",IF(D8<=0,"",(H8-H7)/D8)) | S8: =INDEX(HoSoDN!$H$5:$H$32,MATCH(A8,HoSoDN!$A$5:$A$32,0)) -> FOB | T8: =INDEX(HoSoDN!$I$5:$I$32,MATCH(A8,HoSoDN!$A$5:$A$32,0)) -> Không | U8: =IF(AND(S8="FOB",T8<>"Có",B8>=ThamSo!$C$22,B8<=ThamSo!$C$23,D8<>"",E8<>"",G8<>"",P8<>"",L8<>"",M8<>"",N8<>""),IF(D8>=ThamSo!$C$11,1,0),0) -> 1 | V8: =IF(D8="","",IF(D8<=ThamSo!$C$12,"Nhỏ–vừa","Lớn")) -> Lớn | W8: =IF(D8="","",IF(OR(D8<=ThamSo!$C$13,F8<=ThamSo!$C$14),"Có","Không")) -> Không | X8: =IF(AND(T8<>"Có",M8<>"",D8<>""),IF(D8>=ThamSo!$C$11,M8,""),"") -> 75.031069 | Y8: =IF(U8=1,P8,"") -> 0.15094065 | Z8: =IF(AND(U8=1,V8="Nhỏ–vừa"),P8,"") | AA8: =IF(AND(U8=1,V8="Lớn"),P8,"") -> 0.15094065 | AB8: =IF(U8=1,L8,"") -> 46.399479 | AC8: =IF(AND(U8=1,V8="Nhỏ–vừa"),L8,"") | AD8: =IF(AND(U8=1,V8="Lớn"),L8,"") -> 46.399479 | AE8: =IF(U8=1,M8,"") -> 75.031069 | AF8: =IF(AND(U8=1,V8="Nhỏ–vừa"),M8,"") | AG8: =IF(AND(U8=1,V8="Lớn"),M8,"") -> 75.031069 | AH8: =IF(U8=1,N8,"") -> 38.543819 | AI8: =IF(AND(U8=1,V8="Nhỏ–vừa"),N8,"") | AJ8: =IF(AND(U8=1,V8="Lớn"),N8,"") -> 38.543819 | AK8: =IF(U8=1,Q8,"") -> 0.044449388 | AL8: =IF(AND(U8=1,R8<>""),R8,"") | AM8: =A8&"-"&B8 -> BDG-2023
A9: BDG | B9: 2024 | C9: FiinTrade_..._HUG_20261018.xlsx | D9: 1821385866875 | E9: 0.17196293 | F9: 1132622851960 | G9: 892610103449 | H9: 48862200008 | I9: 265402054405 | J9: 235196575141 | K9: 164275444455 | L9: 47.799581 | M9: 59.720353 | N9: 31.093713 | O9: =IF(OR(D9="",E9=""),"",D9*(1-E9)) -> 1.508175e+12 | P9: =IF(OR(H9="",D9=""),"",IF(D9<=0,"",(H9+N(I9))/D9)) -> 0.17254128 | Q9: =IF(OR(H9="",D9=""),"",IF(D9<=0,"",H9/D9)) -> 0.026826935 | R9: =IF(OR(A8<>A9,B9<=ThamSo!$C$22,H9="",H8="",D9=""),"",IF(D9<=0,"",(H9-H8)/D9)) -> -0.011385152 | S9: =INDEX(HoSoDN!$H$5:$H$32,MATCH(A9,HoSoDN!$A$5:$A$32,0)) -> FOB | T9: =INDEX(HoSoDN!$I$5:$I$32,MATCH(A9,HoSoDN!$A$5:$A$32,0)) -> Không | U9: =IF(AND(S9="FOB",T9<>"Có",B9>=ThamSo!$C$22,B9<=ThamSo!$C$23,D9<>"",E9<>"",G9<>"",P9<>"",L9<>"",M9<>"",N9<>""),IF(D9>=ThamSo!$C$11,1,0),0) -> 1 | V9: =IF(D9="","",IF(D9<=ThamSo!$C$12,"Nhỏ–vừa","Lớn")) -> Lớn | W9: =IF(D9="","",IF(OR(D9<=ThamSo!$C$13,F9<=ThamSo!$C$14),"Có","Không")) -> Không | X9: =IF(AND(T9<>"Có",M9<>"",D9<>""),IF(D9>=ThamSo!$C$11,M9,""),"") -> 59.720353 | Y9: =IF(U9=1,P9,"") -> 0.17254128 | Z9: =IF(AND(U9=1,V9="Nhỏ–vừa"),P9,"") | AA9: =IF(AND(U9=1,V9="Lớn"),P9,"") -> 0.17254128 | AB9: =IF(U9=1,L9,"") -> 47.799581 | AC9: =IF(AND(U9=1,V9="Nhỏ–vừa"),L9,"") | AD9: =IF(AND(U9=1,V9="Lớn"),L9,"") -> 47.799581 | AE9: =IF(U9=1,M9,"") -> 59.720353 | AF9: =IF(AND(U9=1,V9="Nhỏ–vừa"),M9,"") | AG9: =IF(AND(U9=1,V9="Lớn"),M9,"") -> 59.720353 | AH9: =IF(U9=1,N9,"") -> 31.093713 | AI9: =IF(AND(U9=1,V9="Nhỏ–vừa"),N9,"") | AJ9: =IF(AND(U9=1,V9="Lớn"),N9,"") -> 31.093713 | AK9: =IF(U9=1,Q9,"") -> 0.026826935 | AL9: =IF(AND(U9=1,R9<>""),R9,"") -> -0.011385152 | AM9: =A9&"-"&B9 -> BDG-2024
A10: BDG | B10: 2025 | C10: FiinTrade_..._HUG_20261018.xlsx | D10: 1765786732419 | E10: 0.16278391 | F10: 1162581117483 | G10: 836089871106 | H10: 40096734073 | I10: 186523398636 | J10: 236366999548 | K10: 125019390165 | L10: 58.115114 | M10: 58.325885 | N10: 32.642841 | O10: =IF(OR(D10="",E10=""),"",D10*(1-E10)) -> 1.4783451e+12 | P10: =IF(OR(H10="",D10=""),"",IF(D10<=0,"",(H10+N(I10))/D10)) -> 0.12833947 | Q10: =IF(OR(H10="",D10=""),"",IF(D10<=0,"",H10/D10)) -> 0.022707575 | R10: =IF(OR(A9<>A10,B10<=ThamSo!$C$22,H10="",H9="",D10=""),"",IF(D10<=0,"",(H10-H9)/D10)) -> -0.004964057 | S10: =INDEX(HoSoDN!$H$5:$H$32,MATCH(A10,HoSoDN!$A$5:$A$32,0)) -> FOB | T10: =INDEX(HoSoDN!$I$5:$I$32,MATCH(A10,HoSoDN!$A$5:$A$32,0)) -> Không | U10: =IF(AND(S10="FOB",T10<>"Có",B10>=ThamSo!$C$22,B10<=ThamSo!$C$23,D10<>"",E10<>"",G10<>"",P10<>"",L10<>"",M10<>"",N10<>""),IF(D10>=ThamSo!$C$11,1,0),0) -> 1 | V10: =IF(D10="","",IF(D10<=ThamSo!$C$12,"Nhỏ–vừa","Lớn")) -> Lớn | W10: =IF(D10="","",IF(OR(D10<=ThamSo!$C$13,F10<=ThamSo!$C$14),"Có","Không")) -> Không | X10: =IF(AND(T10<>"Có",M10<>"",D10<>""),IF(D10>=ThamSo!$C$11,M10,""),"") -> 58.325885 | Y10: =IF(U10=1,P10,"") -> 0.12833947 | Z10: =IF(AND(U10=1,V10="Nhỏ–vừa"),P10,"") | AA10: =IF(AND(U10=1,V10="Lớn"),P10,"") -> 0.12833947 | AB10: =IF(U10=1,L10,"") -> 58.115114 | AC10: =IF(AND(U10=1,V10="Nhỏ–vừa"),L10,"") | AD10: =IF(AND(U10=1,V10="Lớn"),L10,"") -> 58.115114 | AE10: =IF(U10=1,M10,"") -> 58.325885 | AF10: =IF(AND(U10=1,V10="Nhỏ–vừa"),M10,"") | AG10: =IF(AND(U10=1,V10="Lớn"),M10,"") -> 58.325885 | AH10: =IF(U10=1,N10,"") -> 32.642841 | AI10: =IF(AND(U10=1,V10="Nhỏ–vừa"),N10,"") | AJ10: =IF(AND(U10=1,V10="Lớn"),N10,"") -> 32.642841 | AK10: =IF(U10=1,Q10,"") -> 0.022707575 | AL10: =IF(AND(U10=1,R10<>""),R10,"") -> -0.004964057 | AM10: =A10&"-"&B10 -> BDG-2025
A11: BMG | B11: 2023 | C11: FiinTrade_..._BMG_20261018.xlsx | D11: 295724897278 | E11: 0.16773156 | F11: 170519841613 | G11: 99960557124 | H11: 12093331210 | I11: 22927000000 | J11: 34200655246 | K11: 12757476122 | L11: 35.013296 | M11: 61.04222 | N11: 24.979894 | O11: =IF(OR(D11="",E11=""),"",D11*(1-E11)) -> 2.461225e+11 | P11: =IF(OR(H11="",D11=""),"",IF(D11<=0,"",(H11+N(I11))/D11)) -> 0.11842199 | Q11: =IF(OR(H11="",D11=""),"",IF(D11<=0,"",H11/D11)) -> 0.040893855 | R11: =IF(OR(A10<>A11,B11<=ThamSo!$C$22,H11="",H10="",D11=""),"",IF(D11<=0,"",(H11-H10)/D11)) | S11: =INDEX(HoSoDN!$H$5:$H$32,MATCH(A11,HoSoDN!$A$5:$A$32,0)) -> FOB | T11: =INDEX(HoSoDN!$I$5:$I$32,MATCH(A11,HoSoDN!$A$5:$A$32,0)) -> Không | U11: =IF(AND(S11="FOB",T11<>"Có",B11>=ThamSo!$C$22,B11<=ThamSo!$C$23,D11<>"",E11<>"",G11<>"",P11<>"",L11<>"",M11<>"",N11<>""),IF(D11>=ThamSo!$C$11,1,0),0) -> 1 | V11: =IF(D11="","",IF(D11<=ThamSo!$C$12,"Nhỏ–vừa","Lớn")) -> Nhỏ–vừa | W11: =IF(D11="","",IF(OR(D11<=ThamSo!$C$13,F11<=ThamSo!$C$14),"Có","Không")) -> Không | X11: =IF(AND(T11<>"Có",M11<>"",D11<>""),IF(D11>=ThamSo!$C$11,M11,""),"") -> 61.04222 | Y11: =IF(U11=1,P11,"") -> 0.11842199 | Z11: =IF(AND(U11=1,V11="Nhỏ–vừa"),P11,"") -> 0.11842199 | AA11: =IF(AND(U11=1,V11="Lớn"),P11,"") | AB11: =IF(U11=1,L11,"") -> 35.013296 | AC11: =IF(AND(U11=1,V11="Nhỏ–vừa"),L11,"") -> 35.013296 | AD11: =IF(AND(U11=1,V11="Lớn"),L11,"") | AE11: =IF(U11=1,M11,"") -> 61.04222 | AF11: =IF(AND(U11=1,V11="Nhỏ–vừa"),M11,"") -> 61.04222 | AG11: =IF(AND(U11=1,V11="Lớn"),M11,"") | AH11: =IF(U11=1,N11,"") -> 24.979894 | AI11: =IF(AND(U11=1,V11="Nhỏ–vừa"),N11,"") -> 24.979894 | AJ11: =IF(AND(U11=1,V11="Lớn"),N11,"") | AK11: =IF(U11=1,Q11,"") -> 0.040893855 | AL11: =IF(AND(U11=1,R11<>""),R11,"") | AM11: =A11&"-"&B11 -> BMG-2023
A12: BMG | B12: 2024 | C12: FiinTrade_..._BMG_20261018.xlsx | D12: 275980198004 | E12: 0.17963174 | F12: 178466849746 | G12: 110968220994 | H12: 19154911891 | I12: 20020000000 | J12: 45156721479 | K12: 13133441065 | L12: 31.714545 | M12: 64.140082 | N12: 34.455964 | O12: =IF(OR(D12="",E12=""),"",D12*(1-E12)) -> 2.2640539e+11 | P12: =IF(OR(H12="",D12=""),"",IF(D12<=0,"",(H12+N(I12))/D12)) -> 0.14194827 | Q12: =IF(OR(H12="",D12=""),"",IF(D12<=0,"",H12/D12)) -> 0.069406834 | R12: =IF(OR(A11<>A12,B12<=ThamSo!$C$22,H12="",H11="",D12=""),"",IF(D12<=0,"",(H12-H11)/D12)) -> 0.025587273 | S12: =INDEX(HoSoDN!$H$5:$H$32,MATCH(A12,HoSoDN!$A$5:$A$32,0)) -> FOB | T12: =INDEX(HoSoDN!$I$5:$I$32,MATCH(A12,HoSoDN!$A$5:$A$32,0)) -> Không | U12: =IF(AND(S12="FOB",T12<>"Có",B12>=ThamSo!$C$22,B12<=ThamSo!$C$23,D12<>"",E12<>"",G12<>"",P12<>"",L12<>"",M12<>"",N12<>""),IF(D12>=ThamSo!$C$11,1,0),0) -> 1 | V12: =IF(D12="","",IF(D12<=ThamSo!$C$12,"Nhỏ–vừa","Lớn")) -> Nhỏ–vừa | W12: =IF(D12="","",IF(OR(D12<=ThamSo!$C$13,F12<=ThamSo!$C$14),"Có","Không")) -> Không | X12: =IF(AND(T12<>"Có",M12<>"",D12<>""),IF(D12>=ThamSo!$C$11,M12,""),"") -> 64.140082 | Y12: =IF(U12=1,P12,"") -> 0.14194827 | Z12: =IF(AND(U12=1,V12="Nhỏ–vừa"),P12,"") -> 0.14194827 | AA12: =IF(AND(U12=1,V12="Lớn"),P12,"") | AB12: =IF(U12=1,L12,"") -> 31.714545 | AC12: =IF(AND(U12=1,V12="Nhỏ–vừa"),L12,"") -> 31.714545 | AD12: =IF(AND(U12=1,V12="Lớn"),L12,"") | AE12: =IF(U12=1,M12,"") -> 64.140082 | AF12: =IF(AND(U12=1,V12="Nhỏ–vừa"),M12,"") -> 64.140082 | AG12: =IF(AND(U12=1,V12="Lớn"),M12,"") | AH12: =IF(U12=1,N12,"") -> 34.455964 | AI12: =IF(AND(U12=1,V12="Nhỏ–vừa"),N12,"") -> 34.455964 | AJ12: =IF(AND(U12=1,V12="Lớn"),N12,"") | AK12: =IF(U12=1,Q12,"") -> 0.069406834 | AL12: =IF(AND(U12=1,R12<>""),R12,"") -> 0.025587273 | AM12: =A12&"-"&B12 -> BMG-2024
A13: BMG | B13: 2025 | C13: FiinTrade_..._BMG_20261018.xlsx | D13: 295940834048 | E13: 0.18565914 | F13: 190253004726 | G13: 113467882537 | H13: 11934241483 | I13: 335000000 | J13: 52315467227 | K13: 15332652459 | L13: 22.351583 | M13: 73.812934 | N13: 34.06861 | O13: =IF(OR(D13="",E13=""),"",D13*(1-E13)) -> 2.4099671e+11 | P13: =IF(OR(H13="",D13=""),"",IF(D13<=0,"",(H13+N(I13))/D13)) -> 0.041458427 | Q13: =IF(OR(H13="",D13=""),"",IF(D13<=0,"",H13/D13)) -> 0.040326444 | R13: =IF(OR(A12<>A13,B13<=ThamSo!$C$22,H13="",H12="",D13=""),"",IF(D13<=0,"",(H13-H12)/D13)) -> -0.024399034 | S13: =INDEX(HoSoDN!$H$5:$H$32,MATCH(A13,HoSoDN!$A$5:$A$32,0)) -> FOB | T13: =INDEX(HoSoDN!$I$5:$I$32,MATCH(A13,HoSoDN!$A$5:$A$32,0)) -> Không | U13: =IF(AND(S13="FOB",T13<>"Có",B13>=ThamSo!$C$22,B13<=ThamSo!$C$23,D13<>"",E13<>"",G13<>"",P13<>"",L13<>"",M13<>"",N13<>""),IF(D13>=ThamSo!$C$11,1,0),0) -> 1 | V13: =IF(D13="","",IF(D13<=ThamSo!$C$12,"Nhỏ–vừa","Lớn")) -> Nhỏ–vừa | W13: =IF(D13="","",IF(OR(D13<=ThamSo!$C$13,F13<=ThamSo!$C$14),"Có","Không")) -> Không | X13: =IF(AND(T13<>"Có",M13<>"",D13<>""),IF(D13>=ThamSo!$C$11,M13,""),"") -> 73.812934 | Y13: =IF(U13=1,P13,"") -> 0.041458427 | Z13: =IF(AND(U13=1,V13="Nhỏ–vừa"),P13,"") -> 0.041458427 | AA13: =IF(AND(U13=1,V13="Lớn"),P13,"") | AB13: =IF(U13=1,L13,"") -> 22.351583 | AC13: =IF(AND(U13=1,V13="Nhỏ–vừa"),L13,"") -> 22.351583 | AD13: =IF(AND(U13=1,V13="Lớn"),L13,"") | AE13: =IF(U13=1,M13,"") -> 73.812934 | AF13: =IF(AND(U13=1,V13="Nhỏ–vừa"),M13,"") -> 73.812934 | AG13: =IF(AND(U13=1,V13="Lớn"),M13,"") | AH13: =IF(U13=1,N13,"") -> 34.06861 | AI13: =IF(AND(U13=1,V13="Nhỏ–vừa"),N13,"") -> 34.06861 | AJ13: =IF(AND(U13=1,V13="Lớn"),N13,"") | AK13: =IF(U13=1,Q13,"") -> 0.040326444 | AL13: =IF(AND(U13=1,R13<>""),R13,"") -> -0.024399034 | AM13: =A13&"-"&B13 -> BMG-2025
A14: DCG | B14: 2023 | C14: FiinTrade_..._DM7_20261018.xlsx | D14: 554879911020 | E14: 0.22336446 | F14: 421387983406 | G14: 284808203569 | H14: 51053532229 | I14: 173667154043 | J14: 13826248956 | K14: 12336232260 | L14: 20.317411 | M14: 9.2933175 | N14: 8.3803209 | O14: =IF(OR(D14="",E14=""),"",D14*(1-E14)) -> 4.3093946e+11 | P14: =IF(OR(H14="",D14=""),"",IF(D14<=0,"",(H14+N(I14))/D14)) -> 0.40498977 | Q14: =IF(OR(H14="",D14=""),"",IF(D14<=0,"",H14/D14)) -> 0.092008255 | R14: =IF(OR(A13<>A14,B14<=ThamSo!$C$22,H14="",H13="",D14=""),"",IF(D14<=0,"",(H14-H13)/D14)) | S14: =INDEX(HoSoDN!$H$5:$H$32,MATCH(A14,HoSoDN!$A$5:$A$32,0)) -> CMT | T14: =INDEX(HoSoDN!$I$5:$I$32,MATCH(A14,HoSoDN!$A$5:$A$32,0)) -> Không | U14: =IF(AND(S14="FOB",T14<>"Có",B14>=ThamSo!$C$22,B14<=ThamSo!$C$23,D14<>"",E14<>"",G14<>"",P14<>"",L14<>"",M14<>"",N14<>""),IF(D14>=ThamSo!$C$11,1,0),0) -> 0 | V14: =IF(D14="","",IF(D14<=ThamSo!$C$12,"Nhỏ–vừa","Lớn")) -> Nhỏ–vừa | W14: =IF(D14="","",IF(OR(D14<=ThamSo!$C$13,F14<=ThamSo!$C$14),"Có","Không")) -> Không | X14: =IF(AND(T14<>"Có",M14<>"",D14<>""),IF(D14>=ThamSo!$C$11,M14,""),"") -> 9.2933175 | Y14: =IF(U14=1,P14,"") | Z14: =IF(AND(U14=1,V14="Nhỏ–vừa"),P14,"") | AA14: =IF(AND(U14=1,V14="Lớn"),P14,"") | AB14: =IF(U14=1,L14,"") | AC14: =IF(AND(U14=1,V14="Nhỏ–vừa"),L14,"") | AD14: =IF(AND(U14=1,V14="Lớn"),L14,"") | AE14: =IF(U14=1,M14,"") | AF14: =IF(AND(U14=1,V14="Nhỏ–vừa"),M14,"") | AG14: =IF(AND(U14=1,V14="Lớn"),M14,"") | AH14: =IF(U14=1,N14,"") | AI14: =IF(AND(U14=1,V14="Nhỏ–vừa"),N14,"") | AJ14: =IF(AND(U14=1,V14="Lớn"),N14,"") | AK14: =IF(U14=1,Q14,"") | AL14: =IF(AND(U14=1,R14<>""),R14,"") | AM14: =A14&"-"&B14 -> DCG-2023
A15: DCG | B15: 2024 | C15: FiinTrade_..._DM7_20261018.xlsx | D15: 731875404267 | E15: 0.24068147 | F15: 478123596170 | G15: 336718216466 | H15: 75596173316 | I15: 180256349726 | J15: 11600264321 | K15: 20228202016 | L15: 23.054359 | M15: 8.3500394 | N15: 7.7308265 | O15: =IF(OR(D15="",E15=""),"",D15*(1-E15)) -> 5.5572656e+11 | P15: =IF(OR(H15="",D15=""),"",IF(D15<=0,"",(H15+N(I15))/D15)) -> 0.34958481 | Q15: =IF(OR(H15="",D15=""),"",IF(D15<=0,"",H15/D15)) -> 0.10329104 | R15: =IF(OR(A14<>A15,B15<=ThamSo!$C$22,H15="",H14="",D15=""),"",IF(D15<=0,"",(H15-H14)/D15)) -> 0.033533906 | S15: =INDEX(HoSoDN!$H$5:$H$32,MATCH(A15,HoSoDN!$A$5:$A$32,0)) -> CMT | T15: =INDEX(HoSoDN!$I$5:$I$32,MATCH(A15,HoSoDN!$A$5:$A$32,0)) -> Không | U15: =IF(AND(S15="FOB",T15<>"Có",B15>=ThamSo!$C$22,B15<=ThamSo!$C$23,D15<>"",E15<>"",G15<>"",P15<>"",L15<>"",M15<>"",N15<>""),IF(D15>=ThamSo!$C$11,1,0),0) -> 0 | V15: =IF(D15="","",IF(D15<=ThamSo!$C$12,"Nhỏ–vừa","Lớn")) -> Nhỏ–vừa | W15: =IF(D15="","",IF(OR(D15<=ThamSo!$C$13,F15<=ThamSo!$C$14),"Có","Không")) -> Không | X15: =IF(AND(T15<>"Có",M15<>"",D15<>""),IF(D15>=ThamSo!$C$11,M15,""),"") -> 8.3500394 | Y15: =IF(U15=1,P15,"") | Z15: =IF(AND(U15=1,V15="Nhỏ–vừa"),P15,"") | AA15: =IF(AND(U15=1,V15="Lớn"),P15,"") | AB15: =IF(U15=1,L15,"") | AC15: =IF(AND(U15=1,V15="Nhỏ–vừa"),L15,"") | AD15: =IF(AND(U15=1,V15="Lớn"),L15,"") | AE15: =IF(U15=1,M15,"") | AF15: =IF(AND(U15=1,V15="Nhỏ–vừa"),M15,"") | AG15: =IF(AND(U15=1,V15="Lớn"),M15,"") | AH15: =IF(U15=1,N15,"") | AI15: =IF(AND(U15=1,V15="Nhỏ–vừa"),N15,"") | AJ15: =IF(AND(U15=1,V15="Lớn"),N15,"") | AK15: =IF(U15=1,Q15,"") | AL15: =IF(AND(U15=1,R15<>""),R15,"") | AM15: =A15&"-"&B15 -> DCG-2024
A16: DCG | B16: 2025 | C16: FiinTrade_..._DM7_20261018.xlsx | D16: 515338334088 | E16: 0.24777757 | F16: 360209847551 | G16: 245782632955 | H16: 3204618644 | I16: 152926174724 | J16: 10124390976 | K16: 18592465292 | L16: 38.724489 | M16: 10.227678 | N16: 14.651696 | O16: =IF(OR(D16="",E16=""),"",D16*(1-E16)) -> 3.8764905e+11 | P16: =IF(OR(H16="",D16=""),"",IF(D16<=0,"",(H16+N(I16))/D16)) -> 0.30296755 | Q16: =IF(OR(H16="",D16=""),"",IF(D16<=0,"",H16/D16)) -> 0.0062184752 | R16: =IF(OR(A15<>A16,B16<=ThamSo!$C$22,H16="",H15="",D16=""),"",IF(D16<=0,"",(H16-H15)/D16)) -> -0.14047384 | S16: =INDEX(HoSoDN!$H$5:$H$32,MATCH(A16,HoSoDN!$A$5:$A$32,0)) -> CMT | T16: =INDEX(HoSoDN!$I$5:$I$32,MATCH(A16,HoSoDN!$A$5:$A$32,0)) -> Không | U16: =IF(AND(S16="FOB",T16<>"Có",B16>=ThamSo!$C$22,B16<=ThamSo!$C$23,D16<>"",E16<>"",G16<>"",P16<>"",L16<>"",M16<>"",N16<>""),IF(D16>=ThamSo!$C$11,1,0),0) -> 0 | V16: =IF(D16="","",IF(D16<=ThamSo!$C$12,"Nhỏ–vừa","Lớn")) -> Nhỏ–vừa | W16: =IF(D16="","",IF(OR(D16<=ThamSo!$C$13,F16<=ThamSo!$C$14),"Có","Không")) -> Không | X16: =IF(AND(T16<>"Có",M16<>"",D16<>""),IF(D16>=ThamSo!$C$11,M16,""),"") -> 10.227678 | Y16: =IF(U16=1,P16,"") | Z16: =IF(AND(U16=1,V16="Nhỏ–vừa"),P16,"") | AA16: =IF(AND(U16=1,V16="Lớn"),P16,"") | AB16: =IF(U16=1,L16,"") | AC16: =IF(AND(U16=1,V16="Nhỏ–vừa"),L16,"") | AD16: =IF(AND(U16=1,V16="Lớn"),L16,"") | AE16: =IF(U16=1,M16,"") | AF16: =IF(AND(U16=1,V16="Nhỏ–vừa"),M16,"") | AG16: =IF(AND(U16=1,V16="Lớn"),M16,"") | AH16: =IF(U16=1,N16,"") | AI16: =IF(AND(U16=1,V16="Nhỏ–vừa"),N16,"") | AJ16: =IF(AND(U16=1,V16="Lớn"),N16,"") | AK16: =IF(U16=1,Q16,"") | AL16: =IF(AND(U16=1,R16<>""),R16,"") | AM16: =A16&"-"&B16 -> DCG-2025
A17: DM7 | B17: 2023 | C17: FiinTrade_..._DM7_20261018.xlsx | D17: 620231260463 | E17: 0.13704986 | F17: 496837922532 | G17: 333140259403 | H17: 15299677570 | I17: 0 | J17: 108189581639 | K17: 39614513924 | L17: 83.307468 | M17: 81.818822 | N17: 53.507638 | O17: =IF(OR(D17="",E17=""),"",D17*(1-E17)) -> 5.3522865e+11 | P17: =IF(OR(H17="",D17=""),"",IF(D17<=0,"",(H17+N(I17))/D17)) -> 0.024667698 | Q17: =IF(OR(H17="",D17=""),"",IF(D17<=0,"",H17/D17)) -> 0.024667698 | R17: =IF(OR(A16<>A17,B17<=ThamSo!$C$22,H17="",H16="",D17=""),"",IF(D17<=0,"",(H17-H16)/D17)) | S17: =INDEX(HoSoDN!$H$5:$H$32,MATCH(A17,HoSoDN!$A$5:$A$32,0)) -> FOB | T17: =INDEX(HoSoDN!$I$5:$I$32,MATCH(A17,HoSoDN!$A$5:$A$32,0)) -> Không | U17: =IF(AND(S17="FOB",T17<>"Có",B17>=ThamSo!$C$22,B17<=ThamSo!$C$23,D17<>"",E17<>"",G17<>"",P17<>"",L17<>"",M17<>"",N17<>""),IF(D17>=ThamSo!$C$11,1,0),0) -> 1 | V17: =IF(D17="","",IF(D17<=ThamSo!$C$12,"Nhỏ–vừa","Lớn")) -> Nhỏ–vừa | W17: =IF(D17="","",IF(OR(D17<=ThamSo!$C$13,F17<=ThamSo!$C$14),"Có","Không")) -> Không | X17: =IF(AND(T17<>"Có",M17<>"",D17<>""),IF(D17>=ThamSo!$C$11,M17,""),"") -> 81.818822 | Y17: =IF(U17=1,P17,"") -> 0.024667698 | Z17: =IF(AND(U17=1,V17="Nhỏ–vừa"),P17,"") -> 0.024667698 | AA17: =IF(AND(U17=1,V17="Lớn"),P17,"") | AB17: =IF(U17=1,L17,"") -> 83.307468 | AC17: =IF(AND(U17=1,V17="Nhỏ–vừa"),L17,"") -> 83.307468 | AD17: =IF(AND(U17=1,V17="Lớn"),L17,"") | AE17: =IF(U17=1,M17,"") -> 81.818822 | AF17: =IF(AND(U17=1,V17="Nhỏ–vừa"),M17,"") -> 81.818822 | AG17: =IF(AND(U17=1,V17="Lớn"),M17,"") | AH17: =IF(U17=1,N17,"") -> 53.507638 | AI17: =IF(AND(U17=1,V17="Nhỏ–vừa"),N17,"") -> 53.507638 | AJ17: =IF(AND(U17=1,V17="Lớn"),N17,"") | AK17: =IF(U17=1,Q17,"") -> 0.024667698 | AL17: =IF(AND(U17=1,R17<>""),R17,"") | AM17: =A17&"-"&B17 -> DM7-2023
... A19: DM7 | B19: 2025 | C19: FiinTrade_..._DM7_20261018.xlsx | D19: 741070971989 | E19: 0.16244957 | F19: 546179376122 | G19: 406303984542 | H19: 52146473943 | I19: 0 | J19: 87627616096 | K19: 54978209164 | L19: 112.89637 | M19: 55.712532 | N19: 36.144411 | O19: =IF(OR(D19="",E19=""),"",D19*(1-E19)) -> 6.2068431e+11 | P19: =IF(OR(H19="",D19=""),"",IF(D19<=0,"",(H19+N(I19))/D19)) -> 0.07036637 | Q19: =IF(OR(H19="",D19=""),"",IF(D19<=0,"",H19/D19)) -> 0.07036637 | R19: =IF(OR(A18<>A19,B19<=ThamSo!$C$22,H19="",H18="",D19=""),"",IF(D19<=0,"",(H19-H18)/D19)) -> -0.054495349 | S19: =INDEX(HoSoDN!$H$5:$H$32,MATCH(A19,HoSoDN!$A$5:$A$32,0)) -> FOB | T19: =INDEX(HoSoDN!$I$5:$I$32,MATCH(A19,HoSoDN!$A$5:$A$32,0)) -> Không | U19: =IF(AND(S19="FOB",T19<>"Có",B19>=ThamSo!$C$22,B19<=ThamSo!$C$23,D19<>"",E19<>"",G19<>"",P19<>"",L19<>"",M19<>"",N19<>""),IF(D19>=ThamSo!$C$11,1,0),0) -> 1 | V19: =IF(D19="","",IF(D19<=ThamSo!$C$12,"Nhỏ–vừa","Lớn")) -> Nhỏ–vừa | W19: =IF(D19="","",IF(OR(D19<=ThamSo!$C$13,F19<=ThamSo!$C$14),"Có","Không")) -> Không | X19: =IF(AND(T19<>"Có",M19<>"",D19<>""),IF(D19>=ThamSo!$C$11,M19,""),"") -> 55.712532 | Y19: =IF(U19=1,P19,"") -> 0.07036637 | Z19: =IF(AND(U19=1,V19="Nhỏ–vừa"),P19,"") -> 0.07036637 | AA19: =IF(AND(U19=1,V19="Lớn"),P19,"") | AB19: =IF(U19=1,L19,"") -> 112.89637 | AC19: =IF(AND(U19=1,V19="Nhỏ–vừa"),L19,"") -> 112.89637 | AD19: =IF(AND(U19=1,V19="Lớn"),L19,"") | AE19: =IF(U19=1,M19,"") -> 55.712532 | AF19: =IF(AND(U19=1,V19="Nhỏ–vừa"),M19,"") -> 55.712532 | AG19: =IF(AND(U19=1,V19="Lớn"),M19,"") | AH19: =IF(U19=1,N19,"") -> 36.144411 | AI19: =IF(AND(U19=1,V19="Nhỏ–vừa"),N19,"") -> 36.144411 | AJ19: =IF(AND(U19=1,V19="Lớn"),N19,"") | AK19: =IF(U19=1,Q19,"") -> 0.07036637 | AL19: =IF(AND(U19=1,R19<>""),R19,"") -> -0.054495349 | AM19: =A19&"-"&B19 -> DM7-2025
