Workbook

Sheet Quy_uoc_chung
A1: QUY ƯỚC CHUNG – SME LIQUIDITY COPILOT
A2: Mục | B2: Quy ước | C2: Giá trị (ô nhập) | D2: Ghi chú
A3: Kỳ tính N (ngày) | B3: Số ngày thực tế từ ngày đầu đến ngày cuối kỳ, tính cả hai đầu. | C3: 90 | D3: Dữ liệu mẫu: 03/07/2026–30/09/2026.
A4: Ngày chốt dữ liệu | B4: Mọi số dư và thông tin quan sát kết thúc tại ngày này. | C4: 46295 | D4: Không dùng thanh toán sau ngày chốt làm giảm số dư lịch sử.
A5: Phạm vi bản đặc tả | B5: Giữ cấu trúc v2: quy ước, bối cảnh ngành, công thức, ngưỡng, đầu ra, tính tay, đối chiếu, kết quả và dữ liệu. | C5: Chỉ bao gồm TV1: quy ước, bối cảnh, công thức, ngưỡng, hợp đồng output, diễn giải, mẫu kết quả, tính tay, đối chiếu, kiểm thử và dữ liệu. | D5: Đã loại nội dung thiết kế các tác vụ khác.
A6: Hai lớp dữ liệu | B6: Đặc tả đầy đủ và dữ liệu minh họa có phạm vi khác nhau. | D6: TV1_Tinh_tay dùng dữ liệu v2: trả toàn bộ một lần, chưa VAT, số dư cuối kỳ. Chỉ tiêu mở rộng cần thêm trường thì không tự tính bằng giả định ngầm.
A7: Số dư phải thu/phải trả | B7: Số dư còn lại sau các lần thanh toán và điều chỉnh đến ngày chốt. | D7: Không dùng toàn giá trị hóa đơn khi đã trả một phần. Xem T1-A01/A02 và TV1_Kiem_thu: hóa đơn 100, thu 40 → dư 60.
A8: Cơ sở thuế | B8: Tỷ số dùng AR/AP và doanh thu/mua chịu cùng cơ sở chưa VAT; dự báo tiền dùng số phải thu/trả thực tế gồm VAT. | D8: Thuế phải nộp/hoàn lập lịch riêng. VAT không mặc định 10% cho mọi giao dịch.
A9: Phương pháp số dư | B9: Bình quân ngày khi đủ lịch sử; bình quân đầu-cuối khi đủ hai thời điểm; cuối kỳ khi chỉ có snapshot. | D9: Không gọi số cuối kỳ là bình quân. DSO/DIO/DPO trong một CCC phải cùng phương pháp.
A10: Mẫu số bán/mua chịu | B10: Tách bán chịu và mua chịu khỏi giao dịch tiền mặt. | D10: Dữ liệu mẫu không có cờ bán/mua chịu. Kết quả minh họa giả định toàn bộ là bán/mua chịu. Khi có dữ liệu thực, bỏ giả định này.
A11: Tồn kho | B11: Chỉ ghi nhận tài sản thuộc quyền sở hữu. Tách NVL, BTP, TP, hàng hóa thương mại và HGC. | D11: HGC loại. Hàng đi đường tùy ngày chuyển quyền sở hữu. Thiếu loại/quyền sở hữu: chưa xác định, không mặc định NVL.
A12: Làm tròn | B12: Tính bằng số chưa làm tròn; chỉ định dạng đầu ra. | D12: Tiền VND làm tròn cuối; chỉ số ngày 1 số lẻ; lãi suất tài trợ 2 số lẻ. Không cộng các số ngày đã làm tròn để ra CCC.
A13: Phân tuần | B13: Tuần t từ ngày chốt + 7(t−1) + 1 đến ngày chốt + 7t. | C13: 13 | D13: Khoản sau 13 tuần vẫn lưu để thấy nghĩa vụ đáo hạn và tiền thu ngoài horizon.
A14: Đệm tiền | B14: Ngưỡng tối thiểu chủ doanh nghiệp xác nhận. | D14: Thiếu so với đệm khác số dư âm. Tiền phong tỏa/hạn chế không nằm trong tiền khả dụng.
A15: Ngưỡng và benchmark | B15: Ngưỡng 10/30/50% và 60/30/30 ngày là tham số thử nghiệm. | D15: Phải hiệu chỉnh theo hợp đồng/mô hình. Khoảng DN niêm yết khác phương pháp không dùng tự động kết luận tốt/xấu.
A16: Bản tính mẫu | B16: Các sheet D_* giữ dữ liệu giả lập v2; TV1_Doi_chieu dùng giá trị tham chiếu v2 đã lưu. | D16: Khớp tham chiếu chỉ xác minh tính số trên chế độ mẫu, không chứng minh đã chạy code mới cho toàn bộ đặc tả mở rộng.
A17: Trạng thái đầu ra | B17: ok = đủ và hợp lệ; provisional = tạm tính có giới hạn; missing_data = thiếu; invalid_data = lỗi; not_applicable = không áp dụng. | D17: Mẫu số 0 → không áp dụng; trường thiếu → thiếu dữ liệu. Số dư 0 hợp lệ nếu đã kiểm chứng tập dữ liệu.
A18: Mã chỉ tiêu | B18: T1/T2/T3/T4 xác định tác vụ. A/B/C... xác định nhóm, hai số cuối xác định mục. | D18: Mã chuyên sâu T1-B01 là DSO; T1-C03 là hành vi trễ thu. Các dòng tính tay v2 vẫn giữ tên và vị trí để bảo toàn công thức.
A19: Phê duyệt | B19: Mô phỏng trên bản sao. Chờ duyệt không sửa dữ liệu gốc. | D19: Giả lập thực thi chỉ sau chủ DN duyệt; lưu người duyệt, thời điểm, mã kịch bản và mã hành động.
A20: Giới hạn số liệu ngành | B20: Báo cáo dệt may của nhóm cung cấp bối cảnh, chưa thay thế kiểm chứng độc lập nguồn BCTC. | D20: Giữ nguồn phương pháp tại TV1_Du_lieu. Không tạo benchmark mới từ dữ liệu giả lập.

Sheet TV1_Boi_canh_nganh
A1: BỐI CẢNH NGÀNH VÀ CÁCH ĐẶC TẢ PHẢN ÁNH
A4: # | B4: Đặc điểm của SME dệt may | C4: Tác động lên chỉ số | D4: Cách đặc tả xử lý | E4: Công thức liên quan
A5: 1 | B5: F01 gia công CMT, có một phần FOB. Vải khách giao không thuộc DN. | C5: Cộng nhầm HGC làm DIO và tài sản bảo đảm tăng sai. | D5: Tách sở hữu từng lô; CMT/FOB đọc riêng khi có dữ liệu phân khúc. | E5: T1-A04; T1-D01; T1-D05
A6: 2 | B6: F01 thâm dụng lao động; tiền lương không phải AP thương mại. | C6: DPO trên COGS bị pha loãng bởi lương. | D6: Giữ DPO_cogs để đối chiếu, thêm DPO mua chịu; không gọi chỉ số nào là kỳ hạn được cấp. | E6: T1-B03; T1-B04; T1-E02
A7: 3 | B7: F02 là doanh nghiệp phân phối vải, không phải xưởng sản xuất. | C7: Vải là hàng thương mại của F02. Ngưỡng tuổi nguyên liệu của xưởng chưa chắc phù hợp. | D7: Áp ngưỡng theo loại hàng thương mại, mùa mua và thời gian nhập hàng. | E7: T1-D01; T1-D02; TV1_Nguong
A8: 4 | B8: Hàng nhập khẩu và hàng đi đường có ngày chuyển quyền sở hữu riêng. | C8: Có hàng trong kho chưa thuộc DN hoặc hàng chưa đến kho đã thuộc DN. | D8: Dùng hợp đồng/title_transfer_date; dự báo tỷ giá tại ngày tiền, không dùng một tỷ giá cho mọi mục đích. | E8: T1-A04; T2-G06
A9: 5 | B9: Khách hàng lớn áp kỳ hạn dài và có thể trả chậm. | C9: DSO cao chưa chứng minh vi phạm; tập trung làm rủi ro trễ thu lớn. | D9: Tách kỳ hạn, trễ dương, tuổi nợ và tập trung, đồng thời stress khách lớn. | E9: T1-C01..C04; T2-G06
A10: 6 | B10: Phụ liệu/thẻ bài theo thiết kế riêng có thể không dùng khi đơn hủy. | C10: Tuổi tồn cao là tín hiệu, không phải toàn bộ giá trị bị mất. | D10: Bổ sung nhu cầu/đơn hàng, NRV và tiền thanh lý thực tế. | E10: T1-D02..D04
A11: 7 | B11: DPO tăng có thể do không trả được nhà cung cấp. | C11: DPO dài có thể che AP quá hạn và ngừng cung ứng. | D11: Đo AP quá hạn và khoản phải trả NCC thiết yếu; không kết luận siết nợ chỉ từ kỳ hạn ngắn. | E11: T1-E01..E03
A12: 8 | B12: Lương, thuế, điện và nợ vay có ngày chi khác ngày khách trả. | C12: Cuối tuần còn tiền nhưng có thể thiếu đầu tuần. | D12: Dự báo theo ngày khi có event date; tách đệm tiền và số dư âm. | E12: T2-G03..G05
A13: 9 | B13: Bao thanh toán có phần giữ lại, phí và nghĩa vụ tùy hợp đồng. | C13: Tiền ứng danh nghĩa khác tiền sử dụng; tài trợ không tự rút ngắn vận hành. | D13: Tách bán phải thu/vay bảo đảm, loại dòng thu bị thay thế và ghi đầy đủ tất toán. | E13: T3-H02..H07
A14: 10 | B14: F01–F03 có vị trí khác nhau và dữ liệu mẫu được sinh độc lập. | C14: Không thể chứng minh lan truyền giữa các DN chỉ từ tên đối tác trùng. | D14: Ghép hóa đơn hai sổ trước khi mô phỏng chuỗi; không dùng benchmark niêm yết để xếp hạng tuyệt đối. | E14: T4-F06; T1-B07

Sheet TV1_Cong_thuc
A1: ĐẶC TẢ CÔNG THỨC – TÁC VỤ 1: CHẨN ĐOÁN VỐN LƯU ĐỘNG
A2: TV1: công thức dạng ký hiệu. Σ chỉ cộng dòng đã lọc đúng DN, kỳ/ngày chốt và quyền sở hữu. Xem TV1_Quy_uoc để ánh xạ trường và phân biệt dữ liệu mẫu với bản triển khai.
A4: ID | B4: Lớp | C4: Chỉ tiêu | D4: Ý nghĩa với chủ doanh nghiệp | E4: Công thức | F4: Đầu vào (file.cột) | G4: Điều kiện lọc | H4: Đơn vị, làm tròn | I4: Ngoại lệ
A5: A. Cơ sở dữ liệu và cách đo số dư
A6: T1-A01 | B6: A | C6: Phải thu thương mại còn lại | D6: Phải thu chưa thu, trước dự phòng. Không phải doanh thu; hóa đơn đã thu một phần chỉ tính dư còn lại. Thiếu bảng thanh toán: chế độ trả toàn bộ một lần chỉ hợp lệ khi trả toàn bộ một lần. | E6: AR_i = sales.amount_vnd − Σ payment_allocations.amount_net_vnd − Σ credit_notes.amount_net_vnd AR = Σ MAX(0; AR_i) | F6: sales_invoices: firm_id, invoice_id, issue_date, amount_net, credit_note; payments: allocation_id, invoice_id, payment_date, amount_net Đối chiếu tên trường và hiện trạng tại TV1_Du_lieu. | G6: Cùng firm_id; hóa đơn đã ghi nhận đến ngày chốt; cộng điều chỉnh/thanh toán đến ngày chốt; chọn dư dương. | H6: VND; làm tròn khi xuất Chỉ làm tròn đầu ra. | I6: Chỉ ghi nhận giao dịch đã phát sinh tại ngày chốt. R_i âm phải tách tiền khách trả thừa/ứng trước, không âm hóa AR. Có trả từng phần: không dùng paid_date nhị phân. Ưu tiên nền tảng.
A7: T1-A02 | B7: A | C7: Phải trả thương mại còn lại | D7: AP thương mại khác tổng nợ ngắn hạn. Không cộng nghĩa vụ tài chính vào DPO để làm chỉ số đẹp hơn. | E7: AP_i = purchases.amount_vnd − Σ payment_allocations.amount_net_vnd − Σ purchase_credits.amount_net_vnd AP = Σ MAX(0; AP_i) | F7: purchase_invoices + payment_allocations: cùng cấu trúc T1-A01; category, supplier_id Đối chiếu tên trường và hiện trạng tại TV1_Du_lieu. | G7: Cùng firm_id; nghĩa vụ mua hàng/dịch vụ thuộc phạm vi thương mại; dư dương tại ngày chốt. | H7: VND; làm tròn khi xuất Chỉ làm tròn đầu ra. | I7: Loại vay ngân hàng, thuế, lương và khoản không khớp mẫu số. Khoản ứng trước nhà cung cấp theo dõi riêng. Chỉ khoản đã ghi nhận tại ngày chốt. Ưu tiên nền tảng.
A8: T1-A03 | B8: A | C8: Số phải thu/phải trả dùng dự báo tiền | D8: Không tự giả định VAT 10% cho mọi hàng hóa. | E8: AR_cash_i = sales.amount_gross_vnd − Σ receipts.amount_gross_vnd − Σ credits.amount_gross_vnd AP_cash_i = purchases.amount_gross_vnd − Σ payments.amount_gross_vnd − Σ credits.amount_gross_vnd | F8: gross_amount, tax_amount, net_amount, payment_allocations theo cơ sở gross/net Đối chiếu tên trường và hiện trạng tại TV1_Du_lieu. | G8: Cùng hóa đơn và ngày chốt với T1-A01/T1-A02; dùng cơ sở gồm VAT cho các sự kiện tiền. | H8: VND gồm VAT Chỉ làm tròn đầu ra. | I8: Chẩn đoán tỷ số dùng net đồng nhất; lịch thu/chi dùng gross gồm VAT và khấu trừ thực tế. Thuế phải nộp hoàn lại lập lịch riêng, không khấu trừ hai lần. Ưu tiên nền tảng.
A9: T1-A04 | B9: A | C9: Tồn kho thuộc sở hữu và giá trị ghi sổ | D9: NRV là giá trị thuần có thể thực hiện. Giảm giá trị ghi sổ không tạo tiền. IFRS IAS 2 là tham chiếu phương pháp, cần ánh xạ chế độ kế toán DN áp dụng. | E9: INV_cost_l = inventory.qty × inventory.unit_cost_vnd NRV_l = qty × MAX(0; selling_price_net_vnd − completion_cost_unit_vnd − selling_cost_unit_vnd) INV_book_l = MIN(INV_cost_l; NRV_l) INV = Σ INV_book_l | F9: inventory: lot_id, inventory_type, ownership, qty, unit_cost, location, NRV inputs, title_transfer_date Đối chiếu tên trường và hiện trạng tại TV1_Du_lieu. | G9: Lô thuộc quyền sở hữu DN tại ngày chốt; tách hàng khách giao và hàng chưa rõ quyền sở hữu. | H9: VND; qty theo UOM Chỉ làm tròn đầu ra. | I9: HGC thuộc khách hàng loại khỏi tài sản. Hàng đi đường chỉ cộng khi đã thuộc DN. Thiếu ownership hoặc loại: chưa xác định, không tự coi NVL. Thiếu NRV: dùng cost có nhãn tạm tính. Ưu tiên nền tảng.
A10: T1-A05 | B10: A | C10: Mẫu số bán chịu và mua chịu | D10: S_total chỉ dùng làm proxy có nhãn khi chưa tách bán chịu. PUR_total chỉ dùng proxy khi chưa tách mua chịu. | E10: Rev = financials.revenue_vnd Rev_credit = Σ sales.amount_vnd [is_credit = true] COGS = financials.cogs_vnd PUR = Σ purchases.amount_vnd [issue_date ∈ period] PUR_credit = Σ purchases.amount_vnd [is_credit = true] N = period_end − period_start + 1 | F10: financials, sales ledger: credit_sale, revenue_recognition_date; purchases: credit_purchase, category Đối chiếu tên trường và hiện trạng tại TV1_Du_lieu. | G10: Ngày ghi nhận trong kỳ N; bán chịu/mua chịu; cùng phạm vi số dư; không lấy ngày tiền để lọc doanh thu. | H10: VND; N là ngày Chỉ làm tròn đầu ra. | I10: N = end − start + 1. Không mặc nhiên mọi hóa đơn là bán chịu/mua chịu. Hóa đơn không đồng nghĩa ngày ghi doanh thu. COGS phải cùng kỳ. Ưu tiên nền tảng.
A11: T1-A06 | B11: A | C11: Số dư bình quân và phương pháp snapshot | D11: Snapshot cho biết mức vốn đang tồn tại so với tốc độ kinh doanh vừa qua. Không kết luận mỗi hóa đơn mất đúng từng đó ngày để thu. | E11: AR_avg = Σ AR_end_of_day / N AR_avg_2 = (AR_open + AR_close) / 2 AR_snapshot = AR_close INV_avg, AP_avg: áp dụng cùng quy tắc. | F11: daily_balances hoặc opening/closing balances, method, coverage_days Đối chiếu tên trường và hiện trạng tại TV1_Du_lieu. | G11: Cùng tài khoản, DN, cơ sở kế toán và kỳ; ngày thiếu không tự coi số dư bằng 0. | H11: VND bình quân Chỉ làm tròn đầu ra. | I11: Bình quân ngày ưu tiên khi đủ lịch sử. Bình quân đầu-cuối cần cả hai điểm. Chỉ có cuối kỳ: gắn số dư tại ngày chốt, không dựng số bình quân. Ưu tiên nền tảng.
A12: B. Chu kỳ vận hành và hiệu quả sử dụng vốn
A13: T1-B01 | B13: B | C13: DSO bán chịu và DSO snapshot | D13: DSO cao có thể do kỳ hạn dài, nợ quá hạn hoặc mùa vụ. Cần đọc với tuổi nợ và lịch sử thu, không đồng nhất với thời gian thực tế từng hóa đơn. | E13: DSO = AR / Rev × N [mẫu v2] DSO_credit = AR_selected / Rev_credit × N [đã tách bán chịu] AR_selected = AR_avg hoặc AR_avg_2 hoặc AR_snapshot | F13: T1-A01,T1-A05,T1-A06 Đối chiếu tên trường và hiện trạng tại TV1_Du_lieu. | G13: AR và doanh thu cùng cơ sở chưa VAT; mẫu số bán chịu; một phương pháp số dư nhất quán. | H13: Ngày; 1 số lẻ Chỉ làm tròn đầu ra. | I13: S_credit=0 → không áp dụng; thiếu → thiếu dữ liệu; âm → dữ liệu không hợp lệ. Chọn một phương pháp nhất quán và ghi vào output. Ưu tiên nền tảng.
A14: T1-B02 | B14: B | C14: DIO và vốn trong sản xuất | D14: DIO giảm do ghi giảm tồn kho có thể là tổn thất, không phải vận hành tốt hơn. CMT có DIO thấp vì nguyên liệu thuộc khách. | E14: DIO = INV / COGS × N DIO_cost = INV_cost / COGS × N DIO_book = INV_book / COGS × N | F14: T1-A04,T1-A06, financials.cogs_net Đối chiếu tên trường và hiện trạng tại TV1_Du_lieu. | G14: Tồn kho sở hữu và COGS cùng kỳ; chọn giá gốc/ghi sổ rõ ràng. | H14: Ngày; 1 số lẻ Chỉ làm tròn đầu ra. | I14: COGS=0: không áp dụng. Hàng khách giao loại. Báo riêng DIO_cost và tác động ghi giảm nếu đã giảm giá trị. Ưu tiên nền tảng.
A15: T1-B03 | B15: B | C15: DPO trên giá vốn để đối chiếu CCC | D15: Lương làm COGS lớn nhưng không làm AP thương mại lớn: DPO_cogs bị pha loãng ở xưởng may thâm dụng lao động. | E15: DPO = AP / COGS × N AP = AP_trade_selected | F15: T1-A02,T1-A06, COGS Đối chiếu tên trường và hiện trạng tại TV1_Du_lieu. | G15: AP thương mại và COGS cùng kỳ; cùng phương pháp số dư với DSO/DIO. | H15: Ngày; 1 số lẻ Chỉ làm tròn đầu ra. | I15: AP và COGS cùng phạm vi vận hành. Cho phép giữ công thức đề án để đối chiếu, nêu rõ mẫu số COGS. Không gọi chuẩn duy nhất cho mọi ngành. Ưu tiên nền tảng.
A16: T1-B04 | B16: B | C16: DPO trên mua chịu | D16: Đọc cùng kỳ hạn hợp đồng và quá hạn. Đây vẫn là tỷ số tồn lượng/lưu lượng, không phải số ngày được phép nợ theo hợp đồng. | E16: DPO_PUR = AP / PUR × N [mẫu v2 giả định mua chịu] DPO_credit_PUR = AP / PUR_credit × N [cùng phạm vi AP] | F16: T1-A02,T1-A05,T1-A06 Đối chiếu tên trường và hiện trạng tại TV1_Du_lieu. | G16: AP và mua chịu cùng phạm vi hàng/dịch vụ; cùng phương pháp số dư. | H16: Ngày; 1 số lẻ Chỉ làm tròn đầu ra. | I16: Cùng loại hàng/dịch vụ AP và mua chịu; không dùng toàn mua có tiền mặt. PUR_credit=0 → không áp dụng. Ưu tiên nền tảng.
A17: T1-B05 | B17: B | C17: Chu kỳ chuyển đổi tiền mặt có nhãn mẫu số | D17: CCC âm không tự động là tốt: có thể do chậm trả nhà cung cấp. Chênh lệch hai CCC giúp thấy ảnh hưởng cấu trúc giá vốn. | E17: CCC = DSO + DIO − DPO CCC_PUR = DSO + DIO − DPO_PUR | F17: T1-B01–T1-B04 Đối chiếu tên trường và hiện trạng tại TV1_Du_lieu. | G17: DSO/DIO/DPO đều đủ dữ liệu; cùng kỳ và phương pháp số dư. | H17: Ngày; 1 số lẻ Chỉ làm tròn đầu ra. | I17: Không trộn average với snapshot. CCC_purchase là biến thể dùng mẫu số mua chịu; luôn gắn label. Tính chưa làm tròn rồi xuất 0,1 ngày. Ưu tiên nền tảng.
A18: T1-B06 | B18: B | C18: Đóng góp theo đối tác và dòng hàng | D18: Đóng góp lớn phản ánh quy mô số dư, chưa chứng minh khách đó gây chậm thu. Kèm tỷ trọng quá hạn, lịch sử trễ và hợp đồng. | E18: DSO_k = AR_k / Rev × N DIO_l = INV_l / COGS × N DPO_s = AP_s / COGS × N Σ DSO_k = DSO; Σ DIO_l = DIO; Σ DPO_s = DPO | F18: T1-A01,T1-A02,T1-A04 + buyer/supplier/product_line Đối chiếu tên trường và hiện trạng tại TV1_Du_lieu. | G18: Nhóm theo buyer/supplier/product_line; mẫu số không đổi giữa các đối tượng. | H18: Ngày; 1 số lẻ Chỉ làm tròn đầu ra. | I18: Mọi đóng góp cùng phương pháp và mẫu số với tổng. Σ đóng góp phải bằng chỉ tiêu tổng. Nếu average: dùng số dư đối tượng bình quân. Ưu tiên nền tảng.
A19: T1-B07 | B19: B | C19: Xu hướng, mùa vụ và so sánh ngang | D19: Khoảng tham chiếu DN niêm yết chỉ tham khảo, không dùng tự động gắn tốt/xấu cho ba SME khác vị trí chuỗi cung ứng. | E19: ΔDSO = DSO_current − DSO_previous ΔCCC = CCC_current − CCC_previous ΔCCC = ΔDSO + ΔDIO − ΔDPO benchmark_gap = value − comparable_reference | F19: monthly_balances, business_model, historical revenues/cogs, peer_method Đối chiếu tên trường và hiện trạng tại TV1_Du_lieu. | G19: Kỳ trước/cùng mùa/nhóm đối chiếu cùng cơ sở, mô hình kinh doanh và phương pháp. | H19: Ngày; phân vị % Chỉ làm tròn đầu ra. | I19: Đồng nhất kỳ, phương pháp, net/gross, ngành và mô hình CMT/FOB/thương mại. Thiếu peer phù hợp: unverified_benchmark. Phân tích nâng cao, cần thêm dữ liệu.
A20: C. Chất lượng phải thu và hành vi thanh toán
A21: T1-C01 | B21: C | C21: Tuổi nợ và tỷ lệ phải thu quá hạn | D21: Phân biệt ngày từ phát hành với số ngày quá hạn. Nợ quá hạn nhỏ và nợ lớn phải được thấy riêng. | E21: DPD_i = MAX(0; as_of − sales.due_date) AR_overdue = Σ AR_i [DPD_i > 0] overdue_share = AR_overdue / AR aging_b = Σ AR_i [DPD_i ∈ bucket_b] | F21: T1-A01,due_date, disputed_status Đối chiếu tên trường và hiện trạng tại TV1_Du_lieu. | G21: Hóa đơn bán còn dư tại ngày chốt; phân nhóm theo due_date; dư tiền cùng cơ sở AR. | H21: Ngày; VND; % Chỉ làm tròn đầu ra. | I21: Đúng due_date tại ngày chốt là chưa quá hạn. Phân bổ dư còn lại, không face value. AR=0: share không áp dụng, số tiền 0. Ưu tiên nền tảng.
A22: T1-C02 | B22: C | C22: Kỳ hạn thương mại và thời gian thu thực tế | D22: C02 đo thời gian thực tế các phần đã thu. Mẫu đã trả có thể thiên lệch vì bỏ nợ chưa trả; đọc cùng C01. | E22: terms_wavg = Σ(invoice_amount × (due_date − issue_date)) / Σ invoice_amount collection_days_wavg = Σ(receipt_allocated × (paid_date − issue_date)) / Σ receipt_allocated | F22: payment_allocations,issue_date,due_date; kỳ cấp tín dụng và kỳ nhận tiền tách nhau Đối chiếu tên trường và hiện trạng tại TV1_Du_lieu. | G22: Kỳ hạn: nhóm hóa đơn phát hành trong kỳ. Thời gian thu: các phần thanh toán trong cửa sổ lịch sử. | H22: Ngày; 1 số lẻ Chỉ làm tròn đầu ra. | I22: Terms dùng cohort hóa đơn phát hành trong kỳ. Collection dùng khoản thanh toán trong cửa sổ lịch sử; từng phần lấy ngày thu riêng. Báo n và giá trị mẫu. Ưu tiên nền tảng.
A23: T1-C03 | B23: C | C23: Trễ dương, trả sớm và trễ có dấu | D23: Signed phù hợp mô tả tổng quát; Late_pos phù hợp cảnh báo. | E23: late_positive_wavg = Σ(receipt_allocated × MAX(0; paid_date − due_date)) / Σ receipt_allocated early_wavg = Σ(receipt_allocated × MAX(0; due_date − paid_date)) / Σ receipt_allocated late_signed_wavg = late_positive_wavg − early_wavg | F23: payment_allocations: gross/net nhất quán trong trọng số; buyer_id; lookback 180 ngày Đối chiếu tên trường và hiện trạng tại TV1_Du_lieu. | G23: Thanh toán đã xảy ra trong cửa sổ lookback, có ngày phát hành và đến hạn; nhóm theo khách. | H23: Ngày; 1 số lẻ Chỉ làm tròn đầu ra. | I23: Không bù khách trả sớm vào trễ dương. Chỉ dùng dữ liệu biết tại ngày chốt. Báo số hóa đơn độc lập, không đếm từng payment như một invoice. Ưu tiên nền tảng.
A24: T1-C04 | B24: C | C24: Tập trung và phụ thuộc khách hàng | D24: HHI gần 1 là rất tập trung. Tập trung phải thu và tập trung tiền về trong 13 tuần cùng cao làm thanh khoản dễ bị ảnh hưởng. | E24: AR_share_k = AR_k / AR Top1_share = MAX(AR_share_k) Top3_share = Σ 3 AR_share_k lớn nhất HHI = Σ AR_share_k² | F24: T1-A01 + forecast receipts by buyer Đối chiếu tên trường và hiện trạng tại TV1_Du_lieu. | G24: AR theo cùng ngày chốt; tiền dự báo theo cùng 13 tuần; tách bán chịu với doanh thu tổng. | H24: %; HHI từ 0–1 Chỉ làm tròn đầu ra. | I24: AR=0: HHI không áp dụng. Mặc định Top1>50% chỉ là cờ giả lập, không ngưỡng ngành. Phân biệt tập trung AR với tập trung doanh thu. Ưu tiên nền tảng.
A25: T1-C05 | B25: C | C25: Tranh chấp, chất lượng thu và tổn thất dự kiến | D25: Nợ tranh chấp cần lịch riêng. Tổn thất kỳ vọng phản ánh khả năng mất tiền, không quyết định chính xác ngày thu. | E25: AR_flagged = Σ AR_i [disputed / cancelled / default_flag] scenario_loss = Σ AR_at_risk_i × PD_i × LGD_i | F25: dispute_flag, dispute_amount, resolution_date, scenario_pd, scenario_lgd, recoveries Đối chiếu tên trường và hiện trạng tại TV1_Du_lieu. | G25: Cờ tranh chấp có số tiền cụ thể; PD/LGD có nguồn hoặc giả định công khai. | H25: VND; PD/LGD % Chỉ làm tròn đầu ra. | I25: PD/LGD chỉ dùng khi có cơ sở hoặc giả định công khai; không suy từ DPD đơn lẻ. Không gọi scenario_loss là dự phòng IFRS 9 đã xác lập. Phân tích nâng cao, cần thêm dữ liệu.
A26: T1-C06 | B26: C | C26: Thu hồi theo cohort và độ đầy đủ lịch sử | D26: Khắc phục thiên lệch chỉ dùng hóa đơn đã thanh toán. Ít lịch sử: dùng giả định bảo thủ có nhãn thay vì chắc chắn. | E26: collection_rate_h = receipts_within_h / cohort_invoice_amount coverage = eligible_observed_amount / total_scope_amount | F26: issue cohort, payments đến as_of, horizon h Đối chiếu tên trường và hiện trạng tại TV1_Du_lieu. | G26: Nhóm phát hành đã đủ tuổi h; tất cả thanh toán quan sát được đến ngày chốt. | H26: %; h là ngày Chỉ làm tròn đầu ra. | I26: Chỉ cohort đủ tuổi h mới dùng làm mẫu tại h; báo n và coverage. Không coi hóa đơn mới là chưa thu thành thất bại. Phân tích nâng cao, cần thêm dữ liệu.
A27: D. Chất lượng tồn kho và khả năng chuyển thành tiền
A28: T1-D01 | B28: D | C28: Cơ cấu vốn trong tồn kho | D28: BTP cao có thể do nghẽn chuyền; TP cao có thể do chờ giao; thương mại cao có thể do mua trước mùa. Không suy kết luận từ tuổi duy nhất. | E28: INV_l = Σ qty × unit_cost_vnd [mẫu v2: giá gốc, thuộc sở hữu] INV_share_l = INV_l / INV age_wavg_l = Σ(INV_lot × days_in_stock) / Σ INV_lot | F28: T1-A04,receipt_date,production_stage_date, inventory_type Đối chiếu tên trường và hiện trạng tại TV1_Du_lieu. | G28: Chỉ hàng sở hữu; nhóm theo NVL/BTP/TP/hàng hóa thương mại; thống nhất cách tính tuổi. | H28: VND; %; ngày Chỉ làm tròn đầu ra. | I28: NVL/BTP/TP/HGC và trade_goods tách rõ. F02 vải để bán là hàng thương mại; không mặc định nguyên liệu sản xuất của F02. Ưu tiên nền tảng.
A29: T1-D02 | B29: D | C29: Hàng chậm luân chuyển và hàng không có nhu cầu | D29: Tồn lâu không đồng nghĩa toàn bộ tiền sẽ mất. Tuổi hàng và ngày không có vận động là hai chỉ số khác nhau. | E29: INV_slow = Σ INV_lot [days_in_stock > slow_threshold_days] slow_share = INV_slow / INV INV_no_demand = Σ INV_lot [committed_demand + forecast_demand = 0] | F29: age, last_movement_date, order_id, demand_forecast, threshold by type/model Đối chiếu tên trường và hiện trạng tại TV1_Du_lieu. | G29: Chỉ hàng sở hữu; ngưỡng theo loại và mô hình DN; xét riêng đơn hủy/hàng hư hỏng. | H29: VND; % Chỉ làm tròn đầu ra. | I29: Ngưỡng 60/30/30 ngày là giả định demo. Theo dõi cancelled_order, customer_specific, damaged riêng. INV=0: tỷ lệ không áp dụng. Ưu tiên nền tảng.
A30: T1-D03 | B30: D | C30: Độ phủ nhu cầu và tồn vượt nhu cầu | D30: Ưu tiên hàng excess cao và thiếu đơn hàng. Chỉ tiêu giúp phân biệt dự trữ hợp lý với vốn bị giam do đơn hủy. | E30: weeks_cover = usable_qty / weekly_demand excess_qty = MAX(0; usable_qty − horizon_demand − safety_stock) | F30: SKU, UOM, usable_qty, firm_orders, demand_per_week, lead_time, safety_stock Đối chiếu tên trường và hiện trạng tại TV1_Du_lieu. | G30: Từng SKU và UOM; lượng có thể sử dụng; nhu cầu trong kỳ và tồn an toàn đã xác định. | H30: Tuần; lượng theo UOM Chỉ làm tròn đầu ra. | I30: Không cộng số lượng khác đơn vị. demand=0: no_demand, không trả 0 tuần. Mức tồn an toàn cần căn cứ lead time, không mặc định 0. Phân tích nâng cao, cần thêm dữ liệu.
A31: T1-D04 | B31: D | C31: Giảm giá trị và tiền thu khi thanh lý | D31: Giảm 100 triệu tồn không bảo đảm thu 100 triệu. Tách thanh lý, tiết giảm mua tương lai và tiêu thụ bình thường để không đếm trùng. | E31: write_down = MAX(0; INV_cost − NRV) cash_from_write_down = 0 liquidation_cash = qty_sold × price_gross − selling_cash_cost liquidation_loss = book_value_sold − revenue_net + selling_cost_net | F31: NRV inputs, liquidation_price, sale_date, payment_date, VAT schedule Đối chiếu tên trường và hiện trạng tại TV1_Du_lieu. | G31: Lô được chọn thanh lý/ghi giảm; ngày thu và chi thực tế của kịch bản. | H31: VND; ngày thu/chi Chỉ làm tròn đầu ra. | I31: HGC không bán/pledge. Ghi giảm sổ sách: không phát sinh tiền. Bán thanh lý: tạo sự kiện thu thực tế theo ngày và chi phí. Ưu tiên nền tảng.
A32: T1-D05 | B32: D | C32: Tồn kho đủ điều kiện làm bảo đảm | D32: Tồn kho cao chưa chắc vay được nhiều. Giá trị thẩm định khác cost và NRV. Haircut chỉ áp một lần theo định nghĩa catalogue. | E32: eligible_value = Σ appraised_value_l [eligible = true] remaining_capacity = MAX(0; Σ(appraised_value_l × advance_rate_l) − secured_outstanding) | F32: ownership, lien_id, appraisal, insurance, location, ageing, provider rules Đối chiếu tên trường và hiện trạng tại TV1_Du_lieu. | G32: Hàng được nhà tài trợ chấp nhận, quyền sở hữu rõ và chưa sử dụng hết làm bảo đảm. | H32: VND Chỉ làm tròn đầu ra. | I32: Hàng đi đường, chuyên biệt, hư hỏng chỉ đủ điều kiện nếu catalogue chấp nhận. Không lấy toàn INV làm tài sản bảo đảm. Ưu tiên nền tảng.
A33: E. Nghĩa vụ nhà cung cấp và áp lực thanh toán
A34: T1-E01 | B34: E | C34: AP đến hạn, quá hạn và tỷ lệ quá hạn | D34: DPO cao kèm AP quá hạn cao là kéo dài nợ ngoài thỏa thuận. Không gọi đó là tối ưu vốn. | E34: AP_overdue = Σ AP_i [due_date < as_of] AP_due_h = Σ AP_cash_i [as_of ≤ due_date ≤ as_of + h] AP_overdue_share = AP_overdue / AP | F34: T1-A02,T1-A03,due_date, agreed_extension_date Đối chiếu tên trường và hiện trạng tại TV1_Du_lieu. | G34: Dư AP thương mại tại ngày chốt; due_date đã được hai bên chấp thuận; gross cho lịch tiền. | H34: VND; % Chỉ làm tròn đầu ra. | I34: Giãn hạn chỉ thay lịch cơ sở khi nhà cung cấp đã đồng ý. Khoản đến hạn đúng ngày chốt chưa quá hạn nhưng phải nằm trong nghĩa vụ thanh toán ngay. AP = 0: tỷ lệ không áp dụng. Ưu tiên nền tảng.
A35: T1-E02 | B35: E | C35: Kỳ hạn được cấp và hành vi trả nhà cung cấp | D35: Không suy DPO_purchase−Terms là số ngày vi phạm chính xác: đây là hai thống kê khác loại. Vi phạm phải đọc từ E01/E02. | E35: supplier_terms_wavg = Σ(purchase_amount × (due_date − issue_date)) / Σ purchase_amount payment_late_wavg = Σ(payment_allocated × MAX(0; paid_date − due_date)) / Σ payment_allocated | F35: purchase cohorts,payment_allocations,supplier_id,lookback Đối chiếu tên trường và hiện trạng tại TV1_Du_lieu. | G35: Kỳ hạn: hóa đơn mua chịu phát hành trong kỳ. Trễ: khoản thanh toán trong lịch sử. | H35: Ngày; 1 số lẻ Chỉ làm tròn đầu ra. | I35: Terms cùng cohort phát hành; paid_late cùng cohort thanh toán. Phân tích nhà cung cấp thiết yếu riêng. Ưu tiên nền tảng.
A36: T1-E03 | B36: E | C36: Nhà cung cấp thiết yếu và nguy cơ ngừng cung ứng | D36: Ưu tiên theo nghĩa vụ và tác động vận hành. nhà cung cấp kỳ hạn dưới 30 ngày chưa đủ chứng minh đang siết nợ. | E36: critical_due_h = Σ AP_cash_i [critical_supplier; due_date ≤ as_of + h] purchase_share_s = PUR_s / PUR | F36: critical_flag, substitute_lead_days, minimum_payment, stop_supply_date, purchases Đối chiếu tên trường và hiện trạng tại TV1_Du_lieu. | G36: NCC được xác định thiết yếu; khoản cần trả trong h ngày; cùng phạm vi mua để tính tỷ trọng. | H36: VND; %; ngày Chỉ làm tròn đầu ra. | I36: Cờ critical do nghiệp vụ xác nhận. Lương, điện và vận tải cũng có thể là chi bắt buộc nhưng không gộp AP thương mại. Ưu tiên nền tảng.
A37: T1-E04 | B37: E | C37: Chiết khấu trả sớm và chi phí bỏ qua | D37: So lợi ích tiền với chi phí vay cùng thời hạn và rủi ro thiếu tiền. Annualization chỉ quy đổi, không chứng minh cơ hội tái đầu tư cả năm. | E37: saving = discount_base × d early_cash_required = discount_base × (1 − d) days_early = due_date − early_payment_date simple_annual_rate = d / (1 − d) × 365 / days_early EAR = (1 / (1 − d))^(365 / days_early) − 1 | F37: amount eligible, discount_pct, deadline, due_date, day_basis B, payment plan Đối chiếu tên trường và hiện trạng tại TV1_Du_lieu. | G37: Hóa đơn còn dư, thời hạn chiết khấu chưa hết tại ngày trả dự kiến; chỉ phần đủ điều kiện. | H37: VND; %/năm Chỉ làm tròn đầu ra. | I37: Δdays=due−discount_payment_date>0; deadline≥feasible pay date. d∈[0,1). Phí và thuế thực tế cộng lịch riêng. Ưu tiên nền tảng.
A38: F. Nhu cầu vốn và khả năng chi trả
A39: T1-F01 | B39: F | C39: Vốn lưu động thương mại thuần | D39: TWC không bằng tiền bị kẹt chắc chắn và không bằng khoản vay cần ngay. Khoản phải thu có thể chưa đến hạn, tồn kho có thể phục vụ đơn đã ký. | E39: TWC = AR + INV − AP TWC_extended = TWC + supplier_advances − customer_advances NWC_enterprise = current_assets − current_liabilities | F39: T1-A01,T1-A02,T1-A04,prepayments,advances Đối chiếu tên trường và hiện trạng tại TV1_Du_lieu. | G39: AR/AP theo chưa VAT; INV sở hữu; khoản ứng trước và khách ứng trước phân loại riêng. | H39: VND Chỉ làm tròn đầu ra. | I39: Đổi tên NWC v2 thành TWC. NWC tổng quát = current_assets−current_liabilities cần toàn bảng cân đối. Ưu tiên nền tảng.
A40: T1-F02 | B40: F | C40: Độ nhạy vốn theo từng ngày | D40: Không dùng CCC×COGS/ngày để thay TWC: AR tính trên doanh thu, inventory/AP dùng cơ sở khác. Tác động tiền phải kiểm bằng I01. | E40: Rev_day = Rev / N COGS_day = COGS / N PUR_day = PUR / N cash_per_1_day_DSO = Rev_day cash_per_1_day_DIO = COGS_day cash_per_1_day_DPO = COGS_day equivalent_capital = improvement_days × cash_per_1_day | F40: T1-A05,T1-B01–T1-B04 Đối chiếu tên trường và hiện trạng tại TV1_Du_lieu. | G40: Lưu lượng cùng kỳ N; mẫu số đúng với DSO/DIO/loại DPO. | H40: VND / ngày Chỉ làm tròn đầu ra. | I40: Là xấp xỉ hoạt động ổn định, cố định lưu lượng. Chọn đúng mẫu số DPO. Không hạch toán trực tiếp vào forecast nếu chưa thay lịch. Ưu tiên nền tảng.
A41: T1-F03 | B41: F | C41: Tiền khả dụng và hạn mức còn rút được | D41: Tài khoản có tiền nhưng bị phong tỏa không dùng trả lương được. Cash_available và borrowing_capacity báo riêng. | E41: available_cash = reconciled_cash − restricted_cash undrawn_committed_limit = MAX(0; committed_limit − drawn_amount − blocked_amount) | F41: bank_balances,restrictions,debt limits,covenant status Đối chiếu tên trường và hiện trạng tại TV1_Du_lieu. | G41: Tiền đã đối chiếu tại ngày chốt; hạn mức cam kết còn khả dụng và không vi phạm điều kiện. | H41: VND Chỉ làm tròn đầu ra. | I41: opening_cash của financials phải là số tại ngày chốt để mở forecast, không đầu kỳ 90 ngày. Hạn mức chưa cam kết không coi như tiền. Ưu tiên nền tảng.
...

Sheet TV1_Nguong
A1: THAM SỐ VÀ NGƯỠNG – GIÁ TRỊ THỬ NGHIỆM
A2: Chữ xanh là ô nhập. Ngưỡng cảnh báo là giả định thử nghiệm, không phải chuẩn ngành đã xác minh.
A3: Tham số | B3: Mã | C3: Giá trị | D3: Đơn vị | E3: Lý do đề xuất
A4: Cửa sổ lịch sử thanh toán | B4: lookback | C4: 180 | D4: ngày | E4: Đủ 2 quý để thấy thói quen trả của khách, không quá cũ.
A5: Ngưỡng trễ bình quân để gắn cờ | B5: late | C5: 10 | D5: ngày | E5: Dùng trễ dương ở đặc tả đầy đủ. Bảng mẫu v2 vẫn có trễ có dấu; xem phần bổ sung tại TV1_Tinh_tay.
A6: Ngưỡng quá hạn để gắn cờ | B6: overdue | C6: 30 | D6: ngày | E6: Có hóa đơn quá hạn hơn 1 tháng là dấu hiệu rủi ro rõ.
A7: Ngưỡng tập trung khách hàng | B7: conc | C7: 0.5 | D7: tỷ lệ | E7: Một khách chiếm quá nửa phải thu thì chậm trả của khách đó quyết định thanh khoản.
A8: Ngưỡng tồn lâu – nguyên phụ liệu | B8: NVL | C8: 60 | D8: ngày | E8: NVL của xưởng: tham số demo; cần hiệu chỉnh theo lead time, mùa vụ và đơn hàng.
A9: Ngưỡng tồn lâu – bán thành phẩm | B9: BTP | C9: 30 | D9: ngày | E9: Hàng trên chuyền may bình thường chỉ vài ngày đến vài tuần.
A10: Ngưỡng tồn lâu – thành phẩm | B10: TP | C10: 30 | D10: ngày | E10: Thành phẩm chờ xuất quá 1 tháng là chậm giao hoặc khách chưa nhận.
A11: Ngưỡng kỳ hạn ngắn của nhà cung cấp | B11: short | C11: 30 | D11: ngày | E11: Dưới ngưỡng chỉ là kỳ hạn ngắn. Chưa đủ bằng chứng nhà cung cấp đang siết tín dụng.
A12: Sai lệch doanh thu cho phép (DQ-01) | B12: tol | C12: 0.02 | D12: tỷ lệ | E12: Cho phép lệch nhỏ do làm tròn, hóa đơn điều chỉnh.
A13: Số nguyên nhân nêu tên mỗi loại | B13: topn | C13: 3 | D13: mục | E13: Đủ để chủ doanh nghiệp tập trung xử lý.
A14: Loại tồn kho bị loại trừ | B14: excl | C14: HGC | D14: mã | E14: Hàng nhận gia công không phải tài sản của doanh nghiệp.
A17: Tham chiếu ngành (DN dệt may niêm yết VGT, MSH, TNG – theo báo cáo ngành của nhóm, chưa kiểm chứng độc lập)
A18: Chỉ số | B18: Thấp nhất | C18: Cao nhất | D18: Phương pháp | E18: Cách dùng
A19: DSO | B19: 32 | C19: 47.5 | D19: Số dư bình quân / 365 (khác phương pháp tác vụ 1) | E19: Chỉ so định hướng, không kết luận tốt xấu tuyệt đối; DN niêm yết lớn hơn SME nhiều.
A20: DIO | B20: 57.6 | C20: 82.6 | D20: Số dư bình quân / 365 (khác phương pháp tác vụ 1) | E20: Chỉ so định hướng, không kết luận tốt xấu tuyệt đối; DN niêm yết lớn hơn SME nhiều.
A21: DPO | B21: 16.1 | C21: 38.8 | D21: Số dư bình quân / 365 (khác phương pháp tác vụ 1) | E21: Chỉ so định hướng, không kết luận tốt xấu tuyệt đối; DN niêm yết lớn hơn SME nhiều.
A22: CCC | B22: 64.9 | C22: 98 | D22: Số dư bình quân / 365 (khác phương pháp tác vụ 1) | E22: Chỉ so định hướng, không kết luận tốt xấu tuyệt đối; DN niêm yết lớn hơn SME nhiều.
A24: Ngưỡng tồn lâu – hàng thương mại | B24: HH | C24: 60 | D24: ngày | E24: Hàng thương mại của F02: dùng 60 ngày để giữ khả năng đối chiếu dữ liệu mẫu; cần hiệu chỉnh trước dùng thực tế.
A25: Ngưỡng số dư thiếu so với đệm | B25: cash_gap | C25: 0 | D25: VND | E25: Thiếu = MAX(0; đệm − tiền). Trên 0 là vi phạm đệm.
A26: Độ lệch kiểm chứng ngày | B26: tol_days | C26: 0.05 | D26: ngày | E26: Chỉ kiểm chứng số học, không thay kiểm chứng phương pháp.
A27: Độ lệch kiểm chứng tiền | B27: tol_vnd | C27: 1 | D27: VND | E27: Đơn vị VND; không áp 1 VND cho ví dụ theo triệu.

Sheet TV1_Output
A1: TV1 — CẤU TRÚC KẾT QUẢ VÀ MẪU DIỄN GIẢI AGENT
A2: Kết quả phải trả số đo, đối tượng, bằng chứng và giới hạn. Mẫu tiếng Anh ở phía dưới liên kết công thức với dữ liệu F01.
A4: Trường / đường dẫn | B4: Kiểu | C4: Nội dung bắt buộc | D4: Cách tính / nguồn | E4: Kiểm soát và điều kiện
A5: status | B5: enum | C5: Trạng thái toàn yêu cầu; đủ dữ liệu cốt lõi nhưng có giả định → provisional. | D5: Tổng hợp trạng thái của chỉ tiêu bắt buộc. | E5: Không trả ok nếu phần cốt lõi thiếu hoặc sai. rejected không dùng thay cho thiếu dữ liệu.
A6: meta | B6: object | C6: run_id, firm_id, as_of, period_start/end, period_days, lookback_start/end, formula_version, snapshot_id, currency, generated_at. | D6: Nguồn tham số đầu vào đã xác thực. | E6: Ngày chốt khác kỳ dòng thu/chi; ghi rõ timezone và basis ngày.
A7: inputs | B7: object | C7: Rev, COGS, AR, INV, AP, PUR; nguồn bảng/cột; tax_basis; balance_method; credit_sales_assumption; inventory_valuation. | D7: T1-A01…A06; TV1_Quy_uoc. | E7: Gắn status từng input. Các số dư là còn lại, không phải tổng hóa đơn gốc.
A8: result.metrics[] | B8: array<metric> | C8: id, name, raw_value, display_value, unit, status, reason, numerator, denominator, period_days, method, formula_id, evidence_ids. DSO/DIO/DPO/CCC/DPO_PUR/CCC_PUR. | D8: T1-B01…B05. | E8: Không trộn DPO trên COGS với trên mua. Denominator = 0 → null + not_applicable.
A9: result.compatibility | B9: object | C9: Giữ result.dso/dio/dpo/ccc/dpo_on_purchases cho bên gọi theo v2; là giá trị làm tròn. | D9: Ánh xạ từ result.metrics, không tính lại. | E9: raw_value thuộc metric là nguồn đối soát. API triển khai phải phiên bản hóa schema.
A10: money | B10: object | C10: revenue_per_day_vnd, cogs_per_day_vnd, purchases_per_day_vnd, trade_working_capital_vnd, cash_per_1_day_dso/dio/dpo_vnd. | D10: T1-F01/F02. | E10: net_working_capital_vnd cũ là alias TWC, phải gắn definition. Không gọi TWC là vốn lưu động thuần toàn DN.
A11: money.interpretation | B11: object | C11: TWC: vốn thương mại thuần tại ngày chốt; one_day_values: vốn tương đương theo lưu lượng kỳ. | D11: T1-F01/F02, có assumption_ids. | E11: Giảm 1 ngày DSO không phải cam kết tiền sẽ thu; chưa có đánh giá tiền nên chưa xác định ngày giải phóng tiền.
A12: benchmark[] | B12: array | C12: metric_id, value, range, source, reference_period, balance_method, peer_model, comparability, status, reason. | D12: T1-B07; TV1_Nguong. | E12: Khác kỳ/phương pháp/mô hình → descriptive_only; không good/bad, không xếp hạng tín dụng.
A13: drivers.buyers[] — số dư | B13: array | C13: buyer_id/name, ar_vnd, ar_share, rank_by_ar, dso_contribution_days, open_invoice_count, evidence_ids. | D13: AR_k/AR; AR_k/Rev×N; đếm invoice_id duy nhất. | E13: buyer_id ổn định; cùng phạm vi tổng AR. Tổng đóng góp phải bằng DSO.
A14: drivers.buyers[] — quá hạn | B14: array | C14: overdue_vnd, overdue_share_of_buyer_ar, overdue_share_of_total_ar, overdue_invoice_count, max_days_past_due, aging_vnd. | D14: T1-C01; DPD theo due_date. | E14: Hai tỷ lệ có mẫu số khác nhau phải khác khóa. max DPD chỉ trên hóa đơn còn dư.
A15: drivers.buyers[] — hành vi | B15: array | C15: avg_terms_days, collection_days_wavg, late_positive_wavg, early_wavg, late_signed_wavg, history_invoice_count, paid_amount_vnd, lookback, coverage_status. | D15: T1-C02/C03. | E15: Mẫu ít/thời gian chưa đủ → insufficient_history; không gán 0 ngày trễ.
... A33: narrative | B33: object | C33: executive_summary, receivables, inventory, payables, priorities, limitations; từng phần gắn insight_ids. | D33: Render từ kết quả công cụ; thứ tự ở TV1_Dien_giai. | E33: check_answer kiểm cả đơn vị, mẫu số, thời gian, tên đối tượng, phương pháp và không bịa số; chưa có code kèm để xác nhận đã chạy.
A36: MẪU DIỄN GIẢI AGENT CHO F01 — ENGLISH DEMO, LINKED TO TOOL-STYLE RESULTS
A37: ="Your closing-balance cash conversion cycle is "&TEXT(TV1_Mau_ket_qua!B10,"0.0")&" days (DSO "&TEXT(TV1_Mau_ket_qua!B7,"0.0")&" + DIO "&TEXT(TV1_Mau_ket_qua!B8,"0.0")&" − DPO "&TEXT(TV1_Mau_ket_qua!B9,"0.0")&"), with VND "&TEXT(TV1_Mau_ket_qua!B11/1000000000,"0.00")&" billion in net trade working capital. Receivables are the largest positive component. Exporter K1 accounts for "&TEXT(TV1_Mau_ket_qua!B29,"0.0%")&" of outstanding receivables and contributes "&TEXT(TV1_Mau_ket_qua!B30,"0.0")&" days to DSO. Its historical weighted payment delay is "&TEXT(TV1_Mau_ket_qua!B31,"0.0")&" days after the due date on a signed basis over the 180-day lookback; the positive-delay measure is "&TEXT(TV1_Mau_ket_qua!B32,"0.0")&" days. This separates payment behaviour from the "&TEXT(TV1_Mau_ket_qua!B44,"0")&"-day credit terms. Across all customers, "&TEXT(TV1_Mau_ket_qua!B34,"0.0%")&" of receivables (VND "&TEXT(TV1_Mau_ket_qua!B33/1000000,"0")&" million) is overdue. The first priority is to reconcile overdue invoices and obtain specific payment commitments from K1, rather than treating every outstanding invoice as late. At the period's sales rate, one day of DSO is equivalent to about VND "&TEXT(TV1_Mau_ket_qua!B12/1000000,"0")&" million of capital; this is not guaranteed immediate cash." -> Your closing-balance cash conversion cycle is 69.0 days (DSO 50.0 + DIO 43.9 − DPO 24.8), with VND 6.41 billion in net trade working capital. Receivables are the largest positive component. Exporter K1 accounts for 79.2% of outstanding receivables and contributes 39.6 days to DSO. Its historical weighted payment delay is 20.5 days after the due date on a signed basis over the 180-day lookback; the positive-delay measure is 20.5 days. This separates payment behaviour from the 45-day credit terms. Across all customers, 17.7% of receivables (VND 872 million) is overdue. The first priority is to reconcile overdue invoices and obtain specific payment commitments from K1, rather than treating every outstanding invoice as late. At the period's sales rate, one day of DSO is equivalent to about VND 98 million of capital; this is not guaranteed immediate cash.
A38: ="Inventory needs a separate response: cancelled-order summer trims worth VND "&TEXT(TV1_Mau_ket_qua!B35/1000000,"0")&" million have been held for "&TEXT(TV1_Mau_ket_qua!B36,"0")&" days. They represent "&TEXT(TV1_Mau_ket_qua!B38,"0.0%")&" of owned inventory and "&TEXT(TV1_Mau_ket_qua!B37,"0.0")&" days of DIO. Confirm reuse or sale demand before assuming that book value can be recovered; a write-down alone creates no cash. Fabric worth VND "&TEXT(TV1_Mau_ket_qua!B39/1000000000,"0.0")&" billion belongs to Exporter K1 and is excluded, so it is not F01's working-capital release opportunity. On the payment side, VND "&TEXT(TV1_Mau_ket_qua!B13/1000000,"0")&" million of AP is overdue: the DPO offset therefore cannot automatically be described as efficient supplier financing. Supplier Beta offers a "&TEXT(TV1_Mau_ket_qua!B40,"0%")&" discount on invoice P-F01-0101, saving VND "&TEXT(TV1_Mau_ket_qua!B41/1000000,"0.00")&" million if paid by "&TEXT(TV1_Mau_ket_qua!B43,"dd mmm yyyy")&". Its "&TEXT(TV1_Mau_ket_qua!B42,"0.0%")&" simple annualised rate makes it worth evaluating, but affordability and other mandatory payments must be checked before recommending early payment." -> Inventory needs a separate response: cancelled-order summer trims worth VND 430 million have been held for 118 days. They represent 12.5% of owned inventory and 5.5 days of DIO. Confirm reuse or sale demand before assuming that book value can be recovered; a write-down alone creates no cash. Fabric worth VND 2.6 billion belongs to Exporter K1 and is excluded, so it is not F01's working-capital release opportunity. On the payment side, VND 341 million of AP is overdue: the DPO offset therefore cannot automatically be described as efficient supplier financing. Supplier Beta offers a 2% discount on invoice P-F01-0101, saving VND 4.50 million if paid by 03 Oct 2026. Its 37.2% simple annualised rate makes it worth evaluating, but affordability and other mandatory payments must be checked before recommending early payment.
A39: Your DSO is above the listed Vietnamese garment-company reference range of 32.0–47.5 days. Those references use average balances over 365 days, whereas this diagnosis uses closing balances over 90 days, so the comparison is directional rather than a performance verdict. The practical priorities are buyer-specific collection follow-up, an evidence-based recovery plan for cancelled-order trims, and verification of overdue supplier obligations before pursuing discounts. This snapshot does not establish when cash will arrive or whether all payments can be met. These are diagnostic suggestions, not a credit decision.
A40: Mẫu không chép nguyên văn số cũ: trễ có dấu 20,5 ngày được gắn đúng nhãn; trễ dương tính riêng; % quá hạn và VND tính từ dữ liệu chưa làm tròn. Đoạn demo dùng dữ liệu giả lập, không phải đánh giá doanh nghiệp thật.

Sheet TV1_Tinh_tay
A1: TÍNH TAY TRÊN DỮ LIỆU MẪU V2 VÀ CHỈ TIÊU BỔ SUNG
A2: Dữ liệu v2 giả định trả toàn bộ một lần, chưa VAT và số dư cuối kỳ. Đây là phần tính được trên dữ liệu hiện có; không phải tất cả chỉ tiêu mở rộng.
A4: ID | B4: Chỉ tiêu | C4: F01 | D4: F02 | E4: F03 | F4: Đơn vị
A5: T1-01 | B5: Doanh thu kỳ | C5: =SUMIFS(D_financials!$D$3:$D$5,D_financials!$A$3:$A$5,C$4) -> 8844078000 | D5: =SUMIFS(D_financials!$D$3:$D$5,D_financials!$A$3:$A$5,D$4) -> 11697775000 | E5: =SUMIFS(D_financials!$D$3:$D$5,D_financials!$A$3:$A$5,E$4) -> 6087812000 | F5: VND
A6: T1-02 | B6: Giá vốn kỳ | C6: =SUMIFS(D_financials!$E$3:$E$5,D_financials!$A$3:$A$5,C$4) -> 7075000000 | D6: =SUMIFS(D_financials!$E$3:$E$5,D_financials!$A$3:$A$5,D$4) -> 10528000000 | E6: =SUMIFS(D_financials!$E$3:$E$5,D_financials!$A$3:$A$5,E$4) -> 4870000000 | F6: VND
A7: T1-03 | B7: Phải thu | C7: =SUMIFS(D_sales!$D$3:$D$263,D_sales!$B$3:$B$263,C$4,D_sales!$H$3:$H$263,1) -> 4912255000 | D7: =SUMIFS(D_sales!$D$3:$D$263,D_sales!$B$3:$B$263,D$4,D_sales!$H$3:$H$263,1) -> 4807643000 | E7: =SUMIFS(D_sales!$D$3:$D$263,D_sales!$B$3:$B$263,E$4,D_sales!$H$3:$H$263,1) -> 3881055000 | F7: VND
A8: T1-04 | B8: Tồn kho (không gồm HGC) | C8: =SUMIFS(D_inventory!$K$3:$K$16,D_inventory!$A$3:$A$16,C$4) -> 3450000000 | D8: =SUMIFS(D_inventory!$K$3:$K$16,D_inventory!$A$3:$A$16,D$4) -> 8050000000 | E8: =SUMIFS(D_inventory!$K$3:$K$16,D_inventory!$A$3:$A$16,E$4) -> 1860000000 | F8: VND
A9: T1-04b | B9: Hàng nhận gia công bị loại trừ | C9: =SUMIFS(D_inventory!$G$3:$G$16,D_inventory!$A$3:$A$16,C$4,D_inventory!$H$3:$H$16,1) -> 2600000000 | D9: =SUMIFS(D_inventory!$G$3:$G$16,D_inventory!$A$3:$A$16,D$4,D_inventory!$H$3:$H$16,1) -> 0 | E9: =SUMIFS(D_inventory!$G$3:$G$16,D_inventory!$A$3:$A$16,E$4,D_inventory!$H$3:$H$16,1) -> 0 | F9: VND
A10: T1-05 | B10: Phải trả | C10: =SUMIFS(D_purchases!$D$3:$D$267,D_purchases!$B$3:$B$267,C$4,D_purchases!$J$3:$J$267,1) -> 1951577000 | D10: =SUMIFS(D_purchases!$D$3:$D$267,D_purchases!$B$3:$B$267,D$4,D_purchases!$J$3:$J$267,1) -> 2317750000 | E10: =SUMIFS(D_purchases!$D$3:$D$267,D_purchases!$B$3:$B$267,E$4,D_purchases!$J$3:$J$267,1) -> 888463000 | F10: VND
A11: T1-06 | B11: Mua hàng trong kỳ | C11: =SUMIFS(D_purchases!$D$3:$D$267,D_purchases!$B$3:$B$267,C$4,D_purchases!$K$3:$K$267,1) -> 4238434000 | D11: =SUMIFS(D_purchases!$D$3:$D$267,D_purchases!$B$3:$B$267,D$4,D_purchases!$K$3:$K$267,1) -> 10535902000 | E11: =SUMIFS(D_purchases!$D$3:$D$267,D_purchases!$B$3:$B$267,E$4,D_purchases!$K$3:$K$267,1) -> 3029097000 | F11: VND
A12: T1-07 | B12: DSO | C12: =IF(NOT(ISNUMBER(C5)),"missing_data",IF(C5=0,"not_applicable",C7/C5*Quy_uoc_chung!$C$3)) -> 49.988586 | D12: =IF(NOT(ISNUMBER(D5)),"missing_data",IF(D5=0,"not_applicable",D7/D5*Quy_uoc_chung!$C$3)) -> 36.988903 | E12: =IF(NOT(ISNUMBER(E5)),"missing_data",IF(E5=0,"not_applicable",E7/E5*Quy_uoc_chung!$C$3)) -> 57.376107 | F12: ngày
A13: T1-08 | B13: DIO | C13: =IF(NOT(ISNUMBER(C6)),"missing_data",IF(C6=0,"not_applicable",C8/C6*Quy_uoc_chung!$C$3)) -> 43.886926 | D13: =IF(NOT(ISNUMBER(D6)),"missing_data",IF(D6=0,"not_applicable",D8/D6*Quy_uoc_chung!$C$3)) -> 68.816489 | E13: =IF(NOT(ISNUMBER(E6)),"missing_data",IF(E6=0,"not_applicable",E8/E6*Quy_uoc_chung!$C$3)) -> 34.373717 | F13: ngày
A14: T1-09 | B14: DPO | C14: =IF(NOT(ISNUMBER(C6)),"missing_data",IF(C6=0,"not_applicable",C10/C6*Quy_uoc_chung!$C$3)) -> 24.825714 | D14: =IF(NOT(ISNUMBER(D6)),"missing_data",IF(D6=0,"not_applicable",D10/D6*Quy_uoc_chung!$C$3)) -> 19.813592 | E14: =IF(NOT(ISNUMBER(E6)),"missing_data",IF(E6=0,"not_applicable",E10/E6*Quy_uoc_chung!$C$3)) -> 16.419234 | F14: ngày
A15: T1-10 | B15: CCC | C15: =IF(OR(ISTEXT(C12),ISTEXT(C13),ISTEXT(C14)),"missing_data",C12+C13-C14) -> 69.049797 | D15: =IF(OR(ISTEXT(D12),ISTEXT(D13),ISTEXT(D14)),"missing_data",D12+D13-D14) -> 85.9918 | E15: =IF(OR(ISTEXT(E12),ISTEXT(E13),ISTEXT(E14)),"missing_data",E12+E13-E14) -> 75.330589 | F15: ngày
A16: T1-11 | B16: DPO trên tổng mua (giả định mua chịu) | C16: =IF(NOT(ISNUMBER(C11)),"missing_data",IF(C11=0,"not_applicable",C10/C11*Quy_uoc_chung!$C$3)) -> 41.440289 | D16: =IF(NOT(ISNUMBER(D11)),"missing_data",IF(D11=0,"not_applicable",D10/D11*Quy_uoc_chung!$C$3)) -> 19.798732 | E16: =IF(NOT(ISNUMBER(E11)),"missing_data",IF(E11=0,"not_applicable",E10/E11*Quy_uoc_chung!$C$3)) -> 26.397857 | F16: ngày
A17: T1-08b | B17: DIO nếu tính nhầm cả hàng nhận gia công | C17: =(C8+C9)/C6*Quy_uoc_chung!$C$3 -> 76.961131 | D17: =(D8+D9)/D6*Quy_uoc_chung!$C$3 -> 68.816489 | E17: =(E8+E9)/E6*Quy_uoc_chung!$C$3 -> 34.373717 | F17: ngày
A18: T1-20 | B18: Doanh thu bình quân ngày | C18: =C5/Quy_uoc_chung!$C$3 -> 98267533 | D18: =D5/Quy_uoc_chung!$C$3 -> 1.2997528e+08 | E18: =E5/Quy_uoc_chung!$C$3 -> 67642356 | F18: VND
A19: T1-21 | B19: Giá vốn bình quân ngày | C19: =C6/Quy_uoc_chung!$C$3 -> 78611111 | D19: =D6/Quy_uoc_chung!$C$3 -> 1.1697778e+08 | E19: =E6/Quy_uoc_chung!$C$3 -> 54111111 | F19: VND
A20: T1-22 | B20: Vốn lưu động thương mại thuần (TWC) | C20: =C7+C8-C10 -> 6410678000 | D20: =D7+D8-D10 -> 10539893000 | E20: =E7+E8-E10 -> 4852592000 | F20: VND
A21: T1-34a | B21: Phải thu chưa đến hạn | C21: =SUMIFS(D_sales!$D$3:$D$263,D_sales!$B$3:$B$263,C$4,D_sales!$K$3:$K$263,"Chưa đến hạn") -> 4040690000 | D21: =SUMIFS(D_sales!$D$3:$D$263,D_sales!$B$3:$B$263,D$4,D_sales!$K$3:$K$263,"Chưa đến hạn") -> 3947376000 | E21: =SUMIFS(D_sales!$D$3:$D$263,D_sales!$B$3:$B$263,E$4,D_sales!$K$3:$K$263,"Chưa đến hạn") -> 3536480000 | F21: VND
A22: T1-34b | B22: Quá hạn 1–30 ngày | C22: =SUMIFS(D_sales!$D$3:$D$263,D_sales!$B$3:$B$263,C$4,D_sales!$K$3:$K$263,"Quá hạn 1–30 ngày") -> 871565000 | D22: =SUMIFS(D_sales!$D$3:$D$263,D_sales!$B$3:$B$263,D$4,D_sales!$K$3:$K$263,"Quá hạn 1–30 ngày") -> 860267000 | E22: =SUMIFS(D_sales!$D$3:$D$263,D_sales!$B$3:$B$263,E$4,D_sales!$K$3:$K$263,"Quá hạn 1–30 ngày") -> 344575000 | F22: VND
A23: T1-34c | B23: Quá hạn 31–60 ngày | C23: =SUMIFS(D_sales!$D$3:$D$263,D_sales!$B$3:$B$263,C$4,D_sales!$K$3:$K$263,"Quá hạn 31–60 ngày") -> 0 | D23: =SUMIFS(D_sales!$D$3:$D$263,D_sales!$B$3:$B$263,D$4,D_sales!$K$3:$K$263,"Quá hạn 31–60 ngày") -> 0 | E23: =SUMIFS(D_sales!$D$3:$D$263,D_sales!$B$3:$B$263,E$4,D_sales!$K$3:$K$263,"Quá hạn 31–60 ngày") -> 0 | F23: VND
A24: T1-34d | B24: Quá hạn > 60 ngày | C24: =SUMIFS(D_sales!$D$3:$D$263,D_sales!$B$3:$B$263,C$4,D_sales!$K$3:$K$263,"Quá hạn > 60 ngày") -> 0 | D24: =SUMIFS(D_sales!$D$3:$D$263,D_sales!$B$3:$B$263,D$4,D_sales!$K$3:$K$263,"Quá hạn > 60 ngày") -> 0 | E24: =SUMIFS(D_sales!$D$3:$D$263,D_sales!$B$3:$B$263,E$4,D_sales!$K$3:$K$263,"Quá hạn > 60 ngày") -> 0 | F24: VND
A25: T1-35 | B25: Tỷ lệ quá hạn | C25: =IF(C7=0,"not_applicable",(C7-C21)/C7) -> 0.17742666 | D25: =IF(D7=0,"not_applicable",(D7-D21)/D7) -> 0.17893737 | E25: =IF(E7=0,"not_applicable",(E7-E21)/E7) -> 0.088783849 | F25: %
A26: T1-44 | B26: Giá trị hàng tồn lâu | C26: =SUMIFS(D_inventory!$K$3:$K$16,D_inventory!$A$3:$A$16,C$4,D_inventory!$J$3:$J$16,1) -> 430000000 | D26: =SUMIFS(D_inventory!$K$3:$K$16,D_inventory!$A$3:$A$16,D$4,D_inventory!$J$3:$J$16,1) -> 1450000000 | E26: =SUMIFS(D_inventory!$K$3:$K$16,D_inventory!$A$3:$A$16,E$4,D_inventory!$J$3:$J$16,1) -> 170000000 | F26: VND
A27: T1-44b | B27: Tỷ trọng hàng tồn lâu | C27: =IF(C8=0,"not_applicable",C26/C8) -> 0.12463768 | D27: =IF(D8=0,"not_applicable",D26/D8) -> 0.18012422 | E27: =IF(E8=0,"not_applicable",E26/E8) -> 0.091397849 | F27: %
A28: T1-54 | B28: Tiết kiệm nếu nhận chiết khấu trả sớm | C28: =SUMIFS(D_purchases!$Q$3:$Q$267,D_purchases!$B$3:$B$267,C$4) -> 4501240 | D28: =SUMIFS(D_purchases!$Q$3:$Q$267,D_purchases!$B$3:$B$267,D$4) -> 0 | E28: =SUMIFS(D_purchases!$Q$3:$Q$267,D_purchases!$B$3:$B$267,E$4) -> 0 | F28: VND
A29: T1-54b | B29: Lãi suất ngầm định cao nhất | C29: =IFERROR(_xlfn.MAXIFS(D_purchases!$P$3:$P$267,D_purchases!$B$3:$B$267,C$4,D_purchases!$O$3:$O$267,1),0) -> 0.37244898 | D29: =IFERROR(_xlfn.MAXIFS(D_purchases!$P$3:$P$267,D_purchases!$B$3:$B$267,D$4,D_purchases!$O$3:$O$267,1),0) -> 0 | E29: =IFERROR(_xlfn.MAXIFS(D_purchases!$P$3:$P$267,D_purchases!$B$3:$B$267,E$4,D_purchases!$O$3:$O$267,1),0) -> 0 | F29: %/năm
A30: T1-61 | B30: DQ-01 lệch doanh thu | C30: =(SUMIFS(D_sales!$D$3:$D$263,D_sales!$B$3:$B$263,C$4,D_sales!$I$3:$I$263,1)-C5)/C5 -> 0 | D30: =(SUMIFS(D_sales!$D$3:$D$263,D_sales!$B$3:$B$263,D$4,D_sales!$I$3:$I$263,1)-D5)/D5 -> 0 | E30: =(SUMIFS(D_sales!$D$3:$D$263,D_sales!$B$3:$B$263,E$4,D_sales!$I$3:$I$263,1)-E5)/E5 -> 0 | F30: %
A31: T1-61b | B31: DQ-01 kết quả | C31: =IF(ABS(C30)<=TV1_Nguong!$C$12,"ok","cảnh báo") -> ok | D31: =IF(ABS(D30)<=TV1_Nguong!$C$12,"ok","cảnh báo") -> ok | E31: =IF(ABS(E30)<=TV1_Nguong!$C$12,"ok","cảnh báo") -> ok
A32: T1-60a | B32: DSO so tham chiếu | C32: =IF(NOT(ISNUMBER(C12)),"not_applicable",IF(C12>TV1_Nguong!$C$19,"Cao hơn khoảng (khác phương pháp)",IF(C12<TV1_Nguong!$B$19,"Thấp hơn khoảng (khác phương pháp)","Trong khoảng (khác phương pháp)"))) -> Cao hơn khoảng (khác phương pháp) | D32: =IF(NOT(ISNUMBER(D12)),"not_applicable",IF(D12>TV1_Nguong!$C$19,"Cao hơn khoảng (khác phương pháp)",IF(D12<TV1_Nguong!$B$19,"Thấp hơn khoảng (khác phương pháp)","Trong khoảng (khác phương pháp)"))) -> Trong khoảng (khác phương pháp) | E32: =IF(NOT(ISNUMBER(E12)),"not_applicable",IF(E12>TV1_Nguong!$C$19,"Cao hơn khoảng (khác phương pháp)",IF(E12<TV1_Nguong!$B$19,"Thấp hơn khoảng (khác phương pháp)","Trong khoảng (khác phương pháp)"))) -> Cao hơn khoảng (khác phương pháp)
A33: T1-60b | B33: DIO so tham chiếu | C33: =IF(NOT(ISNUMBER(C13)),"not_applicable",IF(C13>TV1_Nguong!$C$20,"Cao hơn khoảng (khác phương pháp)",IF(C13<TV1_Nguong!$B$20,"Thấp hơn khoảng (khác phương pháp)","Trong khoảng (khác phương pháp)"))) -> Thấp hơn khoảng (khác phương pháp) | D33: =IF(NOT(ISNUMBER(D13)),"not_applicable",IF(D13>TV1_Nguong!$C$20,"Cao hơn khoảng (khác phương pháp)",IF(D13<TV1_Nguong!$B$20,"Thấp hơn khoảng (khác phương pháp)","Trong khoảng (khác phương pháp)"))) -> Trong khoảng (khác phương pháp) | E33: =IF(NOT(ISNUMBER(E13)),"not_applicable",IF(E13>TV1_Nguong!$C$20,"Cao hơn khoảng (khác phương pháp)",IF(E13<TV1_Nguong!$B$20,"Thấp hơn khoảng (khác phương pháp)","Trong khoảng (khác phương pháp)"))) -> Thấp hơn khoảng (khác phương pháp)
A34: T1-60c | B34: DPO so tham chiếu | C34: =IF(NOT(ISNUMBER(C14)),"not_applicable",IF(C14>TV1_Nguong!$C$21,"Cao hơn khoảng (khác phương pháp)",IF(C14<TV1_Nguong!$B$21,"Thấp hơn khoảng (khác phương pháp)","Trong khoảng (khác phương pháp)"))) -> Trong khoảng (khác phương pháp) | D34: =IF(NOT(ISNUMBER(D14)),"not_applicable",IF(D14>TV1_Nguong!$C$21,"Cao hơn khoảng (khác phương pháp)",IF(D14<TV1_Nguong!$B$21,"Thấp hơn khoảng (khác phương pháp)","Trong khoảng (khác phương pháp)"))) -> Trong khoảng (khác phương pháp) | E34: =IF(NOT(ISNUMBER(E14)),"not_applicable",IF(E14>TV1_Nguong!$C$21,"Cao hơn khoảng (khác phương pháp)",IF(E14<TV1_Nguong!$B$21,"Thấp hơn khoảng (khác phương pháp)","Trong khoảng (khác phương pháp)"))) -> Trong khoảng (khác phương pháp)
A35: T1-60d | B35: CCC so tham chiếu | C35: =IF(NOT(ISNUMBER(C15)),"not_applicable",IF(C15>TV1_Nguong!$C$22,"Cao hơn khoảng (khác phương pháp)",IF(C15<TV1_Nguong!$B$22,"Thấp hơn khoảng (khác phương pháp)","Trong khoảng (khác phương pháp)"))) -> Trong khoảng (khác phương pháp) | D35: =IF(NOT(ISNUMBER(D15)),"not_applicable",IF(D15>TV1_Nguong!$C$22,"Cao hơn khoảng (khác phương pháp)",IF(D15<TV1_Nguong!$B$22,"Thấp hơn khoảng (khác phương pháp)","Trong khoảng (khác phương pháp)"))) -> Trong khoảng (khác phương pháp) | E35: =IF(NOT(ISNUMBER(E15)),"not_applicable",IF(E15>TV1_Nguong!$C$22,"Cao hơn khoảng (khác phương pháp)",IF(E15<TV1_Nguong!$B$22,"Thấp hơn khoảng (khác phương pháp)","Trong khoảng (khác phương pháp)"))) -> Trong khoảng (khác phương pháp)
A37: F01 – Phải thu theo khách hàng (lớp C)
A38: Khách hàng | B38: Phải thu | C38: Tỷ trọng | D38: Đóng góp DSO | E38: Số HĐ mở | F38: Quá hạn | G38: Max ngày quá hạn | H38: Trễ BQ có trọng số | I38: Kỳ hạn BQ | J38: Cờ khách hàng
A39: Nhà xuất khẩu K2 | B39: =SUMIFS(D_sales!$D$3:$D$263,D_sales!$B$3:$B$263,"F01",D_sales!$C$3:$C$263,A39,D_sales!$H$3:$H$263,1) -> 666295000 | C39: =IF(TV1_Tinh_tay!$C$7=0,0,B39/TV1_Tinh_tay!$C$7) -> 0.13563933 | D39: =B39/TV1_Tinh_tay!$C$5*Quy_uoc_chung!$C$3 -> 6.7804185 | E39: =COUNTIFS(D_sales!$B$3:$B$263,"F01",D_sales!$C$3:$C$263,A39,D_sales!$H$3:$H$263,1) -> 4 | F39: =SUMIFS(D_sales!$D$3:$D$263,D_sales!$B$3:$B$263,"F01",D_sales!$C$3:$C$263,A39,D_sales!$H$3:$H$263,1,D_sales!$J$3:$J$263,">0") -> 0 | G39: =MAX(0,_xlfn.MAXIFS(D_sales!$J$3:$J$263,D_sales!$B$3:$B$263,"F01",D_sales!$C$3:$C$263,A39,D_sales!$H$3:$H$263,1)) -> 0 | H39: =IFERROR(SUMIFS(D_sales!$N$3:$N$263,D_sales!$B$3:$B$263,"F01",D_sales!$C$3:$C$263,A39)/SUMIFS(D_sales!$D$3:$D$263,D_sales!$B$3:$B$263,"F01",D_sales!$C$3:$C$263,A39,D_sales!$L$3:$L$263,1),"") -> 1.9634711 | I39: =IFERROR(SUMIFS(D_sales!$P$3:$P$263,D_sales!$B$3:$B$263,"F01",D_sales!$C$3:$C$263,A39)/SUMIFS(D_sales!$D$3:$D$263,D_sales!$B$3:$B$263,"F01",D_sales!$C$3:$C$263,A39,D_sales!$L$3:$L$263,1),"") -> 30 | J39: =IF(OR(AND(H39<>"",H39>TV1_Nguong!$C$5),G39>TV1_Nguong!$C$6,C39>TV1_Nguong!$C$7),"Cờ","")
A40: Nhà xuất khẩu Lớn K1 | B40: =SUMIFS(D_sales!$D$3:$D$263,D_sales!$B$3:$B$263,"F01",D_sales!$C$3:$C$263,A40,D_sales!$H$3:$H$263,1) -> 3888513000 | C40: =IF(TV1_Tinh_tay!$C$7=0,0,B40/TV1_Tinh_tay!$C$7) -> 0.79159429 | D40: =B40/TV1_Tinh_tay!$C$5*Quy_uoc_chung!$C$3 -> 39.570679 | E40: =COUNTIFS(D_sales!$B$3:$B$263,"F01",D_sales!$C$3:$C$263,A40,D_sales!$H$3:$H$263,1) -> 8 | F40: =SUMIFS(D_sales!$D$3:$D$263,D_sales!$B$3:$B$263,"F01",D_sales!$C$3:$C$263,A40,D_sales!$H$3:$H$263,1,D_sales!$J$3:$J$263,">0") -> 817756000 | G40: =MAX(0,_xlfn.MAXIFS(D_sales!$J$3:$J$263,D_sales!$B$3:$B$263,"F01",D_sales!$C$3:$C$263,A40,D_sales!$H$3:$H$263,1)) -> 11 | H40: =IFERROR(SUMIFS(D_sales!$N$3:$N$263,D_sales!$B$3:$B$263,"F01",D_sales!$C$3:$C$263,A40)/SUMIFS(D_sales!$D$3:$D$263,D_sales!$B$3:$B$263,"F01",D_sales!$C$3:$C$263,A40,D_sales!$L$3:$L$263,1),"") -> 20.520664 | I40: =IFERROR(SUMIFS(D_sales!$P$3:$P$263,D_sales!$B$3:$B$263,"F01",D_sales!$C$3:$C$263,A40)/SUMIFS(D_sales!$D$3:$D$263,D_sales!$B$3:$B$263,"F01",D_sales!$C$3:$C$263,A40,D_sales!$L$3:$L$263,1),"") -> 45 | J40: =IF(OR(AND(H40<>"",H40>TV1_Nguong!$C$5),G40>TV1_Nguong!$C$6,C40>TV1_Nguong!$C$7),"Cờ","") -> Cờ
A41: Thương hiệu nội địa K3 | B41: =SUMIFS(D_sales!$D$3:$D$263,D_sales!$B$3:$B$263,"F01",D_sales!$C$3:$C$263,A41,D_sales!$H$3:$H$263,1) -> 357447000 | C41: =IF(TV1_Tinh_tay!$C$7=0,0,B41/TV1_Tinh_tay!$C$7) -> 0.072766377 | D41: =B41/TV1_Tinh_tay!$C$5*Quy_uoc_chung!$C$3 -> 3.6374883 | E41: =COUNTIFS(D_sales!$B$3:$B$263,"F01",D_sales!$C$3:$C$263,A41,D_sales!$H$3:$H$263,1) -> 5 | F41: =SUMIFS(D_sales!$D$3:$D$263,D_sales!$B$3:$B$263,"F01",D_sales!$C$3:$C$263,A41,D_sales!$H$3:$H$263,1,D_sales!$J$3:$J$263,">0") -> 53809000 | G41: =MAX(0,_xlfn.MAXIFS(D_sales!$J$3:$J$263,D_sales!$B$3:$B$263,"F01",D_sales!$C$3:$C$263,A41,D_sales!$H$3:$H$263,1)) -> 1 | H41: =IFERROR(SUMIFS(D_sales!$N$3:$N$263,D_sales!$B$3:$B$263,"F01",D_sales!$C$3:$C$263,A41)/SUMIFS(D_sales!$D$3:$D$263,D_sales!$B$3:$B$263,"F01",D_sales!$C$3:$C$263,A41,D_sales!$L$3:$L$263,1),"") -> 9.4617431 | I41: =IFERROR(SUMIFS(D_sales!$P$3:$P$263,D_sales!$B$3:$B$263,"F01",D_sales!$C$3:$C$263,A41)/SUMIFS(D_sales!$D$3:$D$263,D_sales!$B$3:$B$263,"F01",D_sales!$C$3:$C$263,A41,D_sales!$L$3:$L$263,1),"") -> 30 | J41: =IF(OR(AND(H41<>"",H41>TV1_Nguong!$C$5),G41>TV1_Nguong!$C$6,C41>TV1_Nguong!$C$7),"Cờ","")
A43: F01 – Tồn kho theo dòng hàng (lớp D)
...

Sheet TV1_Doi_chieu
A1: ĐỐI CHIẾU CÔNG THỨC MẪU VỚI GIÁ TRỊ THAM CHIẾU V2
A2: Cột tham chiếu là số lưu từ v2, không phải kết quả code mới. Đổi dữ liệu/ngưỡng có thể làm chênh lệch. Kiểm thử đặc tả đầy đủ xem TV1_Kiem_thu.
A4: DN | B4: Hạng mục | C4: Tham chiếu v2 (tĩnh) | D4: Excel hiện tại | E4: Chênh lệch | F4: Kết quả | H4: Tổng hợp
A5: F01 | B5: Phải thu | C5: 4912255000 | D5: =TV1_Tinh_tay!$C$7 -> 4912255000 | E5: =IFERROR(D5-C5,"") -> 0 | F5: =IF(AND(ISNUMBER(C5),ISNUMBER(D5)),IF(ABS(D5-C5)<=1,"Đạt","Không đạt"),"Không đạt") -> Đạt | H5: Số hạng mục Đạt | I5: =COUNTIF(F5:F100,"Đạt") -> 96
A6: F01 | B6: Tồn kho | C6: 3450000000 | D6: =TV1_Tinh_tay!$C$8 -> 3450000000 | E6: =IFERROR(D6-C6,"") -> 0 | F6: =IF(AND(ISNUMBER(C6),ISNUMBER(D6)),IF(ABS(D6-C6)<=1,"Đạt","Không đạt"),"Không đạt") -> Đạt | H6: Số hạng mục Không đạt | I6: =COUNTIF(F5:F100,"Không đạt") -> 0
A7: F01 | B7: Phải trả | C7: 1951577000 | D7: =TV1_Tinh_tay!$C$10 -> 1951577000 | E7: =IFERROR(D7-C7,"") -> 0 | F7: =IF(AND(ISNUMBER(C7),ISNUMBER(D7)),IF(ABS(D7-C7)<=1,"Đạt","Không đạt"),"Không đạt") -> Đạt
A8: F01 | B8: Mua hàng trong kỳ | C8: 4238434000 | D8: =TV1_Tinh_tay!$C$11 -> 4238434000 | E8: =IFERROR(D8-C8,"") -> 0 | F8: =IF(AND(ISNUMBER(C8),ISNUMBER(D8)),IF(ABS(D8-C8)<=1,"Đạt","Không đạt"),"Không đạt") -> Đạt
A9: F01 | B9: DSO | C9: 50 | D9: =TV1_Tinh_tay!$C$12 -> 49.988586 | E9: =IFERROR(D9-C9,"") -> -0.011414418 | F9: =IF(AND(ISNUMBER(C9),ISNUMBER(D9)),IF(ABS(D9-C9)<=0.05,"Đạt","Không đạt"),"Không đạt") -> Đạt
A10: F01 | B10: DIO | C10: 43.9 | D10: =TV1_Tinh_tay!$C$13 -> 43.886926 | E10: =IFERROR(D10-C10,"") -> -0.013074205 | F10: =IF(AND(ISNUMBER(C10),ISNUMBER(D10)),IF(ABS(D10-C10)<=0.05,"Đạt","Không đạt"),"Không đạt") -> Đạt
A11: F01 | B11: DPO | C11: 24.8 | D11: =TV1_Tinh_tay!$C$14 -> 24.825714 | E11: =IFERROR(D11-C11,"") -> 0.025714488 | F11: =IF(AND(ISNUMBER(C11),ISNUMBER(D11)),IF(ABS(D11-C11)<=0.05,"Đạt","Không đạt"),"Không đạt") -> Đạt
