Workbook

Sheet Read_me
A2: Hướng dẫn đọc và phạm vi dữ liệu
A4: Mục | B4: Nội dung | C4: Đọc / kiểm tra ở đâu
A5: Phạm vi | B5: Đặc tả công thức và workbook kiểm thử UC01–UC04 trên một doanh nghiệp F01 gia công CMT. Toàn bộ dữ liệu hư cấu. | C5: Giữ công thức UC01–UC03 của v8; bổ sung UC4_Cong_thuc, UC4_Huong_dan và F01_UC4.
A6: Kỳ UC01 | B6: 01/01–20/06/2026, N=171 ngày. Ngày chốt chung 20/06/2026. | C6: D_F01; F01_UC1
A7: Kỳ UC02 | B7: 21/06–19/09/2026, 13 tuần/91 ngày. Không lấy 171 ngày làm kỳ dự báo. | C7: F01_UC2
A8: Cách đọc | B8: 1. Đọc Read_me → 2. Xem bảng công thức UC1/UC2/UC3/UC4 → 3. Kiểm tra Nguong → 4. Xem các bảng minh họa F01 → 5. Đối soát Kiem_thu và kiểm tra UC04. | C8: Các sheet D_* là đầu vào dùng chung, không có F02/F03.
A9: Cách viết công thức | B9: Mỗi dòng có tên biến, phép tính, phạm vi, đơn vị và ngoại lệ. Dấu Σ là cộng các dòng thỏa điều kiện; MAX(0;x) là chỉ giữ phần dương. | C9: Không dùng công thức dài thay định nghĩa nghiệp vụ.
A10: Dữ liệu được giữ | B10: Giữ mã và số tiền của 111 hóa đơn bán, 127 hóa đơn mua, 33 lô; doanh thu 30 tỷ và giá vốn 24 tỷ từ bản F01 sáu tháng đã xây. | C10: D_sales, D_purchases, D_inventory
A11: Điều chỉnh ngày | B11: Lùi ngày chốt từ 30/09 về 20/06 (102 ngày); lùi các ngày giao dịch tương ứng. Hóa đơn lùi trước 01/01 được đưa về 01/01, giữ chênh lệch due/paid theo hợp đồng. Tồn đầu kỳ có ngày nhập trước 01/01 vẫn được giữ. | C11: Số ngày quá hạn / lưu kho tại chốt giữ khi không bị giới hạn đầu kỳ; lưu vết tại D_F01.
A12: Không giữ kết quả cũ bằng ép số | B12: Số tiền giữ nguyên, N đổi 183→171 nên DSO/DIO/DPO/CCC và W có thể đổi. Không chỉnh số dư để ép về W2. | C12: Ví dụ mới được tính độc lập trong Kiem_thu.
A13: Bổ sung để chạy UC02 | B13: Lịch lương, thuế, thuê xưởng, trả nợ và một lịch thu xác nhận đều là giả lập biết tại ngày chốt; không có trong dữ liệu gốc. | C13: D_flows có source_type, source_ref, known_at và cờ essential.
A14: Nguồn ưu tiên | B14: Giá trị và công thức W theo Ngưỡng SMEs(2).xlsx; nghiệp vụ forecast theo SRS v1.0; mã công thức kế thừa v4. | C14: Nguong ghi nguồn theo sheet/ô; không thay ngưỡng bằng số đã làm tròn trong SRS.
A15: Khác cơ sở ngành | B15: Ngành dùng năm và số dư bình quân; F01 dùng 171 ngày và số dư cuối kỳ. So sánh có nhãn provisional, chỉ định hướng. | C15: Không đổi ngưỡng ngày theo tỷ lệ 171/365. Quy đổi vốn vượt dùng Rev/N hoặc COGS/N.
... A42: Cách thử UC04 | B42: Chọn kịch bản tại F01_UC4!B5; các giả định là số liệu minh họa. UC04 chưa dùng sản phẩm tài trợ UC03, không gửi hành động hoặc thay snapshot. | C42: Giữ nguyên Cash0, ngưỡng và nền UC02; không xóa nghĩa vụ bị giãn ngoài kỳ.

Sheet UC1_Cong_thuc
A2: UC01 Chẩn đoán vốn lưu động
A4: Mã | B4: Nhóm công thức | C4: Chỉ tiêu | D4: Ý nghĩa dễ hiểu | E4: Công thức từng bước | F4: Dữ liệu đầu vào | G4: Phạm vi / điều kiện | H4: Đơn vị / hiển thị | I4: Ngoại lệ / kiểm soát
A5: T1-01 | B5: 01. Số dư và chu kỳ | C5: Doanh thu kỳ (Rev) | D5: Quy mô bán hàng trong N ngày | E5: Rev = financials.revenue_vnd | F5: financials.revenue_vnd; workbook D_F01!B9 | G5: firm_id của phiên; firm_id = F01; ngày chốt 20/06/2026. Kỳ phát sinh 01/01–20/06 nếu áp dụng. | H5: VND | I5: Rev=0: chỉ tiêu phụ thuộc not_applicable. Thiếu Rev: missing_data. Demo dùng tổng doanh thu như proxy bán chịu.
A6: T1-02 | B6: 01. Số dư và chu kỳ | C6: Giá vốn kỳ (COGS) | D6: Chi phí làm ra hàng đã bán, gồm cả lương công nhân | E6: COGS = financials.cogs_vnd | F6: financials.cogs_vnd; workbook D_F01!B10 | G6: firm_id của phiên; firm_id = F01; ngày chốt 20/06/2026. Kỳ phát sinh 01/01–20/06 nếu áp dụng. | H6: VND | I6: COGS=0: tỷ số phụ thuộc not_applicable. Thiếu COGS: missing_data.
A7: T1-03 | B7: 01. Số dư và chu kỳ | C7: Phải thu (AR) | D7: Tiền khách còn nợ | E7: AR = Σ OpenAmount của hóa đơn bán | F7: sales_invoices.Amount | G7: Hóa đơn mở tại AsOf; firm_id = F01; ngày chốt 20/06/2026. Kỳ phát sinh 01/01–20/06 nếu áp dụng. | H7: VND | I7: Không có hóa đơn mở → AR = 0 (hợp lệ)
A8: T1-04 | B8: 01. Số dư và chu kỳ | C8: Tồn kho (INV) | D8: Tiền nằm trong kho dưới dạng hàng | E8: INV = Σ Qty × UnitCost của lô thuộc F01 | F8: inventory.qty, unit_cost_vnd, inventory_type | G8: inventory_type ≠ HGC; firm_id = F01; ngày chốt 20/06/2026. Kỳ phát sinh 01/01–20/06 nếu áp dụng. | H8: VND | I8: Thiếu loại/quyền sở hữu: chưa xác định, không tự coi NVL. Demo HGC loại; cost chưa NRV có nhãn.
A9: T1-05 | B9: 01. Số dư và chu kỳ | C9: Phải trả (AP) | D9: Số tiền doanh nghiệp còn nợ nhà cung cấp | E9: AP = Σ OpenAmount của hóa đơn mua | F9: purchase_invoices.Amount | G9: Hóa đơn mở tại AsOf; firm_id = F01; ngày chốt 20/06/2026. Kỳ phát sinh 01/01–20/06 nếu áp dụng. | H9: VND | I9: Không có hóa đơn mở → AP = 0 (hợp lệ)
A10: T1-06 | B10: 01. Số dư và chu kỳ | C10: Mua hàng trong kỳ (PUR) | D10: Giá trị mua chịu từ nhà cung cấp trong N ngày | E10: PUR = Σ Amount hóa đơn mua phát hành trong kỳ | F10: purchase_invoices.Amount, issue_date | G10: AsOf − N + 1 ≤ issue_date ≤ AsOf; firm_id = F01; ngày chốt 20/06/2026. Kỳ phát sinh 01/01–20/06 nếu áp dụng. | H10: VND | I10: PUR = 0 → bỏ T1-11
A11: T1-07 | B11: 01. Số dư và chu kỳ | C11: DSO | D11: Phải thu quy đổi thành số ngày theo doanh thu kỳ; không là ngày tiền chắc chắn về. | E11: DSO = AR / Rev × N | F11: T1-03, T1-01 | G11: –; firm_id = F01; ngày chốt 20/06/2026. Kỳ phát sinh 01/01–20/06 nếu áp dụng. | H11: ngày; 1 số lẻ khi xuất | I11: Rev=0: not_applicable. Thiếu trường: missing_data.
A12: T1-08 | B12: 01. Số dư và chu kỳ | C12: DIO | D12: Tồn kho quy đổi theo giá vốn kỳ; khác số ngày một lô đã lưu kho. | E12: DIO = INV / COGS × N | F12: T1-04, T1-02 | G12: –; firm_id = F01; ngày chốt 20/06/2026. Kỳ phát sinh 01/01–20/06 nếu áp dụng. | H12: ngày; 1 số lẻ | I12: COGS=0: not_applicable. Thiếu trường: missing_data.
A13: T1-09 | B13: 01. Số dư và chu kỳ | C13: DPO | D13: Phải trả cuối kỳ quy đổi theo giá vốn kỳ; không phải kỳ hạn hợp đồng thực tế. | E13: DPO = AP / COGS × N | F13: T1-05, T1-02 | G13: –; firm_id = F01; ngày chốt 20/06/2026. Kỳ phát sinh 01/01–20/06 nếu áp dụng. | H13: ngày; 1 số lẻ | I13: COGS=0: not_applicable. Thiếu trường: missing_data.
A14: T1-10 | B14: 01. Số dư và chu kỳ | C14: CCC | D14: DSO + DIO − DPO theo cùng phương pháp và kỳ. | E14: CCC = DSO + DIO − DPO | F14: T1-07..T1-09 (chưa làm tròn) | G14: –; firm_id = F01; ngày chốt 20/06/2026. Kỳ phát sinh 01/01–20/06 nếu áp dụng. | H14: ngày; làm tròn bước cuối | I14: Metric phụ thuộc không khả dụng: CCC null cùng reason; giữ phần tính được.
A15: T1-11 | B15: 01. Số dư và chu kỳ | C15: DPO trên mua hàng (chẩn đoán) | D15: Phải trả cuối kỳ quy đổi theo giá trị mua hàng; vẫn không phải kỳ hạn hợp đồng. | E15: DPO_mua = AP / PUR × N | F15: T1-05, T1-06 | G15: –; firm_id = F01; ngày chốt 20/06/2026. Kỳ phát sinh 01/01–20/06 nếu áp dụng. | H15: ngày; 1 số lẻ | I15: PUR = 0 → null
... A61: T1-95 | B61: 09. Chi tiết và liên kết | C61: Quan hệ đối tác | D61: Đặc điểm quan hệ khác mức độ rủi ro thanh toán. | E61: Mới nếu RelationshipAge ≤60 Thường xuyên nếu InvoiceCount ≥12 VÀ ActiveMonths ≥4 Còn lại Vãng lai | F61: D_sales; hồ sơ đối tác | G61: Quy tắc demo, không phải ngưỡng ngành. Ít lịch sử không đồng nghĩa khách xấu. | H61: Nhãn | I61: Không làm tròn giữa các bước; truy vết nguồn và phiên bản.

Sheet UC2_Cong_thuc
A2: UC02 Dự báo tiền và cảnh báo
A4: Mã | B4: Nhóm công thức | C4: Chỉ tiêu | D4: Ý nghĩa dễ hiểu | E4: Công thức từng bước | F4: Dữ liệu đầu vào | G4: Phạm vi / điều kiện | H4: Đơn vị / hiển thị | I4: Ngoại lệ / kiểm soát
A5: T2-01 | B5: 01. Tiền đầu kỳ và nghĩa vụ | C5: Tiền khả dụng đầu dự báo | D5: Tiền doanh nghiệp có thể chi ngay sau ngày chốt. | E5: Cash0 = cash_AsOf_vnd − restricted_vnd | F5: cash_snapshot.cash_vnd, restricted_vnd | G5: Đúng doanh nghiệp, ngày chốt, tiền tệ. | H5: VND; raw | I5: Thiếu Cash0: chỉ dùng proxy được xác định và gắn nhãn trong chính sách → provisional. Nếu không có proxy hợp lệ → missing_data; không tự điền 0. Tiền bị hạn chế phải tách riêng.
A6: T2-02 | B6: 01. Tiền đầu kỳ và nghĩa vụ | C6: Phải thu dùng lập lịch tiền | D6: Chỉ dự báo phần khách chưa trả. | E6: AR_cash = gross_invoice − receipts_to_AsOf − credits_to_AsOf | F6: sales_invoices; receipt_allocations; credit_notes | G6: Đã ghi nhận đến ngày chốt; chọn phần dư dương. | H6: VND gồm thuế | I6: Demo net/noVAT, trả toàn bộ một lần. Dư âm tách ứng trước. Không tự dùng VAT 10%.
A7: T2-03 | B7: 01. Tiền đầu kỳ và nghĩa vụ | C7: Phải trả dùng lập lịch tiền | D7: Chỉ dự báo phần nghĩa vụ chưa trả. | E7: AP_cash = gross_invoice − payments_to_AsOf − credits_to_AsOf | F7: purchase_invoices; payment_allocations | G7: Đúng phạm vi thương mại và ngày chốt. | H7: VND gồm thuế | I7: Lương, thuế, nợ vay vào plan riêng. Một nghĩa vụ chỉ tính một lần.
A8: T2-04 | B8: 02. Lập lịch và tính số dư | C8: Trễ thu bình quân dương | D8: Ước ngày thu theo lịch sử từng khách. Khoản lớn có trọng số lớn. | E8: CompletedLate = MAX(0; PaidDate − DueDate) OpenLowerBound = MAX(0; AsOf − DueDate) ModelDelay = CompletedLate hoặc OpenLowerBound DelayBase = Σ ModelAmount × ModelDelay / Σ ModelAmount | F8: receipt_allocations; due_date | G8: DueDate trong (AsOf − 180; AsOf]; mẫu mở có cờ censored, mẫu trả xong có cờ completed. Chọn khách khi ≥5 mẫu; nếu không dùng toàn F01 ≥5; cuối cùng mặc định 7 ngày. | H8: Ngày; giữ raw | I8: Theo SRS 2.7.11.1: mẫu mở chỉ là cận dưới. Không gọi trung bình hỗn hợp là ngày thanh toán thực tế. UC01 vẫn dùng riêng mẫu đã thanh toán.
A9: T2-05 | B9: 02. Lập lịch và tính số dư | C9: Ngày thu dự kiến | D9: Ưu tiên lịch xác nhận, sau đó mới ước tính. | E9: Ngày thu = ConfirmedDate nếu lịch được biết tại AsOf Chưa quá hạn: MAX(Start; DueDate + CEILING(DelayScenario; 1)) Đã quá hạn: xem T2-19; không tự gom mọi khoản về Start. | F9: receipt_schedule; T2-04; due_date | G9: Lịch biết tại ngày chốt; portions không vượt dư. | H9: Ngày lịch | I9: Ngày đã qua chuyển về Start chỉ theo policy có nhãn. Thiếu ngày: unscheduled. Không dùng paid_date tương lai.
A10: T2-06 | B10: 02. Lập lịch và tính số dư | C10: Ngày chi dự kiến | D10: Giữ nghĩa vụ đến hạn và nói rõ giả định khoản quá hạn. | E10: Ngày chi = ApprovedDate nếu có Chưa quá hạn: DueDate + lịch sử trễ theo chính sách NCC thiết yếu / Conservative: DueDate Quá hạn: AsOf + OffsetScenario + MOD(Rank; 5) | F10: payment_schedule; purchase_invoices | G10: Lịch đã duyệt, biết tại ngày chốt. | H10: Ngày lịch | I10: Đây là chính sách mô phỏng theo SRS, không phải gia hạn đã được NCC chấp thuận. Lịch được duyệt ưu tiên. Offset: Conservative 1, Base 5, Optimistic 10 ngày.
A11: T2-07 | B11: 02. Lập lịch và tính số dư | C11: Tiền vào ngày hoặc tuần | D11: Cộng khoản thu được xếp vào đúng kỳ. | E11: In = Σ Amount [direction = IN; date ∈ kỳ] | F11: cash_events | G11: Cùng firm, run, case, currency; không trùng nguồn. | H11: VND | I11: Thu hóa đơn và thu khác có căn cứ. Không lấy Rev/N làm tiền thu, không tự coi tồn kho sẽ bán được.
A12: T2-08 | B12: 02. Lập lịch và tính số dư | C12: Tiền ra ngày hoặc tuần | D12: Trả nhà cung cấp và các khoản chi có lịch. | E12: Out = Σ Amount [direction = OUT; date ∈ kỳ] | F12: cash_events; planned_events | G12: Cùng scope và kỳ; một phần nghĩa vụ một lần. | H12: VND | I12: Không cộng COGS như tiền chi. Gốc/lãi vay, lương, thuế, đầu tư cần lịch riêng.
A13: T2-09 | B13: 02. Lập lịch và tính số dư | C13: Số dư tiền | D13: Một phép tính cho ngày và tuần, liên kết kỳ trước sang kỳ sau. | E13: CashEnd = CashStart + In − Out CashStart_next = CashEnd | F13: T2-01; T2-07; T2-08 | G13: Ngày đầu bằng Cash0; tuần cộng cùng event ledger. | H13: VND; giữ số âm | I13: Ví dụ đầu100 triệu, thu100, chi150 → cuối50; vẫn có thể âm giữa tuần. Không ép số âm về0.
A14: T2-10 | B14: 03. Cảnh báo thiếu tiền | C14: Thiếu so mức dự phòng | D14: Khoản bù để đạt mức tiền doanh nghiệp muốn giữ. | E14: GapBuffer_d = MAX(0; Rtarget_d − CashEnd_d) | F14: buffer_vnd; T2-09 | G14: Dự phòng đã xác nhận; ghi rõ ngày/cuối tuần. | H14: VND | I14: Tiền còn350 triệu, buffer500 → thiếu150; chưa phải tiền âm.
A15: T2-11 | B15: 03. Cảnh báo thiếu tiền | C15: Thiếu để không âm | D15: Khoản bù để số dư dự kiến trở lại0. | E15: GapZero = MAX(0; −CashEnd) | F15: T2-09 | G15: Cùng ngày/tuần đang xét. | H15: VND | I15: Tiền−50 triệu → thiếu50 để không âm. Không cộng với GapBuffer.
... A41: T2-37 | B41: 06. Chất lượng và bàn giao | C41: Trạng thái dữ liệu | D41: Không dùng “khỏe” khi chưa có dữ liệu. | E41: invalid_data > missing_data > provisional > ok rejected: kiểm soát quyền riêng Thiếu nguồn lõi: TH unknown, không gán màu | F41: Nguồn, validation, manifest | G41: Mẫu luôn provisional vì toàn bộ dữ liệu tạo sinh. Hoàn thành số học không xác nhận doanh nghiệp thật. | H41: Enum | I41: Không làm tròn giữa các bước; truy vết nguồn và phiên bản.

Sheet UC3_Cong_thuc
A2: UC03 So khớp phương án tài trợ
A4: Mã | B4: Nhóm công thức | C4: Chỉ tiêu | D4: Ý nghĩa dễ hiểu | E4: Công thức từng bước | F4: Dữ liệu đầu vào | G4: Phạm vi / điều kiện | H4: Đơn vị / hiển thị | I4: Ngoại lệ / kiểm soát
A5: T3-01 | B5: 01. Khoảng thiếu và đợt cần tiền | C5: Mức thiếu theo khối 2 tuần | D5: Cho biết mỗi khối 2 tuần thiếu bao nhiêu so với mức dự trữ muốn giữ. | E5: Deficit_k = MAX(0; Rtarget − MinDaily_k) k = khối 2 tuần liên tiếp trong 13 tuần | F5: UC02: Rtarget; MinDaily theo khối (T2-13) | G5: Kịch bản Base; chỉ khối có ít nhất một ngày CashEnd < Rtarget mới tính là có thiếu. | H5: VND; raw | I5: Không cộng Deficit_k qua các khối. Chưa phải số tiền cần vay.
A6: T3-02 | B6: 01. Khoảng thiếu và đợt cần tiền | C6: Ngưỡng đổi mức và mức trọng yếu | D6: Lọc nhiễu: chỉ coi là đổi mức khi chênh lệch đủ lớn và giữ đủ lâu. | E6: θ = Rtarget × PARAM_THETA_PCT Is_Material_Gap = 1 nếu |ΔDeficit| ≥ θ VÀ mức mới giữ ≥ PARAM_MIN_DAYS ngày; ngược lại 0 | F6: T3-01; PARAM_THETA_PCT (25%); PARAM_MIN_DAYS (14) | G6: So hai khối liền kề; mức không giữ đủ 14 ngày gộp vào mức trước. | H6: VND; ngày | I6: Dao động nhỏ hoặc xen kẽ bị coi là nhiễu, không tạo đợt mới.
A7: T3-03 | B7: 01. Khoảng thiếu và đợt cần tiền | C7: Dạng khoảng thiếu (gap_shape) | D7: Phân loại đường thiếu theo số lần đổi mức: tối đa một lần. | E7: Đếm n = số lần Is_Material_Gap = 1 trong kỳ n = 0 → đồng đều n = 1 và mức tăng → tăng một lần n = 1 và mức giảm → giảm một lần n ≥ 2 → không phân loại được | F7: T3-02 | G7: Chỉ phân loại đầy đủ ở TH01; TH02 và TH03 dùng để mô tả. | H7: enum | I7: n ≥ 2: dùng mức thiếu lớn nhất cho cả kỳ và gắn cờ REVIEW_MANUAL. Không mô hình hóa bật tắt xen kẽ.
A8: T3-04 | B8: 01. Khoảng thiếu và đợt cần tiền | C8: Cắt đợt cần tiền (gap_request) | D8: Đổi đường thiếu thành tối đa 2 đợt có ngày và số tiền cần. | E8: Đồng đều hoặc giảm một lần: 1 đợt; need_date = ngày đầu CashEnd < Rtarget; G_cum = mức thiếu lớn nhất Tăng một lần: 2 đợt; đợt 1 = mức thấp tại ngày đầu thiếu; đợt 2 = lũy kế mức cao tại ngày chuyển mức G_incr_j = G_cum_j − G_cum_(j−1) | F8: UC02: gap_shape, gap_request; T3-03 | G8: Mỗi đợt có need_date và G_cum; G_incr đợt 1 = G_cum đợt 1. | H8: VND; ngày | I8: Giảm một lần: kỳ hạn chỉ cần phủ đến ngày chuyển mức. Hóa đơn hoặc lô đã dùng ở đợt 1 bị loại khỏi đợt 2.
A9: T3-05 | B9: 01. Khoảng thiếu và đợt cần tiền | C9: Mức nhẹ / nặng của khoảng thiếu | D9: Phân nhẹ hoặc nặng để chọn cách xử lý. | E9: gap_severity = NẶNG nếu PeakGap ≥ θ; NHẸ nếu nhỏ hơn | F9: T3-02; PeakGap của đợt | G9: Tính riêng từng đợt. | H9: enum | I9: Ngưỡng dùng chung với T3-02.
A10: T3-06 | B10: 01. Khoảng thiếu và đợt cần tiền | C10: Số ngày còn lại và chế độ Khẩn | D10: Còn bao nhiêu ngày đến lúc cần tiền; sát hạn thì ưu tiên tiền nhanh nhất. | E10: DaysLeft = need_date − ngày yêu cầu Urgent_Mode = 1 nếu DaysLeft ≤ PARAM_URGENT_DAYS (7) | F10: gap_request; PARAM_URGENT_DAYS | G10: Tính riêng từng đợt; ngày yêu cầu là ngày chạy UC03. | H10: Ngày; 0/1 | I10: DaysLeft ≤ 0: không có nguồn nào kịp ngoài tiền nội bộ; hiển thị “không kịp ngày cần tiền”.
A11: T3-07 | B11: 01. Khoảng thiếu và đợt cần tiền | C11: Thời gian thiếu kéo dài (duration) | D11: Số ngày khoảng thiếu còn tồn tại kể từ ngày cần tiền; dùng để tính chi phí thực. | E11: duration_j = số ngày từ need_date_j đến ngày cuối cùng CashEnd < Rtarget (đồng đều; không phân loại được; tăng một lần); nếu giảm một lần thì đến ngày chuyển mức | F11: UC02: daily[] | G11: Từng đợt. | H11: Ngày | I11: duration < PARAM_MIN_TENOR (14): loại sản phẩm khóa kỳ hạn hoặc có phí cố định, ưu tiên tiền nội bộ và giãn lịch.
A12: T3-08 | B12: 02. Yếu tố góp phần và kịch bản | C12: Tỷ lệ tham chiếu của yếu tố góp phần | D12: Dùng để định tuyến kịch bản, không phải phần thiếu do yếu tố gây ra. | E12: Share_k = MIN(100%; số tiền yếu tố k / PeakGap), k ∈ {E_AR, E_INV, E_AP} Vai trò: CHÍNH nếu ≥ PARAM_CAUSE_MAIN (50%); PHỤ nếu ≥ PARAM_CAUSE_SEC (15%); còn lại BỎ QUA | F12: UC01: E_AR, E_INV, E_AP; PeakGap | G12: Số tiền yếu tố là số tham chiếu, không cộng được (SRS 2.7.11.9). | H12: Tỷ lệ; 1 số lẻ% | I12: Với người dùng chỉ nói “yếu tố góp phần” kèm loại liên kết và mức bằng chứng; candidate phải gắn “chưa kiểm chứng”. Không gọi là nguyên nhân chính.
A13: T3-09 | B13: 02. Yếu tố góp phần và kịch bản | C13: Sự kiện trọng yếu | D13: Nhận biết khoản chi hoặc nhập NVL lớn làm mức thiếu tăng vọt. | E13: Major_Event = 1 nếu giá trị khoản đơn lẻ / PeakGap ≥ PARAM_MAJOR_EVENT (30%) | F13: cash_events OUT; PeakGap | G13: Trong ±7 ngày quanh ngày chuyển mức. | H13: 0/1 | I13: Không có sự kiện nào: ghi “đổi mức không gắn được sự kiện”.
A14: T3-10 | B14: 02. Yếu tố góp phần và kịch bản | C14: Chọn kịch bản một đợt A1–A4 | D14: Chọn nhóm nguồn theo yếu tố chính của khoảng thiếu. | E14: Không chuỗi gap (TH01): main = AR → A1; main = INV → A2; main = AP → A4; còn lại (BN0, L3) → A3 | F14: UC01: main_bottleneck, bn_pattern; T3-08 | G14: Chỉ TH01 và chưa thỏa điều kiện chuỗi gap ở T3-11. | H14: enum | I14: Yếu tố PHỤ mở thêm nhóm sản phẩm nhưng không đổi kịch bản.
A15: T3-11 | B15: 02. Yếu tố góp phần và kịch bản | C15: Chuỗi gap B1 / B2 | D15: Thiếu kéo dài mang tính cấu trúc nên cần gói đa nguồn. | E15: Persistent = 1 nếu TH01 và số khối thiếu liên tiếp ≥ min_blocks (2) Persistent = 1: B2 nếu (W2 và n_yếu_tố ≥ 2) HOẶC BestC < G B1 nếu n_yếu_tố > 0, không có yếu tố tồn kho và mọi liên kết L1 Còn lại B2 | F15: UC02: số khối; UC01: W, bn_pattern, loại liên kết; BestC = MAX C của nguồn qua lọc và kịp hạn | G15: n_yếu_tố = c_AR + c_INV + c_AP. | H15: enum | I15: Thay cách chọn B1/B2 ở phiên bản trước; khớp bộ tính tham chiếu.
... A42: T3-38 | B42: 06. Trạng thái TH02, TH03 và kiểm soát | C42: Ca quyết định của con người | D42: Đánh dấu bước UC03 không thể tự thực hiện. | E42: requires_human_decision = 1 nếu gói có AP_EXT, AR_EARLY, ghi đè hoặc cờ REVIEW_MANUAL | F42: T3-32; cờ cấp phiên | G42: Cả phiên. | H42: 0/1 | I42: UC03 chỉ đề xuất; UC04 soạn nội dung, người có thẩm quyền duyệt.
A44: Tham số ngưỡng UC03 (giá trị mặc định, tách khỏi công thức)
A46: Mã | B46: Tham số | C46: Giá trị mặc định | D46: Ý nghĩa dễ hiểu | E46: Công thức dùng | F46: Ghi chú
A47: T3-P01 | B47: PARAM_THETA_PCT | C47: 25% (% Rtarget) | D47: Chênh lệch tối thiểu công nhận đổi mức; ranh giới gap nhẹ / nặng | E47: T3-02, T3-05 | F47: Mặc định; đổi theo quy mô doanh nghiệp
A48: T3-P02 | B48: PARAM_MIN_DAYS | C48: 14 (ngày) | D48: Thời gian giữ mức mới (2 khối 2 tuần, khớp min_blocks = 2) | E48: T3-02 | F48: Mặc định
A49: T3-P03 | B49: PARAM_CAUSE_MAIN | C49: 50% (% PeakGap) | D49: Từ ngưỡng này là yếu tố góp phần chính (chỉ để định tuyến) | E49: T3-08 | F49: Mặc định
A50: T3-P04 | B50: PARAM_CAUSE_SEC | C50: 15% (% PeakGap) | D50: Từ ngưỡng này đến dưới 50% là yếu tố phụ | E50: T3-08 | F50: Mặc định
A51: T3-P05 | B51: PARAM_MAJOR_EVENT | C51: 30% (% PeakGap) | D51: Khoản đơn lẻ từ ngưỡng này là sự kiện trọng yếu | E51: T3-09 | F51: Mặc định
A52: T3-P06 | B52: PARAM_MIN_DRAW_PCT | C52: 5% (% PeakGap) | D52: Số rút tối thiểu mỗi nguồn | E52: T3-32 | F52: Mặc định
A53: T3-P07 | B53: PARAM_MAX_SOURCES | C53: 4 (nguồn) | D53: Số nguồn tối đa trong một gói | E53: T3-32 | F53: Mặc định
A54: T3-P08 | B54: PARAM_URGENT_DAYS | C54: 7 (ngày) | D54: DaysLeft nhỏ hơn hoặc bằng ngưỡng là chế độ Khẩn | E54: T3-06, T3-27 | F54: Mặc định
A55: T3-P09 | B55: PARAM_MIN_TENOR | C55: 14 (ngày) | D55: Thời gian thiếu ngắn hơn ngưỡng thì loại sản phẩm khóa kỳ hạn hoặc phí cố định | E55: T3-07 | F55: Mặc định
A56: T3-P10 | B56: PARAM_KEY_PARTNER | C56: 30% (% mua/bán) | D56: Nhà cung cấp từ ngưỡng này bị loại khỏi giãn nợ; khách hàng từ ngưỡng này chuyển cấp quản lý | E56: T3-14, T3-19 | F56: Mặc định

Sheet UC4_Cong_thuc
A2: UC04 Mô phỏng tác động lên dòng tiền
A4: Mã | B4: Nhóm công thức | C4: Chỉ tiêu | D4: Ý nghĩa dễ hiểu | E4: Công thức từng bước | F4: Dữ liệu đầu vào | G4: Phạm vi / điều kiện | H4: Đơn vị / hiển thị | I4: Ngoại lệ / kiểm soát
A5: U4-01 | B5: 01. Phạm vi và dữ liệu | C5: Đường tiền đối chiếu | D5: Lấy kết quả UC02 làm điểm xuất phát, không dựng lại lịch tùy ý. | E5: Base = UC02.daily Events = UC02.cash_events Giữ firm, snapshot, kỳ, Cash0, dự trữ và phiên bản | F5: F01_UC2!A70:M160; A220:Y341; D_F01 | G5: Workbook bắt đầu bằng D_F01!B19=1 (Base). Có thể thử nền UC02 khác, nhãn phải đổi theo. | H5: Ngày; VND | I5: Run UC01/UC02 khác firm/snapshot → chặn. Không ghép run-off và continuing như cùng cơ sở.
A6: U4-02 | B6: 01. Phạm vi và dữ liệu | C6: Đối tượng mô phỏng | D6: Chọn khách, NCC và lô từ kết quả chẩn đoán, rồi nối đến sự kiện tiền. | E6: Candidate = UC01.drivers AffectedEvents = Events có entity_id/source_id được chọn | F6: UC01; D_sales; D_purchases; D_inventory | G6: ID gốc, không nối bằng tên. Bản minh họa chọn 1 khách, 1 NCC, 1 lô; backend nhận danh sách event. | H6: ID / danh sách | I6: Điểm nghẽn UC01 chưa chắc tạo gap. Chỉ mô tả tác động do phép thử; không khẳng định quan hệ nhân quả đã được chứng minh.
A7: U4-03 | B7: 01. Phạm vi và dữ liệu | C7: Kiểm tra giả định | D7: Phân biệt giá trị 0 đã nhập với thiếu đầu vào. | E7: 0 ≤ Share ≤1; Days ≥0 và nguyên 0 ≤ Discount, Fee, Recovery, SaleCost ≤1 ID có thật; ngày hợp lệ; số tiền không vượt dư | F7: F01_UC4!B5:B27 | G7: 0%/0 ngày là lựa chọn không tác động. Rmin≤Rtarget≤Rupper; Rtarget>0. | H7: Hợp lệ / lỗi | I7: Sai tham số → rejected; nguồn mâu thuẫn → invalid_data; thiếu dữ liệu cần thiết → missing_data. Không cắt số sai về mức hợp lệ.
A8: U4-04 | B8: 02. Thu sớm hoặc thu chậm | C8: Phần tiền chuyển lịch | D8: Chỉ chuyển một phần khoản thu; phần còn lại giữ lịch cũ. | E8: Moved_i = Amount_i × ShareAR Remain_i = Amount_i − Moved_i | F8: UC02 event IN, category Thu công nợ; AR_share | G8: Đúng customer_id, hóa đơn mở. Lịch confirmed giữ nguyên trừ khi bật giả định thay cam kết. | H8: VND | I8: Một phần hóa đơn chỉ được phân bổ một lần. Không dùng Rev/ngày × số ngày như tiền sẽ thu.
A9: U4-05 | B9: 02. Thu sớm hoặc thu chậm | C9: Ngày thu mới | D9: Có thể thử cả thu sớm và khách trả chậm. | E9: Thu sớm: NewDate_i = MAX(Start; OldDate_i − EarlyDays) Stress chậm: NewDate_i = OldDate_i + LateDays | F9: Ngày thu UC02; số ngày do người dùng nhập | G9: Chỉ tương lai sau AsOf; stress mới thay thế thao tác thu sớm trên cùng phần tiền. | H9: Ngày lịch | I9: Không dịch lịch sử, không coi khách đã đồng ý. Lịch xác nhận bị thay phải có cờ và lý do.
A10: U4-06 | B10: 02. Thu sớm hoặc thu chậm | C10: Thu ròng và chiết khấu | D10: Thu nhanh hơn có thể phải chấp nhận giảm số tiền. | E10: DiscountCost_i = Moved_i × Discount NewReceipt_i = Moved_i − DiscountCost_i | F10: AR_discount; U4-04 | G10: Chiết khấu chỉ áp phần thực sự được thu sớm; không áp ngày không thay đổi hoặc stress thu chậm. | H10: VND | I10: Workbook ghi khoản chiết khấu bằng giảm thu, không ghi thêm OUT lần hai. Không tự đặt chiết khấu 0 khi chưa biết trong vận hành.
A11: U4-07 | B11: 03. Giãn trả nhà cung cấp | C11: Phần chi chuyển lịch | D11: Giãn chi tạo khoảng đệm thời gian, không xóa nợ. | E11: MovedPay_i = Amount_i × ShareAP RemainPay_i = Amount_i − MovedPay_i NewPayDate_i = OldDate_i + ExtendDays | F11: UC02 OUT / Trả NCC; supplier_id | G11: Chỉ khoản thương mại đã chọn. Lương, thuế, gốc/lãi vay không áp đòn bẩy này. | H11: VND; ngày | I11: NCC thiết yếu chỉ mô phỏng khi có xác nhận giả định được phép thử. Không coi xác nhận mô phỏng là thỏa thuận thật.
A12: U4-08 | B12: 03. Giãn trả nhà cung cấp | C12: Phí giãn trả | D12: Đưa đủ chi phí vào lịch trả mới. | E12: ExtensionFee_i = MovedPay_i × FeeAP NewPayment_i = MovedPay_i + ExtensionFee_i | F12: AP_fee_pct; U4-07 | G12: Phí phần trăm một lần trong bản đầu; biết ngày chi cùng ngày trả mới. | H12: VND | I12: NCC từ chối trong stress → giữ lịch cũ, không phí. Mất chiết khấu chỉ tính khi đã mô hình trong nền, không cộng tùy ý.
A13: U4-09 | B13: 04. Bán một phần tồn kho | C13: Lô được phép thử bán | D13: Không lấy hàng của khách hoặc hàng vướng quyền làm tiền của F01. | E13: EligibleLot = Owner=F01 AND Pledged=không AND UserSaleAssumption=1 ReleasedBook = OwnedValue × SaleShare | F13: D_inventory!A:M; sale_assumption | G13: Kiểm tra lượng bán≤lượng lô. Bản đầu chỉ bán lô chưa có khoản thu bán tương ứng trong nền. | H13: VND giá ghi sổ | I13: Hàng HGC, cầm cố hoặc chưa rõ cầm cố → chặn đòn bẩy lô đó. Muốn thử cần bổ sung bằng chứng, không sửa D_inventory để vượt chặn.
A14: U4-10 | B14: 04. Bán một phần tồn kho | C14: Tiền bán hàng và phí | D14: Giá ghi sổ giảm không đồng nghĩa thu được từng ấy tiền. | E14: SaleGross = ReleasedBook × RecoveryRate SaleCashCost = SaleGross × SaleCostRate SaleNet = SaleGross − SaleCashCost | F14: Tỷ lệ bán; tỷ lệ thu hồi; tỷ lệ chi phí | G14: Demo RecoveryRate từ 0 đến 100% giá ghi sổ; không tự đặt giá thị trường. | H14: VND | I14: Chênh lệch giá ghi sổ và tiền bán là tổn thất giá trị mô phỏng, không là một dòng tiền chi thêm.
A15: U4-11 | B15: 04. Bán một phần tồn kho | C15: Ngày bán và ngày thu | D15: Chỉ phát sinh tiền khi giả định có giao dịch và thời điểm thu rõ. | E15: SaleDate = Start + SaleLag SaleReceiptDate = SaleDate + ReceiptLag Kho giảm tại SaleDate; tiền về tại SaleReceiptDate | F15: F01_UC4 tham số lô; nhật ký giả định | G15: Bản minh họa ReceiptLag=0, thu ngay; backend cho phép trả chậm. | H15: Ngày; VND | I15: Tái sử dụng nguyên liệu hoặc ghi giảm giá trị chưa tạo tiền; chỉ ghi giảm chi mua khi có kế hoạch mua thay thế tương ứng được điều chỉnh.
... A34: U4-30 | B34: 08. Giới hạn chỉ số và đầu ra | C34: Đợt thiếu sau và ma trận | D34: Đánh giá trạng thái tiền mới nhưng không xóa chẩn đoán cũ. | E34: TH_after = quy tắc UC02 trên đường tiền sau Matrix_after = M(3×W_index+TH_index) | F34: W tại AsOf; TH_after; cùng cơ sở nền | G34: Nếu không phải nền Base thì TH/matrix chỉ là tham khảo; W không thay do thao tác tương lai. | H34: W / TH / M | I34: Không đổi W2 thành W0 vì tiền tạm dư. Mức màu tính riêng, không suy từ ô M.

Sheet UC4_Huong_dan
A2: UC04 Phạm vi và hướng dẫn triển khai
A4: Nhóm | B4: Nội dung | C4: Quy tắc áp dụng | D4: Vị trí / ví dụ
A5: Luồng tổng thể | B5: UC01 chọn đối tượng → UC02 cung cấp lịch tiền → UC04 thay giả định trên bản sao → so trước/sau và stress. | C5: Không cần chạy UC03. Không mặc định khách/NCC đã chấp thuận. | D5: F01_UC4: thiết lập A4:C40; kết quả E4:H40; ngày dòng 50; sự kiện dòng 150; tuần dòng 306.
A6: Phạm vi bản đầu | B6: Ba đòn bẩy nội bộ: thu sớm/chậm, giãn trả NCC, bán lô tồn sở hữu. | C6: Không gồm vay, tài trợ hóa đơn, đầu tư tiền dư, gửi thư hoặc phê duyệt hành động. Không đổi SRS trong lần này. | D6: Bản thiết kế công thức chờ duyệt. UC03 vẫn có thể nối thêm sau.
A7: Đối chiếu draft cũ | B7: Giữ bản sao bất biến, dịch sự kiện, kiểm tra gap mới, chi phí và bằng chứng. | C7: Bỏ phụ thuộc TV3_Nguong/TV3_Dot_thieu/D_catalogue; bỏ bộ F02/F03, bảng bản nháp và submit_action. | D7: Draft cũ có 30 sheet, gồm cả UC03 và dữ liệu cũ. Bản mới chỉ bổ sung 3 sheet.
A8: Sửa điểm nghiệp vụ | B8: Không dùng doanh thu bình quân×ngày để thay AR/AP tại ngày chốt; không mặc định tài trợ được loại AR; không coi toàn bộ thiếu biến mất khi hết một đợt. | C8: Giữ CCC lịch sử; tập trung tiền theo ngày, ngày xấu đi và nghĩa vụ ngoài kỳ. | D8: U4-14, U4-17, U4-26. Không suy tiết kiệm lãi khi chưa có lịch dư nợ thực.
A9: Dùng chung dữ liệu | B9: F01, ngày chốt 20/06/2026; chẩn đoán 01/01–20/06; forecast 21/06–19/09. | C9: Không chép lại D_* từ TV4 draft. UC04 nối trực tiếp sự kiện UC02 và lô từ D_inventory. | D9: D_F01, D_sales, D_purchases, D_inventory, D_flows giữ nguyên.
A10: Mã công thức | B10: UC04 dùng mã U4-01…U4-30 để phân biệt bản draft T4 cũ. | C10: Bảng 9 cột giống UC1/UC2_Cong_thuc; mỗi phép có đầu vào, điều kiện và ngoại lệ. | D10: Không gộp công thức và yêu cầu quyền thành một phép toán.
A11: Kịch bản đang chọn | B11: 0 Giữ nguyên; 1 Thực hiện giả định; 2 Chỉ thu sớm được 50%; 3 NCC từ chối; 4 Bán tồn chậm; 5 Ba bất lợi kết hợp; 6 Khách trả chậm. | C11: Một selector ở F01_UC4!B5; tất cả dùng cùng một ledger và một đường tiền. | D11: B6 đọc nhãn; B28:B34 là giả định hiệu lực tính từ selector và thông số.
A12: Nhóm khách hàng | B12: Gợi ý chọn từ UC01 theo vốn đang giữ, trễ bao lâu, quan hệ và mức tập trung; người dùng chọn ID. | C12: Không tự siết khách mới/vãng lai hoặc nới khách lớn. Nhãn quan hệ là ngữ cảnh, không phải sự chấp thuận. | D12: B7 customer_id. Có thể lọc từng event_id ở backend; workbook áp theo khách và tỷ lệ chung.
A13: Nhóm nhà cung cấp | B13: Chỉ dịch khoản Trả NCC thuộc supplier_id; giữ lương, thuế và nghĩa vụ tài chính. | C13: NCC thiết yếu cần bật xác nhận giả định mô phỏng. Không dùng công cụ what-if để sửa hợp đồng. | D13: B13 supplier_id; B17 chỉ xác nhận được phép thử, không xác nhận đối tác đã đồng ý.
A14: Nhóm hàng tồn kho | B14: Bán lô phải thuộc F01, không cầm cố và có giả định thị trường. | C14: Mặc định L27 không cầm cố; lô phụ liệu đơn hủy L06 chưa rõ cầm cố nên không chọn sẵn để tạo tiền. | D14: B18 lot_id; B24 xác nhận giả định; nếu đổi sang L06 mà chưa có dữ liệu thì trạng thái chặn.
A15: Điều kiện lịch xác nhận | B15: Mặc định không đổi lịch thu được xác nhận ở UC02. | C15: B12=1 cho phép thử thay lịch xác nhận; phải nói rõ giả định này trong kết quả. | D15: Không lấy paid_date tương lai làm chứng cứ có tại ngày chốt.
... A63: U4-T14 | B63: Sai firm/snapshot, thiếu quyền, lời giải thích không có fact hoặc ghi audit lỗi. | C63: Chặn đúng điểm; không thực thi hoặc phát hành ngoài quyền; Decimal và kiểm chứng cùng run. | D63: Ca nghiệm thu backend; không tuyên bố đã có ứng dụng.

Sheet Nguong
A2: Ngưỡng SMEs, biến điều tiết và quy tắc áp dụng
A4: Khóa cấu hình | B4: Giá trị nguồn | C4: Đơn vị | D4: Áp dụng | E4: Nguồn | F4: Giới hạn
A5: wc.dso.reference.cmt | B5: 26.270167 | C5: ngày | D5: Phải thu – tham chiếu, CMT | E5: verified_reference: FiinTrade 2016–2025, 27 DN may
A6: wc.dso.watch.cmt | B6: 35.829007 | C6: ngày | D6: Phải thu – R-AR-1, CMT | E6: verified_reference: FiinTrade 2016–2025, 27 DN may
A7: wc.dso.severe.cmt | B7: 45.958406 | C7: ngày | D7: Phải thu – R-AR-2, CMT | E7: verified_reference: FiinTrade 2016–2025, 27 DN may
A8: wc.dio.reference.cmt | B8: 7.1334971 | C8: ngày | D8: Tồn kho – tham chiếu, CMT | E8: verified_reference: FiinTrade 2016–2025, 27 DN may
A9: wc.dio.watch.cmt | B9: 9.4688973 | C9: ngày | D9: Tồn kho – R-INV-1, CMT | E9: verified_reference: FiinTrade 2016–2025, 27 DN may
A10: wc.dio.severe.cmt | B10: 13.701588 | C10: ngày | D10: Tồn kho – R-INV-2, CMT | E10: verified_reference: FiinTrade 2016–2025, 27 DN may
A11: wc.dpo.high_info.cmt | B11: 11.901427 | C11: ngày | D11: Phải trả – R-AP-INFO, CMT | E11: verified_reference: FiinTrade 2016–2025, 27 DN may
A12: wc.dpo.low.cmt | B12: 2.6371842 | C12: ngày | D12: Phải trả – R-AP-1, CMT | E12: verified_reference: FiinTrade 2016–2025, 27 DN may
A13: liq.cash_buffer.thin.cmt | B13: 0.16118171 | C13: % doanh thu | D13: Phải trả – R-AP-1 (điều kiện kèm), CMT | E13: verified_reference: FiinTrade 2016–2025, 27 DN may
A14: wc.dso.reference.fob | B14: 41.589239 | C14: ngày | D14: Phải thu – tham chiếu, FOB | E14: verified_reference: FiinTrade 2016–2025, 27 DN may
A15: wc.dso.watch.fob | B15: 56.722179 | C15: ngày | D15: Phải thu – R-AR-1, FOB | E15: verified_reference: FiinTrade 2016–2025, 27 DN may
A16: wc.dso.severe.fob | B16: 72.758392 | C16: ngày | D16: Phải thu – R-AR-2, FOB | E16: verified_reference: FiinTrade 2016–2025, 27 DN may
... A22: liq.cash_buffer.thin.fob | B22: 0.05317588 | C22: % doanh thu | D22: Phải trả – R-AP-1 (điều kiện kèm), FOB | E22: verified_reference: FiinTrade 2016–2025, 27 DN may
A23: wc.materiality_share | B23: 0.05 | C23: tỷ lệ TSNH | D23: R-MAT → W2 | E23: owner_policy (mặc định demo) | F23: Chủ DN duyệt; độ nhạy ở B5
A24: wc.severe_forces_w2 | B24: 1 | C24: cờ | D24: R-AR-2 / R-INV-2 → W2 | E24: owner_policy
A25: wc.factor.business_model.dso.cmt | B25: 0.66980693 | C25: hệ số | D25: Nhân vào ngưỡng DSO | E25: verified_reference | F25: p < 0,05
A26: wc.factor.business_model.dio.cmt | B26: 0.1 | C26: hệ số | D26: Nhân vào ngưỡng DIO | E26: verified_reference | F26: Đã chặn min
A27: wc.factor.size | B27: 1 | C27: hệ số | D27: Mọi ngưỡng | E27: verified_reference | F27: Không khác biệt có ý nghĩa → 1
A28: wc.factor.season | B28: 1 | C28: hệ số | D28: Ngưỡng DSO, DIO | E28: demo_assumption | F28: Chưa hiệu chỉnh
A29: ar.invoice.overdue_watch_rho | B29: 0.5 | C29: lần | D29: Cấp hóa đơn: ngày quá hạn / kỳ hạn | E29: demo_assumption | F29: Không hiệu chỉnh được từ BCTC
A30: ar.invoice.overdue_severe_rho | B30: 1 | C30: lần | D30: Cấp hóa đơn | E30: demo_assumption
A31: inv.lot.slow_days.nvl_hh | B31: 60 | C31: ngày | D31: Cấp lô: NVL, hàng hóa | E31: demo_assumption | F31: Giữ theo TV1 v1.3
A32: inv.lot.slow_days.btp_tp | B32: 30 | C32: ngày | D32: Cấp lô: BTP, thành phẩm | E32: demo_assumption | F32: Giữ theo TV1 v1.3
A34: Nguồn: Ngưỡng SMEs(2).xlsx / Nguong_SRS. Dòng 5–32 giữ cùng số dòng và đủ độ chính xác; các nhãn verified_reference là nhãn của tài liệu nguồn.
A38: Chỉ tiêu | B38: P10 ngành | C38: P25 ngành | D38: P50 ngành | E38: P75 ngành | F38: P90 ngành | G38: Trung vị CMT | H38: Trung vị ngành | I38: p-value | J38: Hệ số áp dụng
A39: DSO | B39: 21.525386 | C39: 30.041728 | D39: 39.220507 | E39: 53.491544 | F39: 68.614408 | G39: 26.270167 | H39: 39.220507 | I39: 0.012161286 | J39: =IF(I39<0.05,MIN(3,MAX(0.1,G39/H39)),1) -> 0.66980693
A40: DIO | B40: 23.402667 | C40: 50.090421 | D40: 71.334971 | E40: 94.688973 | F40: 137.01588 | G40: 6.2691796 | H40: 71.334971 | I40: 0.0061648034 | J40: =IF(I40<0.05,MIN(3,MAX(0.1,G40/H40)),1) -> 0.1
A41: DPO | B41: 12.067853 | C41: 20.234332 | D41: 31.055698 | E41: 54.461371 | F41: 79.786548 | G41: 6.7865922 | H41: 31.055698 | I41: 0.0097497369 | J41: =IF(I41<0.05,MIN(3,MAX(0.1,G41/H41)),1) -> 0.2185297
A42: Cash | B42: 0.021638222 | C42: 0.058418494 | D42: 0.11272339 | E42: 0.20957132 | F42: 0.35995356 | G42: 0.31101364 | H42: 0.11272339 | I42: 0.027890529 | J42: =IF(I42<0.05,MIN(3,MAX(0.1,G42/H42)),1) -> 2.759087
A45: Ngưỡng CMT tính lại | B45: Giá trị | C45: Cách đọc
A46: DSO theo dõi | B46: =E39*J39*B27*B28 -> 35.829007 | C46: P75 DSO × hệ số CMT × quy mô × mùa vụ
A47: DSO nghiêm trọng | B47: =F39*J39*B27*B28 -> 45.958406 | C47: P90 DSO × hệ số CMT × quy mô × mùa vụ
A48: DIO theo dõi | B48: =E40*J40*B27*B28 -> 9.4688973 | C48: P75 DIO × hệ số CMT × quy mô × mùa vụ
A49: DIO nghiêm trọng | B49: =F40*J40*B27*B28 -> 13.701588 | C49: P90 DIO × hệ số CMT × quy mô × mùa vụ
A50: DPO thấp | B50: =B41*J41*B27 -> 2.6371842 | C50: P10 DPO × hệ số CMT × quy mô
A51: DPO cao (thông tin) | B51: =E41*J41*B27 -> 11.901427 | C51: P75 DPO × hệ số CMT × quy mô
A52: Tiền mỏng (tỷ lệ năm) | B52: =C42*J42*B27 -> 0.16118171 | C52: P25 tỷ lệ tiền × hệ số CMT × quy mô
A53: Rmin ngành, tỷ lệ | B53: =C42*J42*B27 -> 0.16118171 | C53: Chỉ quy đổi bằng RevenueTTM thực khi chưa có owner_policy
...

Sheet F01_UC1
A2: F01 Chẩn đoán tại 20/06/2026
A4: Chỉ tiêu | B4: Giá trị | C4: Cách tính / giới hạn | D4: Đơn vị
A5: Doanh thu | B5: =D_F01!B9 -> 30000000000 | C5: Rev = financials.revenue_vnd | D5: VND
A6: Giá vốn | B6: =D_F01!B10 -> 24000000000 | C6: COGS = financials.cogs_vnd | D6: VND
A7: Số ngày kỳ | B7: =D_F01!B8 -> 171 | C7: Ngày cuối − ngày đầu +1 | D7: Ngày
A8: Phải thu | B8: =SUM(D_sales!N5:N115) -> 6885245902 | C8: AR = tổng dư hóa đơn bán mở | D8: VND
A9: Tồn sở hữu | B9: =SUM(D_inventory!P5:P37) -> 1.5737705e+09 | C9: INV = tổng giá trị lô thuộc F01 | D9: VND
A10: Phải trả | B10: =SUM(D_purchases!O5:O131) -> 1311475410 | C10: AP = tổng dư hóa đơn mua mở | D10: VND
A11: Tổng mua kỳ | B11: =SUM(D_purchases!G5:G131) -> 6589780047 | C11: PUR; không bằng giá vốn do có lao động và chi phí sản xuất | D11: VND
A12: DSO | B12: =B8/B5*B7 -> 39.245902 | C12: AR / Rev × N | D12: Ngày
A13: DIO | B13: =B9/B6*B7 -> 11.213115 | C13: INV / COGS × N | D13: Ngày
A14: DPO | B14: =B10/B6*B7 -> 9.3442623 | C14: AP / COGS × N | D14: Ngày
A15: CCC | B15: =B12+B13-B14 -> 41.114754 | C15: DSO + DIO − DPO | D15: Ngày
A16: Vốn thương mại ròng | B16: =B8+B9-B10 -> 7147540984 | C16: AR + INV − AP; không phải tiền mặt | D16: VND
A17: Phải thu quá hạn | B17: =SUMIFS(D_sales!N5:N115,D_sales!O5:O115,">0") -> 1260283330 | C17: Chỉ phần đã đến hạn chưa trả | D17: VND
A18: Phải trả quá hạn | B18: =SUMIFS(D_purchases!O5:O131,D_purchases!P5:P131,">0") -> 400396507 | C18: Không tự suy NCC ngừng cung ứng | D18: VND
A19: Tồn lâu hoặc đơn hủy | B19: =SUMPRODUCT(D_inventory!P5:P37,D_inventory!S5:S37) -> 4.2961299e+08 | C19: Hợp của hai cờ; không cộng trùng | D19: VND
A20: Tồn thuộc khách hàng | B20: =SUM(D_inventory!O5:O37)-B9 -> 3.405e+09 | C20: Loại khỏi INV, TWC và TSNH | D20: VND
A21: Tài sản ngắn hạn | B21: =D_F01!B11+D_F01!B13+D_F01!B14+B8+B9 -> 12459016394 | C21: Tiền + ĐTNH + tài sản khác + AR + INV | D21: VND
A22: Mức AR | B22: =IF(B12>Nguong!B47,2,IF(B12>Nguong!B46,1,0)) -> 1 | C22: So ngưỡng CMT, raw chưa làm tròn | D22: 0/1/2
A23: Mức INV | B23: =IF(B13>Nguong!B49,2,IF(B13>Nguong!B48,1,0)) -> 1 | C23: So ngưỡng CMT | D23: 0/1/2
A24: Doanh thu năm tham chiếu | B24: =IF(AND(ISNUMBER(D_F01!B21),D_F01!B21>0),D_F01!B21,B5*365/B7) -> 6.4035088e+10 | C24: Ưu tiên TTM thực; nếu thiếu, dùng proxy Rev×365/N chỉ trong demo | D24: VND
A25: Tỷ lệ tiền proxy | B25: =(D_F01!B11+D_F01!B13)/B24 -> 0.031232877 | C25: (Tiền + ĐTNH) / RevAnnualProxy | D25: Tỷ lệ
A26: Tín hiệu AP | B26: =IF(AND(B14<Nguong!B50,B25<Nguong!B52),1,0) -> 0 | C26: DPO thấp đồng thời tiền mỏng | D26: 0/1
A27: Vốn AR vượt ngưỡng | B27: =MAX(0,B12-Nguong!B46)*B5/B7 -> 5.9945523e+08 | C27: MAX(DSO − DSOWatch;0) × Rev/N | D27: VND
A28: Vốn tồn vượt ngưỡng | B28: =MAX(0,B13-Nguong!B48)*B6/B7 -> 2.4480245e+08 | C28: MAX(DIO − DIOWatch;0) × COGS/N | D28: VND
A29: Tỷ lệ trọng yếu | B29: =MAX(B27,B28)/B21 -> 0.048114169 | C29: MAX(vốn AR vượt; vốn tồn vượt) / TSNH | D29: Tỷ lệ
A30: Phân lớp W | B30: =IF(OR(B5<=0,B6<=0,B21<=0),"unknown",IF(OR(AND(Nguong!B24=1,MAX(B22,B23)=2),AND(MAX(B22,B23)>=1,B29>=Nguong!B23)),"W2",IF(OR(MAX(B22,B23)>=1,B26=1),"W1","W0"))) -> W1 | C30: Đúng B4 file SMEs; chi tiết quá hạn không tự nâng W | D30: Enum
A31: Vốn vượt tổng | B31: =B27+B28 -> 8.4425768e+08 | C31: Không cộng vào dòng thu hay mức thiếu UC02 | D31: VND
A32: Lô sở hữu lưu lâu nhất | B32: =_xlfn.MAXIFS(D_inventory!N5:N37,D_inventory!E5:E37,"F01") -> 228 | C32: Lưu kho có thể trước đầu kỳ | D32: Ngày
A33: Mô hình / trạng thái | B33: CMT / provisional | C33: Số dư cuối kỳ 171 ngày khác bình quân năm của ngành | D33: Nhãn
A40: Khách | B40: Tên | C40: Phải thu | D40: Tỷ trọng AR | E40: Góp DSO | F40: Quá hạn tổng | G40: 1–30 ngày | H40: 31–60 ngày | I40: >60 ngày | J40: MaxDPD | K40: Trễ có dấu 180d | L40: Trễ dương 180d | M40: Số hóa đơn đã thu | N40: Kỳ hạn hợp đồng | O40: Quan hệ demo
A41: BYR-F01-002 | B41: Nhà xuất khẩu Lớn K1 | C41: =SUMIFS(D_sales!$N$5:$N$115,D_sales!$C$5:$C$115,A41) -> 3823320516 | D41: =IF($B$8>0,C41/$B$8,0) -> 0.55529179 | E41: =C41/$B$5*$B$7 -> 21.792927 | F41: =SUMIFS(D_sales!$N$5:$N$115,D_sales!$C$5:$C$115,A41,D_sales!$O$5:$O$115,">0") -> 765714824 | G41: =SUMIFS(D_sales!$N$5:$N$115,D_sales!$C$5:$C$115,A41,D_sales!$O$5:$O$115,">0",D_sales!$O$5:$O$115,"<=30") -> 765714824 | H41: =SUMIFS(D_sales!$N$5:$N$115,D_sales!$C$5:$C$115,A41,D_sales!$O$5:$O$115,">30",D_sales!$O$5:$O$115,"<=60") -> 0 | I41: =SUMIFS(D_sales!$N$5:$N$115,D_sales!$C$5:$C$115,A41,D_sales!$O$5:$O$115,">60",D_sales!$O$5:$O$115,"<=9999") -> 0 | J41: =_xlfn.MAXIFS(D_sales!$O$5:$O$115,D_sales!$C$5:$C$115,A41) -> 21 | K41: =IF(SUMIFS(D_sales!$T$5:$T$115,D_sales!$C$5:$C$115,A41)=0,"n.a.",SUMIFS(D_sales!$Z$5:$Z$115,D_sales!$C$5:$C$115,A41)/SUMIFS(D_sales!$T$5:$T$115,D_sales!$C$5:$C$115,A41)) -> 18.68153 | L41: =IF(SUMIFS(D_sales!$T$5:$T$115,D_sales!$C$5:$C$115,A41)=0,"n.a.",SUMIFS(D_sales!$S$5:$S$115,D_sales!$C$5:$C$115,A41)/SUMIFS(D_sales!$T$5:$T$115,D_sales!$C$5:$C$115,A41)) -> 18.68153 | M41: =COUNTIFS(D_sales!$C$5:$C$115,A41,D_sales!$R$5:$R$115,1) -> 14 | N41: =IF(SUMIFS(D_sales!$T$5:$T$115,D_sales!$C$5:$C$115,A41)=0,"n.a.",SUMIFS(D_sales!$AA$5:$AA$115,D_sales!$C$5:$C$115,A41)/SUMIFS(D_sales!$T$5:$T$115,D_sales!$C$5:$C$115,A41)) -> 45 | O41: =IF(D_F01!$B$7-_xlfn.MINIFS(D_sales!$G$5:$G$115,D_sales!$C$5:$C$115,A41)+1<=60,"Mới",IF(AND(COUNTIF(D_sales!$C$5:$C$115,A41)>=12,6>=4),"Thường xuyên","Vãng lai")) -> Thường xuyên
A42: BYR-F01-001 | B42: Nhà xuất khẩu K2 | C42: =SUMIFS(D_sales!$N$5:$N$115,D_sales!$C$5:$C$115,A42) -> 1101205853 | D42: =IF($B$8>0,C42/$B$8,0) -> 0.15993704 | E42: =C42/$B$5*$B$7 -> 6.2768734 | F42: =SUMIFS(D_sales!$N$5:$N$115,D_sales!$C$5:$C$115,A42,D_sales!$O$5:$O$115,">0") -> 0 | G42: =SUMIFS(D_sales!$N$5:$N$115,D_sales!$C$5:$C$115,A42,D_sales!$O$5:$O$115,">0",D_sales!$O$5:$O$115,"<=30") -> 0 | H42: =SUMIFS(D_sales!$N$5:$N$115,D_sales!$C$5:$C$115,A42,D_sales!$O$5:$O$115,">30",D_sales!$O$5:$O$115,"<=60") -> 0 | I42: =SUMIFS(D_sales!$N$5:$N$115,D_sales!$C$5:$C$115,A42,D_sales!$O$5:$O$115,">60",D_sales!$O$5:$O$115,"<=9999") -> 0 | J42: =_xlfn.MAXIFS(D_sales!$O$5:$O$115,D_sales!$C$5:$C$115,A42) -> 0 | K42: =IF(SUMIFS(D_sales!$T$5:$T$115,D_sales!$C$5:$C$115,A42)=0,"n.a.",SUMIFS(D_sales!$Z$5:$Z$115,D_sales!$C$5:$C$115,A42)/SUMIFS(D_sales!$T$5:$T$115,D_sales!$C$5:$C$115,A42)) -> -1.1383316 | L42: =IF(SUMIFS(D_sales!$T$5:$T$115,D_sales!$C$5:$C$115,A42)=0,"n.a.",SUMIFS(D_sales!$S$5:$S$115,D_sales!$C$5:$C$115,A42)/SUMIFS(D_sales!$T$5:$T$115,D_sales!$C$5:$C$115,A42)) -> 1.1151265 | M42: =COUNTIFS(D_sales!$C$5:$C$115,A42,D_sales!$R$5:$R$115,1) -> 24 | N42: =IF(SUMIFS(D_sales!$T$5:$T$115,D_sales!$C$5:$C$115,A42)=0,"n.a.",SUMIFS(D_sales!$AA$5:$AA$115,D_sales!$C$5:$C$115,A42)/SUMIFS(D_sales!$T$5:$T$115,D_sales!$C$5:$C$115,A42)) -> 30 | O42: =IF(D_F01!$B$7-_xlfn.MINIFS(D_sales!$G$5:$G$115,D_sales!$C$5:$C$115,A42)+1<=60,"Mới",IF(AND(COUNTIF(D_sales!$C$5:$C$115,A42)>=12,6>=4),"Thường xuyên","Vãng lai")) -> Thường xuyên
A43: BYR-F01-005 | B43: Công ty may xuất khẩu K5 | C43: =SUMIFS(D_sales!$N$5:$N$115,D_sales!$C$5:$C$115,A43) -> 511520154 | D43: =IF($B$8>0,C43/$B$8,0) -> 0.074292213 | E43: =C43/$B$5*$B$7 -> 2.9156649 | F43: =SUMIFS(D_sales!$N$5:$N$115,D_sales!$C$5:$C$115,A43,D_sales!$O$5:$O$115,">0") -> 389384879 | G43: =SUMIFS(D_sales!$N$5:$N$115,D_sales!$C$5:$C$115,A43,D_sales!$O$5:$O$115,">0",D_sales!$O$5:$O$115,"<=30") -> 0 | H43: =SUMIFS(D_sales!$N$5:$N$115,D_sales!$C$5:$C$115,A43,D_sales!$O$5:$O$115,">30",D_sales!$O$5:$O$115,"<=60") -> 174551672 | I43: =SUMIFS(D_sales!$N$5:$N$115,D_sales!$C$5:$C$115,A43,D_sales!$O$5:$O$115,">60",D_sales!$O$5:$O$115,"<=9999") -> 214833207 | J43: =_xlfn.MAXIFS(D_sales!$O$5:$O$115,D_sales!$C$5:$C$115,A43) -> 67 | K43: =IF(SUMIFS(D_sales!$T$5:$T$115,D_sales!$C$5:$C$115,A43)=0,"n.a.",SUMIFS(D_sales!$Z$5:$Z$115,D_sales!$C$5:$C$115,A43)/SUMIFS(D_sales!$T$5:$T$115,D_sales!$C$5:$C$115,A43)) -> 5.3203879 | L43: =IF(SUMIFS(D_sales!$T$5:$T$115,D_sales!$C$5:$C$115,A43)=0,"n.a.",SUMIFS(D_sales!$S$5:$S$115,D_sales!$C$5:$C$115,A43)/SUMIFS(D_sales!$T$5:$T$115,D_sales!$C$5:$C$115,A43)) -> 5.3203879 | M43: =COUNTIFS(D_sales!$C$5:$C$115,A43,D_sales!$R$5:$R$115,1) -> 15 | N43: =IF(SUMIFS(D_sales!$T$5:$T$115,D_sales!$C$5:$C$115,A43)=0,"n.a.",SUMIFS(D_sales!$AA$5:$AA$115,D_sales!$C$5:$C$115,A43)/SUMIFS(D_sales!$T$5:$T$115,D_sales!$C$5:$C$115,A43)) -> 30 | O43: =IF(D_F01!$B$7-_xlfn.MINIFS(D_sales!$G$5:$G$115,D_sales!$C$5:$C$115,A43)+1<=60,"Mới",IF(AND(COUNTIF(D_sales!$C$5:$C$115,A43)>=12,6>=4),"Thường xuyên","Vãng lai")) -> Thường xuyên
A44: BYR-F01-006 | B44: Thương hiệu thời trang theo mùa K6 | C44: =SUMIFS(D_sales!$N$5:$N$115,D_sales!$C$5:$C$115,A44) -> 997764531 | D44: =IF($B$8>0,C44/$B$8,0) -> 0.14491342 | E44: =C44/$B$5*$B$7 -> 5.6872578 | F44: =SUMIFS(D_sales!$N$5:$N$115,D_sales!$C$5:$C$115,A44,D_sales!$O$5:$O$115,">0") -> 0 | G44: =SUMIFS(D_sales!$N$5:$N$115,D_sales!$C$5:$C$115,A44,D_sales!$O$5:$O$115,">0",D_sales!$O$5:$O$115,"<=30") -> 0 | H44: =SUMIFS(D_sales!$N$5:$N$115,D_sales!$C$5:$C$115,A44,D_sales!$O$5:$O$115,">30",D_sales!$O$5:$O$115,"<=60") -> 0 | I44: =SUMIFS(D_sales!$N$5:$N$115,D_sales!$C$5:$C$115,A44,D_sales!$O$5:$O$115,">60",D_sales!$O$5:$O$115,"<=9999") -> 0 | J44: =_xlfn.MAXIFS(D_sales!$O$5:$O$115,D_sales!$C$5:$C$115,A44) -> 0 | K44: =IF(SUMIFS(D_sales!$T$5:$T$115,D_sales!$C$5:$C$115,A44)=0,"n.a.",SUMIFS(D_sales!$Z$5:$Z$115,D_sales!$C$5:$C$115,A44)/SUMIFS(D_sales!$T$5:$T$115,D_sales!$C$5:$C$115,A44)) -> 0.28424073 | L44: =IF(SUMIFS(D_sales!$T$5:$T$115,D_sales!$C$5:$C$115,A44)=0,"n.a.",SUMIFS(D_sales!$S$5:$S$115,D_sales!$C$5:$C$115,A44)/SUMIFS(D_sales!$T$5:$T$115,D_sales!$C$5:$C$115,A44)) -> 1.4013312 | M44: =COUNTIFS(D_sales!$C$5:$C$115,A44,D_sales!$R$5:$R$115,1) -> 6 | N44: =IF(SUMIFS(D_sales!$T$5:$T$115,D_sales!$C$5:$C$115,A44)=0,"n.a.",SUMIFS(D_sales!$AA$5:$AA$115,D_sales!$C$5:$C$115,A44)/SUMIFS(D_sales!$T$5:$T$115,D_sales!$C$5:$C$115,A44)) -> 36.437466 | O44: =IF(D_F01!$B$7-_xlfn.MINIFS(D_sales!$G$5:$G$115,D_sales!$C$5:$C$115,A44)+1<=60,"Mới",IF(AND(COUNTIF(D_sales!$C$5:$C$115,A44)>=12,5>=4),"Thường xuyên","Vãng lai")) -> Vãng lai
A45: BYR-F01-003 | B45: Thương hiệu nội địa K3 | C45: =SUMIFS(D_sales!$N$5:$N$115,D_sales!$C$5:$C$115,A45) -> 249221739 | D45: =IF($B$8>0,C45/$B$8,0) -> 0.036196491 | E45: =C45/$B$5*$B$7 -> 1.4205639 | F45: =SUMIFS(D_sales!$N$5:$N$115,D_sales!$C$5:$C$115,A45,D_sales!$O$5:$O$115,">0") -> 0 | G45: =SUMIFS(D_sales!$N$5:$N$115,D_sales!$C$5:$C$115,A45,D_sales!$O$5:$O$115,">0",D_sales!$O$5:$O$115,"<=30") -> 0 | H45: =SUMIFS(D_sales!$N$5:$N$115,D_sales!$C$5:$C$115,A45,D_sales!$O$5:$O$115,">30",D_sales!$O$5:$O$115,"<=60") -> 0 | I45: =SUMIFS(D_sales!$N$5:$N$115,D_sales!$C$5:$C$115,A45,D_sales!$O$5:$O$115,">60",D_sales!$O$5:$O$115,"<=9999") -> 0 | J45: =_xlfn.MAXIFS(D_sales!$O$5:$O$115,D_sales!$C$5:$C$115,A45) -> 0 | K45: =IF(SUMIFS(D_sales!$T$5:$T$115,D_sales!$C$5:$C$115,A45)=0,"n.a.",SUMIFS(D_sales!$Z$5:$Z$115,D_sales!$C$5:$C$115,A45)/SUMIFS(D_sales!$T$5:$T$115,D_sales!$C$5:$C$115,A45)) -> 2.200413 | L45: =IF(SUMIFS(D_sales!$T$5:$T$115,D_sales!$C$5:$C$115,A45)=0,"n.a.",SUMIFS(D_sales!$S$5:$S$115,D_sales!$C$5:$C$115,A45)/SUMIFS(D_sales!$T$5:$T$115,D_sales!$C$5:$C$115,A45)) -> 2.3803458 | M45: =COUNTIFS(D_sales!$C$5:$C$115,A45,D_sales!$R$5:$R$115,1) -> 11 | N45: =IF(SUMIFS(D_sales!$T$5:$T$115,D_sales!$C$5:$C$115,A45)=0,"n.a.",SUMIFS(D_sales!$AA$5:$AA$115,D_sales!$C$5:$C$115,A45)/SUMIFS(D_sales!$T$5:$T$115,D_sales!$C$5:$C$115,A45)) -> 30 | O45: =IF(D_F01!$B$7-_xlfn.MINIFS(D_sales!$G$5:$G$115,D_sales!$C$5:$C$115,A45)+1<=60,"Mới",IF(AND(COUNTIF(D_sales!$C$5:$C$115,A45)>=12,5>=4),"Thường xuyên","Vãng lai")) -> Thường xuyên
A46: BYR-F01-007 | B46: Đại lý vãng lai K7 | C46: =SUMIFS(D_sales!$N$5:$N$115,D_sales!$C$5:$C$115,A46) -> 0 | D46: =IF($B$8>0,C46/$B$8,0) -> 0 | E46: =C46/$B$5*$B$7 -> 0 | F46: =SUMIFS(D_sales!$N$5:$N$115,D_sales!$C$5:$C$115,A46,D_sales!$O$5:$O$115,">0") -> 0 | G46: =SUMIFS(D_sales!$N$5:$N$115,D_sales!$C$5:$C$115,A46,D_sales!$O$5:$O$115,">0",D_sales!$O$5:$O$115,"<=30") -> 0 | H46: =SUMIFS(D_sales!$N$5:$N$115,D_sales!$C$5:$C$115,A46,D_sales!$O$5:$O$115,">30",D_sales!$O$5:$O$115,"<=60") -> 0 | I46: =SUMIFS(D_sales!$N$5:$N$115,D_sales!$C$5:$C$115,A46,D_sales!$O$5:$O$115,">60",D_sales!$O$5:$O$115,"<=9999") -> 0 | J46: =_xlfn.MAXIFS(D_sales!$O$5:$O$115,D_sales!$C$5:$C$115,A46) -> 0 | K46: =IF(SUMIFS(D_sales!$T$5:$T$115,D_sales!$C$5:$C$115,A46)=0,"n.a.",SUMIFS(D_sales!$Z$5:$Z$115,D_sales!$C$5:$C$115,A46)/SUMIFS(D_sales!$T$5:$T$115,D_sales!$C$5:$C$115,A46)) -> 1.19485 | L46: =IF(SUMIFS(D_sales!$T$5:$T$115,D_sales!$C$5:$C$115,A46)=0,"n.a.",SUMIFS(D_sales!$S$5:$S$115,D_sales!$C$5:$C$115,A46)/SUMIFS(D_sales!$T$5:$T$115,D_sales!$C$5:$C$115,A46)) -> 2.4512708 | M46: =COUNTIFS(D_sales!$C$5:$C$115,A46,D_sales!$R$5:$R$115,1) -> 3 | N46: =IF(SUMIFS(D_sales!$T$5:$T$115,D_sales!$C$5:$C$115,A46)=0,"n.a.",SUMIFS(D_sales!$AA$5:$AA$115,D_sales!$C$5:$C$115,A46)/SUMIFS(D_sales!$T$5:$T$115,D_sales!$C$5:$C$115,A46)) -> 30 | O46: =IF(D_F01!$B$7-_xlfn.MINIFS(D_sales!$G$5:$G$115,D_sales!$C$5:$C$115,A46)+1<=60,"Mới",IF(AND(COUNTIF(D_sales!$C$5:$C$115,A46)>=12,3>=4),"Thường xuyên","Vãng lai")) -> Vãng lai
A47: BYR-F01-004 | B47: Khách mới K4 | C47: =SUMIFS(D_sales!$N$5:$N$115,D_sales!$C$5:$C$115,A47) -> 177887054 | D47: =IF($B$8>0,C47/$B$8,0) -> 0.025835977 | E47: =C47/$B$5*$B$7 -> 1.0139562 | F47: =SUMIFS(D_sales!$N$5:$N$115,D_sales!$C$5:$C$115,A47,D_sales!$O$5:$O$115,">0") -> 80857572 | G47: =SUMIFS(D_sales!$N$5:$N$115,D_sales!$C$5:$C$115,A47,D_sales!$O$5:$O$115,">0",D_sales!$O$5:$O$115,"<=30") -> 80857572 | H47: =SUMIFS(D_sales!$N$5:$N$115,D_sales!$C$5:$C$115,A47,D_sales!$O$5:$O$115,">30",D_sales!$O$5:$O$115,"<=60") -> 0 | I47: =SUMIFS(D_sales!$N$5:$N$115,D_sales!$C$5:$C$115,A47,D_sales!$O$5:$O$115,">60",D_sales!$O$5:$O$115,"<=9999") -> 0 | J47: =_xlfn.MAXIFS(D_sales!$O$5:$O$115,D_sales!$C$5:$C$115,A47) -> 19 | K47: =IF(SUMIFS(D_sales!$T$5:$T$115,D_sales!$C$5:$C$115,A47)=0,"n.a.",SUMIFS(D_sales!$Z$5:$Z$115,D_sales!$C$5:$C$115,A47)/SUMIFS(D_sales!$T$5:$T$115,D_sales!$C$5:$C$115,A47)) -> n.a. | L47: =IF(SUMIFS(D_sales!$T$5:$T$115,D_sales!$C$5:$C$115,A47)=0,"n.a.",SUMIFS(D_sales!$S$5:$S$115,D_sales!$C$5:$C$115,A47)/SUMIFS(D_sales!$T$5:$T$115,D_sales!$C$5:$C$115,A47)) -> n.a. | M47: =COUNTIFS(D_sales!$C$5:$C$115,A47,D_sales!$R$5:$R$115,1) -> 0 | N47: =IF(SUMIFS(D_sales!$T$5:$T$115,D_sales!$C$5:$C$115,A47)=0,"n.a.",SUMIFS(D_sales!$AA$5:$AA$115,D_sales!$C$5:$C$115,A47)/SUMIFS(D_sales!$T$5:$T$115,D_sales!$C$5:$C$115,A47)) -> n.a. | O47: =IF(D_F01!$B$7-_xlfn.MINIFS(D_sales!$G$5:$G$115,D_sales!$C$5:$C$115,A47)+1<=60,"Mới",IF(AND(COUNTIF(D_sales!$C$5:$C$115,A47)>=12,2>=4),"Thường xuyên","Vãng lai")) -> Mới
A48: BYR-F01-008 | B48: Cửa hàng nhỏ K8 | C48: =SUMIFS(D_sales!$N$5:$N$115,D_sales!$C$5:$C$115,A48) -> 24326055 | D48: =IF($B$8>0,C48/$B$8,0) -> 0.0035330699 | E48: =C48/$B$5*$B$7 -> 0.13865851 | F48: =SUMIFS(D_sales!$N$5:$N$115,D_sales!$C$5:$C$115,A48,D_sales!$O$5:$O$115,">0") -> 24326055 | G48: =SUMIFS(D_sales!$N$5:$N$115,D_sales!$C$5:$C$115,A48,D_sales!$O$5:$O$115,">0",D_sales!$O$5:$O$115,"<=30") -> 0 | H48: =SUMIFS(D_sales!$N$5:$N$115,D_sales!$C$5:$C$115,A48,D_sales!$O$5:$O$115,">30",D_sales!$O$5:$O$115,"<=60") -> 0 | I48: =SUMIFS(D_sales!$N$5:$N$115,D_sales!$C$5:$C$115,A48,D_sales!$O$5:$O$115,">60",D_sales!$O$5:$O$115,"<=9999") -> 24326055 | J48: =_xlfn.MAXIFS(D_sales!$O$5:$O$115,D_sales!$C$5:$C$115,A48) -> 82 | K48: =IF(SUMIFS(D_sales!$T$5:$T$115,D_sales!$C$5:$C$115,A48)=0,"n.a.",SUMIFS(D_sales!$Z$5:$Z$115,D_sales!$C$5:$C$115,A48)/SUMIFS(D_sales!$T$5:$T$115,D_sales!$C$5:$C$115,A48)) -> 0 | L48: =IF(SUMIFS(D_sales!$T$5:$T$115,D_sales!$C$5:$C$115,A48)=0,"n.a.",SUMIFS(D_sales!$S$5:$S$115,D_sales!$C$5:$C$115,A48)/SUMIFS(D_sales!$T$5:$T$115,D_sales!$C$5:$C$115,A48)) -> 0 | M48: =COUNTIFS(D_sales!$C$5:$C$115,A48,D_sales!$R$5:$R$115,1) -> 3 | N48: =IF(SUMIFS(D_sales!$T$5:$T$115,D_sales!$C$5:$C$115,A48)=0,"n.a.",SUMIFS(D_sales!$AA$5:$AA$115,D_sales!$C$5:$C$115,A48)/SUMIFS(D_sales!$T$5:$T$115,D_sales!$C$5:$C$115,A48)) -> 30 | O48: =IF(D_F01!$B$7-_xlfn.MINIFS(D_sales!$G$5:$G$115,D_sales!$C$5:$C$115,A48)+1<=60,"Mới",IF(AND(COUNTIF(D_sales!$C$5:$C$115,A48)>=12,2>=4),"Thường xuyên","Vãng lai")) -> Vãng lai
...

Sheet F01_UC2
A2: F01 Dự báo tiền từ 21/06 đến 19/09/2026
A4: Chỉ tiêu | B4: Giá trị | C4: Ý nghĩa
A5: Kịch bản | B5: =CHOOSE(D_F01!B19,"Base","Optimistic","Conservative","Stress7","Continuing") -> Base | C5: Một selector tại D_F01!B19
A6: Ngày đầu | B6: =D_F01!B7+1 -> 46194 | C6: AsOf+1
A7: Ngày cuối | B7: =D_F01!B7+7*D_F01!B18 -> 46284 | C7: H13=91 ngày; không phải N171
A8: Cash0 | B8: =D_F01!B11-D_F01!B12 -> 1200000000 | C8: Tiền khả dụng giả lập tại ngày chốt
A9: Rmin | B9: =D_F01!B15 -> 250000000 | C9: Dưới sàn này là Đỏ kể cả còn tiền dương
A10: Rtarget | B10: =D_F01!B16 -> 500000000 | C10: Mục tiêu dự trữ, không phải dòng chi
A11: Rupper | B11: =D_F01!B17 -> 1000000000 | C11: Trên trần liên tục ≥14 ngày mới là dư bền
A12: MinCash | B12: =MIN(G70:G160) -> -3063626768 | C12: Số dư cuối ngày thấp nhất
A13: Ngày MinCash | B13: =INDEX(A70:A160,MATCH(B12,G70:G160,0)) -> 46283 | C13: Nếu bằng nhau lấy ngày đầu
A14: PeakBuffer | B14: =MAX(H70:H160) -> 3563626768 | C14: Không cộng gap lặp qua ngày
A15: PeakZero | B15: =MAX(I70:I160) -> 3063626768 | C15: Không cộng với PeakBuffer
A16: MinCum | B16: =MIN(0,MIN(D70:D160)) -> -4263626768 | C16: Lũy kế thu trừ chi, chưa có Cash0
A17: NeedTarget | B17: =MAX(0,B10-B16) -> 4763626768 | C17: Tổng tiền đầu kỳ cần để không dưới mục tiêu
A18: NeedZero | B18: =MAX(0,-B16) -> 4263626768 | C18: Tổng tiền đầu kỳ cần để không âm
A19: Additional | B19: =MAX(0,B17-B8) -> 3563626768 | C19: NeedTarget trừ tiền đang có, chặn dưới 0
A20: Ngày đầu thiếu | B20: =IF(COUNTIF(G70:G160,"<"&B10)=0,"n.a.",_xlfn.MINIFS(A70:A160,G70:G160,"<"&B10)) -> 46203 | C20: Không có ngày thiếu → n.a.
A21: Ngày đầu âm | B21: =IF(COUNTIF(G70:G160,"<0")=0,"n.a.",_xlfn.MINIFS(A70:A160,G70:G160,"<0")) -> 46234 | C21: Tách riêng ngày đầu dưới dự trữ
A22: Cảnh báo toàn kỳ | B22: =CHOOSE(MAX(K70:K160)+1,"Không cảnh báo","Vàng","Cam","Đỏ") -> Đỏ | C22: Mức nặng nhất theo ngày của kịch bản đang chọn
A23: TH để định tuyến | B23: =IF(D_F01!B19<>1,"Chọn Base để định tuyến",IF(MIN(G70:G160)<B10,"TH01",IF(MAX(M70:M160)>=14,"TH03","TH02"))) -> TH01 | C23: Chỉ Base xác định TH chính thức; run-off dư chỉ là tham chiếu
A24: Ô ma trận | B24: =IF(D_F01!B19<>1,"n.a.",IF(F01_UC1!B30="unknown","n.a.","M"&(VALUE(RIGHT(F01_UC1!B30,1))*3+VALUE(RIGHT(B23,1))))) -> M4 | C24: W và TH cùng snapshot; LLM không chọn ô
A25: Trạng thái | B25: provisional | C25: Dữ liệu hư cấu, net/noVAT, lịch chi quá hạn là giả định
A26: Chế độ | B26: =D_F01!B20 -> run_off | C26: Run-off không có toàn bộ hoạt động mới; continuing có thêm cả thu và chi
A28: Tuần | B28: Ngày đầu | C28: Ngày cuối | D28: Thu | E28: Chi | F28: Cuối tuần | G28: Thấp nhất tuần | H28: Ngày thấp nhất | I28: Mức cuối tuần | J28: Mức xấu nhất | L28: Khối | M28: Ngày đầu | N28: Ngày cuối | O28: MinDaily | P28: Trạng thái | Q28: Mức xấu nhất | R28: Số ngày | S28: Giới hạn
A29: 1 | B29: =$B$6+0 -> 46194 | C29: =B29+6 -> 46200 | D29: =SUMIFS($B$70:$B$160,$A$70:$A$160,">="&B29,$A$70:$A$160,"<="&C29) -> 869815315 | E29: =SUMIFS($C$70:$C$160,$A$70:$A$160,">="&B29,$A$70:$A$160,"<="&C29) -> 315656774 | F29: =INDEX($G$70:$G$160,MATCH(C29,$A$70:$A$160,0)) -> 1754158541 | G29: =_xlfn.MINIFS($G$70:$G$160,$A$70:$A$160,">="&B29,$A$70:$A$160,"<="&C29) -> 1173205255 | H29: =_xlfn.MINIFS($A$70:$A$160,$A$70:$A$160,">="&B29,$A$70:$A$160,"<="&C29,$G$70:$G$160,G29) -> 46194 | I29: =INDEX($K$70:$K$160,MATCH(C29,$A$70:$A$160,0)) -> 0 | J29: =_xlfn.MAXIFS($K$70:$K$160,$A$70:$A$160,">="&B29,$A$70:$A$160,"<="&C29) -> 0 | L29: =1 -> 1 | M29: =$B$6+0 -> 46194 | N29: =MIN($B$7,M29+13) -> 46207 | O29: =_xlfn.MINIFS($G$70:$G$160,$A$70:$A$160,">="&M29,$A$70:$A$160,"<="&N29) -> 797304 | P29: =IF(O29<$B$10,"Thiếu",IF(O29>$B$11,"Dư","Cân bằng")) -> Thiếu | Q29: =_xlfn.MAXIFS($K$70:$K$160,$A$70:$A$160,">="&M29,$A$70:$A$160,"<="&N29) -> 3 | R29: =N29-M29+1 -> 14 | S29: =IF(R29=7,"Khối cuối 7 ngày","Khối 14 ngày") -> Khối 14 ngày
A30: 2 | B30: =$B$6+7 -> 46201 | C30: =B30+6 -> 46207 | D30: =SUMIFS($B$70:$B$160,$A$70:$A$160,">="&B30,$A$70:$A$160,"<="&C30) -> 1961945965 | E30: =SUMIFS($C$70:$C$160,$A$70:$A$160,">="&B30,$A$70:$A$160,"<="&C30) -> 3192473589 | F30: =INDEX($G$70:$G$160,MATCH(C30,$A$70:$A$160,0)) -> 523630917 | G30: =_xlfn.MINIFS($G$70:$G$160,$A$70:$A$160,">="&B30,$A$70:$A$160,"<="&C30) -> 797304 | H30: =_xlfn.MINIFS($A$70:$A$160,$A$70:$A$160,">="&B30,$A$70:$A$160,"<="&C30,$G$70:$G$160,G30) -> 46203 | I30: =INDEX($K$70:$K$160,MATCH(C30,$A$70:$A$160,0)) -> 0 | J30: =_xlfn.MAXIFS($K$70:$K$160,$A$70:$A$160,">="&B30,$A$70:$A$160,"<="&C30) -> 3 | L30: =2 -> 2 | M30: =$B$6+14 -> 46208 | N30: =MIN($B$7,M30+13) -> 46221 | O30: =_xlfn.MINIFS($G$70:$G$160,$A$70:$A$160,">="&M30,$A$70:$A$160,"<="&N30) -> 470478434 | P30: =IF(O30<$B$10,"Thiếu",IF(O30>$B$11,"Dư","Cân bằng")) -> Thiếu | Q30: =_xlfn.MAXIFS($K$70:$K$160,$A$70:$A$160,">="&M30,$A$70:$A$160,"<="&N30) -> 1 | R30: =N30-M30+1 -> 14 | S30: =IF(R30=7,"Khối cuối 7 ngày","Khối 14 ngày") -> Khối 14 ngày
A31: 3 | B31: =$B$6+14 -> 46208 | C31: =B31+6 -> 46214 | D31: =SUMIFS($B$70:$B$160,$A$70:$A$160,">="&B31,$A$70:$A$160,"<="&C31) -> 918677924 | E31: =SUMIFS($C$70:$C$160,$A$70:$A$160,">="&B31,$A$70:$A$160,"<="&C31) -> 207442851 | F31: =INDEX($G$70:$G$160,MATCH(C31,$A$70:$A$160,0)) -> 1234865990 | G31: =_xlfn.MINIFS($G$70:$G$160,$A$70:$A$160,">="&B31,$A$70:$A$160,"<="&C31) -> 470478434 | H31: =_xlfn.MINIFS($A$70:$A$160,$A$70:$A$160,">="&B31,$A$70:$A$160,"<="&C31,$G$70:$G$160,G31) -> 46208 | I31: =INDEX($K$70:$K$160,MATCH(C31,$A$70:$A$160,0)) -> 0 | J31: =_xlfn.MAXIFS($K$70:$K$160,$A$70:$A$160,">="&B31,$A$70:$A$160,"<="&C31) -> 1 | L31: =3 -> 3 | M31: =$B$6+28 -> 46222 | N31: =MIN($B$7,M31+13) -> 46235 | O31: =_xlfn.MINIFS($G$70:$G$160,$A$70:$A$160,">="&M31,$A$70:$A$160,"<="&N31) -> -522821317 | P31: =IF(O31<$B$10,"Thiếu",IF(O31>$B$11,"Dư","Cân bằng")) -> Thiếu | Q31: =_xlfn.MAXIFS($K$70:$K$160,$A$70:$A$160,">="&M31,$A$70:$A$160,"<="&N31) -> 3 | R31: =N31-M31+1 -> 14 | S31: =IF(R31=7,"Khối cuối 7 ngày","Khối 14 ngày") -> Khối 14 ngày
A32: 4 | B32: =$B$6+21 -> 46215 | C32: =B32+6 -> 46221 | D32: =SUMIFS($B$70:$B$160,$A$70:$A$160,">="&B32,$A$70:$A$160,"<="&C32) -> 743512543 | E32: =SUMIFS($C$70:$C$160,$A$70:$A$160,">="&B32,$A$70:$A$160,"<="&C32) -> 275438990 | F32: =INDEX($G$70:$G$160,MATCH(C32,$A$70:$A$160,0)) -> 1702939543 | G32: =_xlfn.MINIFS($G$70:$G$160,$A$70:$A$160,">="&B32,$A$70:$A$160,"<="&C32) -> 1234865990 | H32: =_xlfn.MINIFS($A$70:$A$160,$A$70:$A$160,">="&B32,$A$70:$A$160,"<="&C32,$G$70:$G$160,G32) -> 46215 | I32: =INDEX($K$70:$K$160,MATCH(C32,$A$70:$A$160,0)) -> 0 | J32: =_xlfn.MAXIFS($K$70:$K$160,$A$70:$A$160,">="&B32,$A$70:$A$160,"<="&C32) -> 0 | L32: =4 -> 4 | M32: =$B$6+42 -> 46236 | N32: =MIN($B$7,M32+13) -> 46249 | O32: =_xlfn.MINIFS($G$70:$G$160,$A$70:$A$160,">="&M32,$A$70:$A$160,"<="&N32) -> -522821317 | P32: =IF(O32<$B$10,"Thiếu",IF(O32>$B$11,"Dư","Cân bằng")) -> Thiếu | Q32: =_xlfn.MAXIFS($K$70:$K$160,$A$70:$A$160,">="&M32,$A$70:$A$160,"<="&N32) -> 3 | R32: =N32-M32+1 -> 14 | S32: =IF(R32=7,"Khối cuối 7 ngày","Khối 14 ngày") -> Khối 14 ngày
A33: 5 | B33: =$B$6+28 -> 46222 | C33: =B33+6 -> 46228 | D33: =SUMIFS($B$70:$B$160,$A$70:$A$160,">="&B33,$A$70:$A$160,"<="&C33) -> 821516015 | E33: =SUMIFS($C$70:$C$160,$A$70:$A$160,">="&B33,$A$70:$A$160,"<="&C33) -> 343087379 | F33: =INDEX($G$70:$G$160,MATCH(C33,$A$70:$A$160,0)) -> 2181368179 | G33: =_xlfn.MINIFS($G$70:$G$160,$A$70:$A$160,">="&B33,$A$70:$A$160,"<="&C33) -> 1964661800 | H33: =_xlfn.MINIFS($A$70:$A$160,$A$70:$A$160,">="&B33,$A$70:$A$160,"<="&C33,$G$70:$G$160,G33) -> 46222 | I33: =INDEX($K$70:$K$160,MATCH(C33,$A$70:$A$160,0)) -> 0 | J33: =_xlfn.MAXIFS($K$70:$K$160,$A$70:$A$160,">="&B33,$A$70:$A$160,"<="&C33) -> 0 | L33: =5 -> 5 | M33: =$B$6+56 -> 46250 | N33: =MIN($B$7,M33+13) -> 46263 | O33: =_xlfn.MINIFS($G$70:$G$160,$A$70:$A$160,">="&M33,$A$70:$A$160,"<="&N33) -> -63697085 | P33: =IF(O33<$B$10,"Thiếu",IF(O33>$B$11,"Dư","Cân bằng")) -> Thiếu | Q33: =_xlfn.MAXIFS($K$70:$K$160,$A$70:$A$160,">="&M33,$A$70:$A$160,"<="&N33) -> 3 | R33: =N33-M33+1 -> 14 | S33: =IF(R33=7,"Khối cuối 7 ngày","Khối 14 ngày") -> Khối 14 ngày
