Workbook

Sheet Read_me
A2: Hướng dẫn đọc và phạm vi dữ liệu
A4: Mục | B4: Nội dung | C4: Đọc / kiểm tra ở đâu
A5: Phạm vi | B5: Đặc tả và workbook minh họa UC01–UC04 cho doanh nghiệp may F01 theo mô hình FOB: tự mua NVL, sản xuất và bán thành phẩm. Dữ liệu F01 hoàn toàn hư cấu. | C5: Bản v11 đồng bộ nguồn ngưỡng FOB 2023–2025 và Miller–Orr; giữ bố cục gốc.
A6: Kỳ UC01 | B6: 01/01–30/06/2026 (bán niên), N=181 ngày. Ngày chốt chung 30/06/2026. | C6: D_F01; F01_UC1
A7: Kỳ UC02 | B7: 01/07–29/09/2026, 13 tuần/91 ngày. Không lấy 181 ngày làm kỳ dự báo. | C7: F01_UC2
A8: Cách đọc | B8: 1. Đọc Read_me → 2. Xem bảng công thức UC1/UC2/UC3/UC4 → 3. Kiểm tra Nguong → 4. Xem các bảng minh họa F01 → 5. Đối soát Kiem_thu và kiểm tra UC04. | C8: Các sheet D_* là đầu vào dùng chung, không có F02/F03.
A9: Cách viết công thức | B9: Mỗi dòng có tên biến, phép tính, phạm vi, đơn vị và ngoại lệ. Dấu Σ là cộng các dòng thỏa điều kiện; MAX(0;x) là chỉ giữ phần dương. | C9: Không dùng công thức dài thay định nghĩa nghiệp vụ.
A10: Dữ liệu được giữ | B10: 117 hóa đơn bán, 135 hóa đơn mua, 36 lô sở hữu F01. Giá trị và cấu hình kinh doanh được tạo sinh lại cho FOB; doanh thu/giá vốn tính từ bảng dữ liệu. | C10: D_sales, D_purchases, D_inventory
A11: Điều chỉnh ngày | B11: Giữ khóa giao dịch v10 và nối dài dữ liệu đến ngày chốt 30/06/2026 (hóa đơn, lô tồn, dòng tiền ngày 21–30/06). Hóa đơn đã trả trong 21–30/06 ghi PaidDate; số ngày quá hạn / lưu kho tính lại tại ngày chốt mới. | C11: Số ngày quá hạn / lưu kho tại chốt giữ khi không bị giới hạn đầu kỳ; lưu vết tại D_F01.
A12: Không giữ kết quả cũ bằng ép số | B12: Không ép W hoặc TH về một nhãn định sẵn. Kết quả được tính lại từ đầu vào FOB và ngưỡng nguồn. | C12: Ví dụ mới được tính độc lập trong Kiem_thu.
A13: Bổ sung để chạy UC02 | B13: Lịch lương, thuế, thuê xưởng, trả nợ và một lịch thu xác nhận đều là giả lập biết tại ngày chốt; không có trong dữ liệu gốc. | C13: D_flows có source_type, source_ref, known_at và cờ essential.
A14: Nguồn ưu tiên | B14: Nguồn chuẩn duy nhất về ngưỡng và ma trận: Nguong_SMEs_FOB_2023_2025 (1).xlsx, config fob.threshold.v3. Công thức dự báo giữ cơ chế sự kiện và chống cộng trùng. | C14: Nguong ghi nguồn theo sheet/ô; không thay ngưỡng bằng số đã làm tròn trong SRS.
A15: Khác cơ sở ngành | B15: Ngành dùng năm và số dư bình quân; F01 dùng 181 ngày và số dư cuối kỳ. So sánh có nhãn provisional, chỉ định hướng. | C15: Không đổi ngưỡng ngày theo tỷ lệ 181/365. Quy đổi vốn vượt dùng Rev/N hoặc COGS/N.
... A58: MinCash Base; TH; ô ma trận | B58: 4,64 tỷ (21/06); TH01; M3 | C58: 4,14 tỷ (02/07); TH01; M3

Sheet UC1_Cong_thuc
A2: UC01 Chẩn đoán vốn lưu động
A4: Mã | B4: Nhóm công thức | C4: Chỉ tiêu | D4: Ý nghĩa dễ hiểu | E4: Công thức từng bước | F4: Dữ liệu đầu vào | G4: Phạm vi / điều kiện | H4: Đơn vị / hiển thị | I4: Ngoại lệ / kiểm soát
A5: T1-01 | B5: 01. Số dư và chu kỳ | C5: Doanh thu kỳ (Rev) | D5: Quy mô bán hàng trong N ngày | E5: Rev = financials.revenue_vnd | F5: financials.revenue_vnd; workbook D_F01!B9 | G5: firm_id của phiên; firm_id = F01; ngày chốt 30/06/2026. Kỳ phát sinh 01/01–30/06 nếu áp dụng. | H5: VND | I5: Rev=0: chỉ tiêu phụ thuộc not_applicable. Thiếu Rev: missing_data. Demo dùng tổng doanh thu như proxy bán chịu.
A6: T1-02 | B6: 01. Số dư và chu kỳ | C6: Giá vốn kỳ (COGS) | D6: Chi phí làm ra hàng đã bán, gồm cả lương công nhân | E6: COGS = financials.cogs_vnd | F6: financials.cogs_vnd; workbook D_F01!B10 | G6: firm_id của phiên; firm_id = F01; ngày chốt 30/06/2026. Kỳ phát sinh 01/01–30/06 nếu áp dụng. | H6: VND | I6: COGS=0: tỷ số phụ thuộc not_applicable. Thiếu COGS: missing_data.
A7: T1-03 | B7: 01. Số dư và chu kỳ | C7: Phải thu (AR) | D7: Tiền khách còn nợ | E7: AR = Σ OpenAmount của hóa đơn bán | F7: sales_invoices.Amount | G7: Hóa đơn mở tại AsOf; firm_id = F01; ngày chốt 30/06/2026. Kỳ phát sinh 01/01–30/06 nếu áp dụng. | H7: VND | I7: Không có hóa đơn mở → AR = 0 (hợp lệ)
A8: T1-04 | B8: 01. Số dư và chu kỳ | C8: Tồn kho (INV) | D8: Tiền nằm trong kho dưới dạng hàng | E8: INV = Σ Qty × UnitCost của lô thuộc F01 | F8: inventory.qty, unit_cost_vnd, inventory_type | G8: inventory_type ≠ HGC; firm_id = F01; ngày chốt 30/06/2026. Kỳ phát sinh 01/01–30/06 nếu áp dụng. | H8: VND | I8: Thiếu loại/quyền sở hữu: chưa xác định, không tự coi NVL. Demo HGC loại; cost chưa NRV có nhãn.
A9: T1-05 | B9: 01. Số dư và chu kỳ | C9: Phải trả (AP) | D9: Số tiền doanh nghiệp còn nợ nhà cung cấp | E9: AP = Σ OpenAmount của hóa đơn mua | F9: purchase_invoices.Amount | G9: Hóa đơn mở tại AsOf; firm_id = F01; ngày chốt 30/06/2026. Kỳ phát sinh 01/01–30/06 nếu áp dụng. | H9: VND | I9: Không có hóa đơn mở → AP = 0 (hợp lệ)
A10: T1-06 | B10: 01. Số dư và chu kỳ | C10: Mua hàng trong kỳ (PUR) | D10: Giá trị mua chịu từ nhà cung cấp trong N ngày | E10: PUR = Σ Amount hóa đơn mua phát hành trong kỳ | F10: purchase_invoices.Amount, issue_date | G10: AsOf − N + 1 ≤ issue_date ≤ AsOf; firm_id = F01; ngày chốt 30/06/2026. Kỳ phát sinh 01/01–30/06 nếu áp dụng. | H10: VND | I10: PUR = 0 → bỏ T1-11
A11: T1-07 | B11: 01. Số dư và chu kỳ | C11: DSO | D11: Phải thu quy đổi thành số ngày theo doanh thu kỳ; không là ngày tiền chắc chắn về. | E11: DSO = AR / Rev × N | F11: T1-03, T1-01 | G11: –; firm_id = F01; ngày chốt 30/06/2026. Kỳ phát sinh 01/01–30/06 nếu áp dụng. | H11: ngày; 1 số lẻ khi xuất | I11: Rev=0: not_applicable. Thiếu trường: missing_data.
A12: T1-08 | B12: 01. Số dư và chu kỳ | C12: DIO | D12: Tồn kho quy đổi theo giá vốn kỳ; khác số ngày một lô đã lưu kho. | E12: DIO = INV / COGS × N | F12: T1-04, T1-02 | G12: –; firm_id = F01; ngày chốt 30/06/2026. Kỳ phát sinh 01/01–30/06 nếu áp dụng. | H12: ngày; 1 số lẻ | I12: COGS=0: not_applicable. Thiếu trường: missing_data.
A13: T1-09 | B13: 01. Số dư và chu kỳ | C13: DPO | D13: Phải trả cuối kỳ quy đổi theo giá vốn kỳ; không phải kỳ hạn hợp đồng thực tế. | E13: DPO = AP / COGS × N | F13: T1-05, T1-02 | G13: –; firm_id = F01; ngày chốt 30/06/2026. Kỳ phát sinh 01/01–30/06 nếu áp dụng. | H13: ngày; 1 số lẻ | I13: COGS=0: not_applicable. Thiếu trường: missing_data.
A14: T1-10 | B14: 01. Số dư và chu kỳ | C14: CCC | D14: DSO + DIO − DPO theo cùng phương pháp và kỳ. | E14: CCC = DSO + DIO − DPO | F14: T1-07..T1-09 (chưa làm tròn) | G14: –; firm_id = F01; ngày chốt 30/06/2026. Kỳ phát sinh 01/01–30/06 nếu áp dụng. | H14: ngày; làm tròn bước cuối | I14: Metric phụ thuộc không khả dụng: CCC null cùng reason; giữ phần tính được.
A15: T1-11 | B15: 01. Số dư và chu kỳ | C15: DPO trên mua hàng (chẩn đoán) | D15: Phải trả cuối kỳ quy đổi theo giá trị mua hàng; vẫn không phải kỳ hạn hợp đồng. | E15: DPO_mua = AP / PUR × N | F15: T1-05, T1-06 | G15: –; firm_id = F01; ngày chốt 30/06/2026. Kỳ phát sinh 01/01–30/06 nếu áp dụng. | H15: ngày; 1 số lẻ | I15: PUR = 0 → null
... A61: T1-95 | B61: 09. Chi tiết và liên kết | C61: Quan hệ đối tác | D61: Đặc điểm quan hệ khác mức độ rủi ro thanh toán. | E61: Mới nếu RelationshipAge ≤60 Thường xuyên nếu InvoiceCount ≥12 VÀ ActiveMonths ≥4 Còn lại Vãng lai | F61: D_sales; hồ sơ đối tác | G61: Quy tắc demo, không phải ngưỡng ngành. Ít lịch sử không đồng nghĩa khách xấu. | H61: Nhãn | I61: Không làm tròn giữa các bước; truy vết nguồn và phiên bản.

Sheet UC2_Cong_thuc
A2: UC02 Dự báo tiền và cảnh báo
A4: Mã | B4: Nhóm công thức | C4: Chỉ tiêu | D4: Ý nghĩa dễ hiểu | E4: Công thức từng bước | F4: Dữ liệu đầu vào | G4: Phạm vi / điều kiện | H4: Đơn vị / hiển thị | I4: Ngoại lệ / kiểm soát
A5: T2-01 | B5: 01. Tiền đầu kỳ và nghĩa vụ | C5: Tiền khả dụng đầu dự báo | D5: Tiền doanh nghiệp có thể chi ngay sau ngày chốt. | E5: Cash0 = cash_AsOf_vnd − restricted_vnd | F5: cash_snapshot.cash_vnd, restricted_vnd | G5: Đúng doanh nghiệp, ngày chốt, tiền tệ. | H5: VND; raw | I5: Thiếu Cash0: chỉ dùng proxy được xác định và gắn nhãn trong chính sách → provisional. Nếu không có proxy hợp lệ → missing_data; không tự điền 0. Tiền bị hạn chế phải tách riêng.
A6: T2-02 | B6: 01. Tiền đầu kỳ và nghĩa vụ | C6: Phải thu dùng lập lịch tiền | D6: Chỉ dự báo phần khách chưa trả. | E6: AR_cash = gross_invoice − receipts_to_AsOf − credits_to_AsOf | F6: sales_invoices; receipt_allocations; credit_notes | G6: Đã ghi nhận đến ngày chốt; chọn phần dư dương. | H6: VND gồm thuế | I6: Demo net/noVAT, trả toàn bộ một lần. Dư âm tách ứng trước. Không tự dùng VAT 10%.
A7: T2-03 | B7: 01. Tiền đầu kỳ và nghĩa vụ | C7: Phải trả dùng lập lịch tiền | D7: Chỉ dự báo phần nghĩa vụ chưa trả. | E7: AP_cash = gross_invoice − payments_to_AsOf − credits_to_AsOf | F7: purchase_invoices; payment_allocations | G7: Đúng phạm vi thương mại và ngày chốt. | H7: VND gồm thuế | I7: Lương, thuế, nợ vay vào plan riêng. Một nghĩa vụ chỉ tính một lần.
A8: T2-04 | B8: 02. Lập lịch và tính số dư | C8: Trễ thu bình quân dương | D8: Ước ngày thu theo lịch sử từng khách. Khoản lớn có trọng số lớn. | E8: CompletedLate = MAX(0; PaidDate − DueDate) OpenLowerBound = MAX(0; AsOf − DueDate) ModelDelay = CompletedLate hoặc OpenLowerBound DelayBase = Σ ModelAmount × ModelDelay / Σ ModelAmount | F8: receipt_allocations; due_date | G8: DueDate trong (AsOf − 180; AsOf]; mẫu mở có cờ censored, mẫu trả xong có cờ completed. Chọn khách khi ≥5 mẫu; nếu không dùng toàn F01 ≥5; cuối cùng mặc định 7 ngày. | H8: Ngày; giữ raw | I8: Theo SRS 2.7.11.1: mẫu mở chỉ là cận dưới. Không gọi trung bình hỗn hợp là ngày thanh toán thực tế. UC01 vẫn dùng riêng mẫu đã thanh toán.
A9: T2-05 | B9: 02. Lập lịch và tính số dư | C9: Ngày thu dự kiến | D9: Ưu tiên lịch xác nhận, sau đó mới ước tính. | E9: Ngày thu = ConfirmedDate nếu lịch được biết tại AsOf Chưa quá hạn: MAX(Start; DueDate + CEILING(DelayScenario; 1)) Đã quá hạn: xem T2-19; không tự gom mọi khoản về Start. | F9: receipt_schedule; T2-04; due_date | G9: Lịch biết tại ngày chốt; portions không vượt dư. | H9: Ngày lịch | I9: Ngày đã qua chuyển về Start chỉ theo policy có nhãn. Thiếu ngày: unscheduled. Không dùng paid_date tương lai.
A10: T2-06 | B10: 02. Lập lịch và tính số dư | C10: Ngày chi dự kiến | D10: Giữ nghĩa vụ đến hạn và nói rõ giả định khoản quá hạn. | E10: Ngày chi = ApprovedDate nếu có Chưa quá hạn: DueDate + lịch sử trễ theo chính sách NCC thiết yếu / Conservative: DueDate Quá hạn: AsOf + OffsetScenario + MOD(Rank; 5) | F10: payment_schedule; purchase_invoices | G10: Lịch đã duyệt, biết tại ngày chốt. | H10: Ngày lịch | I10: Đây là chính sách mô phỏng theo SRS, không phải gia hạn đã được NCC chấp thuận. Lịch được duyệt ưu tiên. Offset: Conservative 1, Base 5, Optimistic 10 ngày.
A11: T2-07 | B11: 02. Lập lịch và tính số dư | C11: Tiền vào ngày hoặc tuần | D11: Cộng khoản thu được xếp vào đúng kỳ. | E11: In = Σ Amount [direction = IN; date ∈ kỳ] | F11: cash_events | G11: Cùng firm, run, case, currency; không trùng nguồn. | H11: VND | I11: Thu hóa đơn và thu khác có căn cứ. Không lấy Rev/N làm tiền thu, không tự coi tồn kho sẽ bán được.
A12: T2-08 | B12: 02. Lập lịch và tính số dư | C12: Tiền ra ngày hoặc tuần | D12: Trả nhà cung cấp và các khoản chi có lịch. | E12: Out = Σ Amount [direction = OUT; date ∈ kỳ] | F12: cash_events; planned_events | G12: Cùng scope và kỳ; một phần nghĩa vụ một lần. | H12: VND | I12: Không cộng COGS như tiền chi. Gốc/lãi vay, lương, thuế, đầu tư cần lịch riêng.
A13: T2-09 | B13: 02. Lập lịch và tính số dư | C13: Số dư tiền | D13: Một phép tính cho ngày và tuần, liên kết kỳ trước sang kỳ sau. | E13: CashEnd = CashStart + In − Out CashStart_next = CashEnd | F13: T2-01; T2-07; T2-08 | G13: Ngày đầu bằng Cash0; tuần cộng cùng event ledger. | H13: VND; giữ số âm | I13: Ví dụ đầu100 triệu, thu100, chi150 → cuối50; vẫn có thể âm giữa tuần. Không ép số âm về0.
A14: T2-10 | B14: 03. Cảnh báo thiếu tiền | C14: Thiếu so mức dự phòng | D14: Chỉ phát sinh nhu cầu điều chỉnh khi dưới L; số tiền cần bổ sung đưa về Z. | E14: GapRestore_d = IF(CashEnd_d < L; Z − CashEnd_d; 0) GapFloor_d = MAX(0; L − CashEnd_d) | F14: buffer_vnd; T2-09 | G14: Dự phòng đã xác nhận; ghi rõ ngày/cuối tuần. | H14: VND | I14: Tiền còn350 triệu, buffer500 → thiếu150; chưa phải tiền âm.
A15: T2-11 | B15: 03. Cảnh báo thiếu tiền | C15: Thiếu để không âm | D15: Khoản bù để số dư dự kiến trở lại0. | E15: GapZero = MAX(0; −CashEnd) | F15: T2-09 | G15: Cùng ngày/tuần đang xét. | H15: VND | I15: Tiền−50 triệu → thiếu50 để không âm. Không cộng với GapBuffer.
... A41: T2-37 | B41: 06. Chất lượng và bàn giao | C41: Trạng thái dữ liệu | D41: Phân biệt giả định đủ dữ liệu với kiểm soát quyền và nguồn. | E41: Giả định doanh nghiệp luôn tải đủ dữ liệu; phân lớp W và tiền luôn tính được. Giữ kiểm soát quyền truy cập, snapshot, thời điểm biết dữ liệu và chống trùng. | F41: Nguồn, validation, manifest | G41: Dữ liệu F01 vẫn ghi provisional vì là dữ liệu tạo sinh, không có trạng thái W chưa xác định. | H41: Enum | I41: Không làm tròn giữa các bước; truy vết nguồn và phiên bản.

Sheet UC3_Cong_thuc
A2: UC03 So khớp phương án tài trợ
A4: Mã | B4: Nhóm công thức | C4: Chỉ tiêu | D4: Ý nghĩa dễ hiểu | E4: Công thức từng bước | F4: Dữ liệu đầu vào | G4: Phạm vi / điều kiện | H4: Đơn vị / hiển thị | I4: Ngoại lệ / kiểm soát
A5: T3-01 | B5: 01. Khoảng thiếu và đợt cần tiền | C5: Mức thiếu theo khối 2 tuần | D5: Cho biết mỗi khối 2 tuần thiếu bao nhiêu so với mức dự trữ muốn giữ. | E5: Deficit_k = IF(MinDaily_k < L; Z−MinDaily_k; 0) k là khối 2 tuần trong 13 tuần. | F5: UC02: Rtarget; MinDaily theo khối (T2-13) | G5: Chỉ khối có ngày dưới L mới tạo nhu cầu; số tiền điều chỉnh đưa về Z. | H5: VND; raw | I5: Không cộng Deficit_k qua các khối. Chưa phải số tiền cần vay.
A6: T3-02 | B6: 01. Khoảng thiếu và đợt cần tiền | C6: Ngưỡng đổi mức và mức trọng yếu | D6: Lọc nhiễu: chỉ coi là đổi mức khi chênh lệch đủ lớn và giữ đủ lâu. | E6: θ = Rtarget × PARAM_THETA_PCT Is_Material_Gap = 1 nếu |ΔDeficit| ≥ θ VÀ mức mới giữ ≥ PARAM_MIN_DAYS ngày; ngược lại 0 | F6: T3-01; PARAM_THETA_PCT (25%); PARAM_MIN_DAYS (14) | G6: So hai khối liền kề; mức không giữ đủ 14 ngày gộp vào mức trước. | H6: VND; ngày | I6: Dao động nhỏ hoặc xen kẽ bị coi là nhiễu, không tạo đợt mới.
A7: T3-03 | B7: 01. Khoảng thiếu và đợt cần tiền | C7: Dạng khoảng thiếu (gap_shape) | D7: Phân loại đường thiếu theo số lần đổi mức: tối đa một lần. | E7: Đếm n = số lần Is_Material_Gap = 1 trong kỳ n = 0 → đồng đều n = 1 và mức tăng → tăng một lần n = 1 và mức giảm → giảm một lần n ≥ 2 → không phân loại được | F7: T3-02 | G7: Chỉ TH01 tạo khoảng cần tài trợ; TH02 là thừa tiền; trong vùng L–H tiếp tục theo dõi. | H7: enum | I7: n ≥ 2: dùng mức thiếu lớn nhất cho cả kỳ và gắn cờ REVIEW_MANUAL. Không mô hình hóa bật tắt xen kẽ.
A8: T3-04 | B8: 01. Khoảng thiếu và đợt cần tiền | C8: Cắt đợt cần tiền (gap_request) | D8: Đổi đường thiếu thành tối đa 2 đợt có ngày và số tiền cần. | E8: Đồng đều/giảm một lần: need_date = ngày đầu CashEnd<L; G_cum là mức điều chỉnh lớn nhất về Z. Tăng một lần: tối đa 2 đợt; G_incr_j=G_cum_j−G_cum_(j−1). | F8: UC02: gap_shape, gap_request; T3-03 | G8: Mỗi đợt có need_date và G_cum; G_incr đợt 1 = G_cum đợt 1. | H8: VND; ngày | I8: Giảm một lần: kỳ hạn chỉ cần phủ đến ngày chuyển mức. Hóa đơn hoặc lô đã dùng ở đợt 1 bị loại khỏi đợt 2.
A9: T3-05 | B9: 01. Khoảng thiếu và đợt cần tiền | C9: Mức nhẹ / nặng của khoảng thiếu | D9: Phân nhẹ hoặc nặng để chọn cách xử lý. | E9: gap_severity = NẶNG nếu PeakGap ≥ θ; NHẸ nếu nhỏ hơn | F9: T3-02; PeakGap của đợt | G9: Tính riêng từng đợt. | H9: enum | I9: Ngưỡng dùng chung với T3-02.
A10: T3-06 | B10: 01. Khoảng thiếu và đợt cần tiền | C10: Số ngày còn lại và chế độ Khẩn | D10: Còn bao nhiêu ngày đến lúc cần tiền; sát hạn thì ưu tiên tiền nhanh nhất. | E10: DaysLeft = need_date − ngày yêu cầu Urgent_Mode = 1 nếu DaysLeft ≤ PARAM_URGENT_DAYS (7) | F10: gap_request; PARAM_URGENT_DAYS | G10: Tính riêng từng đợt; ngày yêu cầu là ngày chạy UC03. | H10: Ngày; 0/1 | I10: DaysLeft ≤ 0: không có nguồn nào kịp ngoài tiền nội bộ; hiển thị “không kịp ngày cần tiền”.
A11: T3-07 | B11: 01. Khoảng thiếu và đợt cần tiền | C11: Thời gian thiếu kéo dài (duration) | D11: Số ngày khoảng thiếu còn tồn tại kể từ ngày cần tiền; dùng để tính chi phí thực. | E11: duration_j tính từ need_date đến ngày cuối CashEnd<L; giảm một lần tính đến ngày chuyển mức. | F11: UC02: daily[] | G11: Từng đợt. | H11: Ngày | I11: duration < PARAM_MIN_TENOR (14): loại sản phẩm khóa kỳ hạn hoặc có phí cố định, ưu tiên tiền nội bộ và giãn lịch.
A12: T3-08 | B12: 02. Yếu tố góp phần và kịch bản | C12: Tỷ lệ tham chiếu của yếu tố góp phần | D12: Dùng để định tuyến kịch bản, không phải phần thiếu do yếu tố gây ra. | E12: Share_k = MIN(100%; số tiền yếu tố k / PeakGap), k ∈ {E_AR, E_INV, E_AP} Vai trò: CHÍNH nếu ≥ PARAM_CAUSE_MAIN (50%); PHỤ nếu ≥ PARAM_CAUSE_SEC (15%); còn lại BỎ QUA | F12: UC01: E_AR, E_INV, E_AP; PeakGap | G12: Số tiền yếu tố là số tham chiếu, không cộng được (SRS 2.7.11.9). | H12: Tỷ lệ; 1 số lẻ% | I12: Với người dùng chỉ nói “yếu tố góp phần” kèm loại liên kết và mức bằng chứng; candidate phải gắn “chưa kiểm chứng”. Không gọi là nguyên nhân chính.
A13: T3-09 | B13: 02. Yếu tố góp phần và kịch bản | C13: Sự kiện trọng yếu | D13: Nhận biết khoản chi hoặc nhập NVL lớn làm mức thiếu tăng vọt. | E13: Major_Event = 1 nếu giá trị khoản đơn lẻ / PeakGap ≥ PARAM_MAJOR_EVENT (30%) | F13: cash_events OUT; PeakGap | G13: Trong ±7 ngày quanh ngày chuyển mức. | H13: 0/1 | I13: Không có sự kiện nào: ghi “đổi mức không gắn được sự kiện”.
A14: T3-10 | B14: 02. Yếu tố góp phần và kịch bản | C14: Chọn kịch bản một đợt A1–A4 | D14: Chọn nhóm nguồn theo yếu tố chính của khoảng thiếu. | E14: Không chuỗi gap (TH01): main = AR → A1; main = INV → A2; main = AP → A4; còn lại (BN0, L3) → A3 | F14: UC01: main_bottleneck, bn_pattern; T3-08 | G14: Chỉ TH01 và chưa thỏa điều kiện chuỗi gap ở T3-11. | H14: enum | I14: Yếu tố PHỤ mở thêm nhóm sản phẩm nhưng không đổi kịch bản.
A15: T3-11 | B15: 02. Yếu tố góp phần và kịch bản | C15: Chuỗi gap B1 / B2 | D15: Thiếu kéo dài mang tính cấu trúc nên cần gói đa nguồn. | E15: Persistent = 1 nếu TH01 và số khối thiếu liên tiếp ≥ min_blocks (2) Persistent = 1: B2 nếu (W2 và n_yếu_tố ≥ 2) HOẶC BestC < G B1 nếu n_yếu_tố > 0, không có yếu tố tồn kho và mọi liên kết L1 Còn lại B2 | F15: UC02: số khối; UC01: W, bn_pattern, loại liên kết; BestC = MAX C của nguồn qua lọc và kịp hạn | G15: n_yếu_tố = c_AR + c_INV + c_AP. | H15: enum | I15: Thay cách chọn B1/B2 ở phiên bản trước; khớp bộ tính tham chiếu.
... A42: T3-38 | B42: 06. Thừa tiền và kiểm soát | C42: Ca quyết định của con người | D42: Đánh dấu bước UC03 không thể tự thực hiện. | E42: requires_human_decision = 1 nếu gói có AP_EXT, AR_EARLY, ghi đè hoặc cờ REVIEW_MANUAL | F42: T3-32; cờ cấp phiên | G42: Cả phiên. | H42: 0/1 | I42: UC03 chỉ đề xuất; UC04 soạn nội dung, người có thẩm quyền duyệt.
A44: Tham số ngưỡng UC03 (giá trị mặc định, tách khỏi công thức)
A46: Mã | B46: Tham số | C46: Giá trị mặc định | D46: Ý nghĩa dễ hiểu | E46: Công thức dùng | F46: Ghi chú
A47: T3-P01 | B47: PARAM_THETA_PCT | C47: 25% (% Rtarget) | D47: Chênh lệch tối thiểu công nhận đổi mức; ranh giới gap nhẹ / nặng | E47: T3-02, T3-05 | F47: Mặc định; đổi theo quy mô doanh nghiệp
A48: T3-P02 | B48: PARAM_MIN_DAYS | C48: 14 (ngày) | D48: Thời gian giữ mức mới (2 khối 2 tuần, khớp min_blocks = 2) | E48: T3-02 | F48: Mặc định
A49: T3-P03 | B49: PARAM_CAUSE_MAIN | C49: 50% (% PeakGap) | D49: Từ ngưỡng này là yếu tố góp phần chính (chỉ để định tuyến) | E49: T3-08 | F49: Mặc định
A50: T3-P04 | B50: PARAM_CAUSE_SEC | C50: 15% (% PeakGap) | D50: Từ ngưỡng này đến dưới 50% là yếu tố phụ | E50: T3-08 | F50: Mặc định
A51: T3-P05 | B51: PARAM_MAJOR_EVENT | C51: 30% (% PeakGap) | D51: Khoản đơn lẻ từ ngưỡng này là sự kiện trọng yếu | E51: T3-09 | F51: Mặc định
A52: T3-P06 | B52: PARAM_MIN_DRAW_PCT | C52: 5% (% PeakGap) | D52: Số rút tối thiểu mỗi nguồn | E52: T3-32 | F52: Mặc định
A53: T3-P07 | B53: PARAM_MAX_SOURCES | C53: 4 (nguồn) | D53: Số nguồn tối đa trong một gói | E53: T3-32 | F53: Mặc định
A54: T3-P08 | B54: PARAM_URGENT_DAYS | C54: 7 (ngày) | D54: DaysLeft nhỏ hơn hoặc bằng ngưỡng là chế độ Khẩn | E54: T3-06, T3-27 | F54: Mặc định
A55: T3-P09 | B55: PARAM_MIN_TENOR | C55: 14 (ngày) | D55: Thời gian thiếu ngắn hơn ngưỡng thì loại sản phẩm khóa kỳ hạn hoặc phí cố định | E55: T3-07 | F55: Mặc định
A56: T3-P10 | B56: PARAM_KEY_PARTNER | C56: 30% (% mua/bán) | D56: Nhà cung cấp từ ngưỡng này bị loại khỏi giãn nợ; khách hàng từ ngưỡng này chuyển cấp quản lý | E56: T3-14, T3-19 | F56: Mặc định

Sheet UC4_Cong_thuc
A2: UC04 Mô phỏng tác động lên dòng tiền
A4: Mã | B4: Nhóm công thức | C4: Chỉ tiêu | D4: Ý nghĩa dễ hiểu | E4: Công thức từng bước | F4: Dữ liệu đầu vào | G4: Phạm vi / điều kiện | H4: Đơn vị / hiển thị | I4: Ngoại lệ / kiểm soát
A5: U4-01 | B5: 01. Phạm vi và dữ liệu | C5: Đường tiền đối chiếu | D5: Lấy kết quả UC02 làm điểm xuất phát, không dựng lại lịch tùy ý. | E5: Base = UC02.daily Events = UC02.cash_events Giữ firm, snapshot, kỳ, Cash0, dự trữ và phiên bản | F5: F01_UC2!A70:M160; A220:Y341; D_F01 | G5: Workbook bắt đầu bằng D_F01!B19=1 (Base). Có thể thử nền UC02 khác, nhãn phải đổi theo. | H5: Ngày; VND | I5: Run UC01/UC02 khác firm/snapshot → chặn. Không ghép run-off và continuing như cùng cơ sở.
A6: U4-02 | B6: 01. Phạm vi và dữ liệu | C6: Đối tượng mô phỏng | D6: Chọn khách, NCC và lô từ kết quả chẩn đoán, rồi nối đến sự kiện tiền. | E6: Candidate = UC01.drivers AffectedEvents = Events có entity_id/source_id được chọn | F6: UC01; D_sales; D_purchases; D_inventory | G6: ID gốc, không nối bằng tên. Bản minh họa chọn 1 khách, 1 NCC, 1 lô; backend nhận danh sách event. | H6: ID / danh sách | I6: Điểm nghẽn UC01 chưa chắc tạo gap. Chỉ mô tả tác động do phép thử; không khẳng định quan hệ nhân quả đã được chứng minh.
A7: U4-03 | B7: 01. Phạm vi và dữ liệu | C7: Kiểm tra giả định | D7: Phân biệt giá trị 0 đã nhập với thiếu đầu vào. | E7: 0 ≤ Share ≤1; Days ≥0 và nguyên 0 ≤ Discount, Fee, Recovery, SaleCost ≤1 ID có thật; ngày hợp lệ; số tiền không vượt dư | F7: F01_UC4!B5:B27 | G7: 0%/0 ngày là lựa chọn không tác động. Rmin≤Rtarget≤Rupper; Rtarget>0. | H7: Hợp lệ / lỗi | I7: Sai tham số → rejected; nguồn mâu thuẫn → invalid_data; thiếu dữ liệu cần thiết → missing_data. Không cắt số sai về mức hợp lệ.
A8: U4-04 | B8: 02. Thu sớm hoặc thu chậm | C8: Phần tiền chuyển lịch | D8: Chỉ chuyển một phần khoản thu; phần còn lại giữ lịch cũ. | E8: Moved_i = Amount_i × ShareAR Remain_i = Amount_i − Moved_i | F8: UC02 event IN, category Thu công nợ; AR_share | G8: Đúng customer_id, hóa đơn mở. Lịch confirmed giữ nguyên trừ khi bật giả định thay cam kết. | H8: VND | I8: Một phần hóa đơn chỉ được phân bổ một lần. Không dùng Rev/ngày × số ngày như tiền sẽ thu.
A9: U4-05 | B9: 02. Thu sớm hoặc thu chậm | C9: Ngày thu mới | D9: Có thể thử cả thu sớm và khách trả chậm. | E9: Thu sớm: NewDate_i = MAX(Start; OldDate_i − EarlyDays) Stress chậm: NewDate_i = OldDate_i + LateDays | F9: Ngày thu UC02; số ngày do người dùng nhập | G9: Chỉ tương lai sau AsOf; stress mới thay thế thao tác thu sớm trên cùng phần tiền. | H9: Ngày lịch | I9: Không dịch lịch sử, không coi khách đã đồng ý. Lịch xác nhận bị thay phải có cờ và lý do.
A10: U4-06 | B10: 02. Thu sớm hoặc thu chậm | C10: Thu ròng và chiết khấu | D10: Thu nhanh hơn có thể phải chấp nhận giảm số tiền. | E10: DiscountCost_i = Moved_i × Discount NewReceipt_i = Moved_i − DiscountCost_i | F10: AR_discount; U4-04 | G10: Chiết khấu chỉ áp phần thực sự được thu sớm; không áp ngày không thay đổi hoặc stress thu chậm. | H10: VND | I10: Workbook ghi khoản chiết khấu bằng giảm thu, không ghi thêm OUT lần hai. Không tự đặt chiết khấu 0 khi chưa biết trong vận hành.
A11: U4-07 | B11: 03. Giãn trả nhà cung cấp | C11: Phần chi chuyển lịch | D11: Giãn chi tạo khoảng đệm thời gian, không xóa nợ. | E11: MovedPay_i = Amount_i × ShareAP RemainPay_i = Amount_i − MovedPay_i NewPayDate_i = OldDate_i + ExtendDays | F11: UC02 OUT / Trả NCC; supplier_id | G11: Chỉ khoản thương mại đã chọn. Lương, thuế, gốc/lãi vay không áp đòn bẩy này. | H11: VND; ngày | I11: NCC thiết yếu chỉ mô phỏng khi có xác nhận giả định được phép thử. Không coi xác nhận mô phỏng là thỏa thuận thật.
A12: U4-08 | B12: 03. Giãn trả nhà cung cấp | C12: Phí giãn trả | D12: Đưa đủ chi phí vào lịch trả mới. | E12: ExtensionFee_i = MovedPay_i × FeeAP NewPayment_i = MovedPay_i + ExtensionFee_i | F12: AP_fee_pct; U4-07 | G12: Phí phần trăm một lần trong bản đầu; biết ngày chi cùng ngày trả mới. | H12: VND | I12: NCC từ chối trong stress → giữ lịch cũ, không phí. Mất chiết khấu chỉ tính khi đã mô hình trong nền, không cộng tùy ý.
A13: U4-09 | B13: 04. Bán một phần tồn kho | C13: Lô được phép thử bán | D13: Không lấy hàng của khách hoặc hàng vướng quyền làm tiền của F01. | E13: EligibleLot = Owner=F01 AND Pledged=không AND UserSaleAssumption=1 ReleasedBook = OwnedValue × SaleShare | F13: D_inventory!A:M; sale_assumption | G13: Kiểm tra lượng bán≤lượng lô. Bản đầu chỉ bán lô chưa có khoản thu bán tương ứng trong nền. | H13: VND giá ghi sổ | I13: Hàng HGC, cầm cố hoặc chưa rõ cầm cố → chặn đòn bẩy lô đó. Muốn thử cần bổ sung bằng chứng, không sửa D_inventory để vượt chặn.
A14: U4-10 | B14: 04. Bán một phần tồn kho | C14: Tiền bán hàng và phí | D14: Giá ghi sổ giảm không đồng nghĩa thu được từng ấy tiền. | E14: SaleGross = ReleasedBook × RecoveryRate SaleCashCost = SaleGross × SaleCostRate SaleNet = SaleGross − SaleCashCost | F14: Tỷ lệ bán; tỷ lệ thu hồi; tỷ lệ chi phí | G14: Demo RecoveryRate từ 0 đến 100% giá ghi sổ; không tự đặt giá thị trường. | H14: VND | I14: Chênh lệch giá ghi sổ và tiền bán là tổn thất giá trị mô phỏng, không là một dòng tiền chi thêm.
A15: U4-11 | B15: 04. Bán một phần tồn kho | C15: Ngày bán và ngày thu | D15: Chỉ phát sinh tiền khi giả định có giao dịch và thời điểm thu rõ. | E15: SaleDate = Start + SaleLag SaleReceiptDate = SaleDate + ReceiptLag Kho giảm tại SaleDate; tiền về tại SaleReceiptDate | F15: F01_UC4 tham số lô; nhật ký giả định | G15: Bản minh họa ReceiptLag=0, thu ngay; backend cho phép trả chậm. | H15: Ngày; VND | I15: Tái sử dụng nguyên liệu hoặc ghi giảm giá trị chưa tạo tiền; chỉ ghi giảm chi mua khi có kế hoạch mua thay thế tương ứng được điều chỉnh.
... A34: U4-30 | B34: 08. Giới hạn chỉ số và đầu ra | C34: Đợt thiếu sau và ma trận | D34: Đánh giá trạng thái tiền mới nhưng không xóa chẩn đoán cũ. | E34: TH_after = quy tắc UC02 trên đường tiền sau Matrix_after = M(3×W_index+TH_index) | F34: W tại AsOf; TH_after; cùng cơ sở nền | G34: Nếu không phải nền Base thì TH/matrix chỉ là tham khảo; W không thay do thao tác tương lai. | H34: W / TH / M | I34: Không đổi W2 thành W0 vì tiền tạm dư. Mức màu tính riêng, không suy từ ô M.

Sheet UC4_Huong_dan
A2: UC04 Phạm vi và hướng dẫn triển khai
A4: Nhóm | B4: Nội dung | C4: Quy tắc áp dụng | D4: Vị trí / ví dụ
A5: Luồng tổng thể | B5: UC01 chọn đối tượng → UC02 cung cấp lịch tiền → UC04 thay giả định trên bản sao → so trước/sau và stress. | C5: Không cần chạy UC03. Không mặc định khách/NCC đã chấp thuận. | D5: F01_UC4: thiết lập A4:C40; kết quả E4:H40; ngày dòng 50; sự kiện dòng 150; tuần dòng 306.
A6: Phạm vi bản đầu | B6: Ba đòn bẩy nội bộ: thu sớm/chậm, giãn trả NCC, bán lô tồn sở hữu. | C6: Không gồm vay, tài trợ hóa đơn, đầu tư tiền dư, gửi thư hoặc phê duyệt hành động. Không đổi SRS trong lần này. | D6: Bản thiết kế công thức chờ duyệt. UC03 vẫn có thể nối thêm sau.
A7: Đối chiếu draft cũ | B7: Giữ bản sao bất biến, dịch sự kiện, kiểm tra gap mới, chi phí và bằng chứng. | C7: Bỏ phụ thuộc TV3_Nguong/TV3_Dot_thieu/D_catalogue; bỏ bộ F02/F03, bảng bản nháp và submit_action. | D7: Draft cũ có 30 sheet, gồm cả UC03 và dữ liệu cũ. Bản mới chỉ bổ sung 3 sheet.
A8: Sửa điểm nghiệp vụ | B8: Không dùng doanh thu bình quân×ngày để thay AR/AP tại ngày chốt; không mặc định tài trợ được loại AR; không coi toàn bộ thiếu biến mất khi hết một đợt. | C8: Giữ CCC lịch sử; tập trung tiền theo ngày, ngày xấu đi và nghĩa vụ ngoài kỳ. | D8: U4-14, U4-17, U4-26. Không suy tiết kiệm lãi khi chưa có lịch dư nợ thực.
A9: Dùng chung dữ liệu | B9: F01, ngày chốt 30/06/2026; chẩn đoán 01/01–30/06; forecast 01/07–29/09. | C9: Không chép lại D_* từ TV4 draft. UC04 nối trực tiếp sự kiện UC02 và lô từ D_inventory. | D9: D_F01, D_sales, D_purchases, D_inventory, D_flows giữ nguyên.
A10: Mã công thức | B10: UC04 dùng mã U4-01…U4-30 để phân biệt bản draft T4 cũ. | C10: Bảng 9 cột giống UC1/UC2_Cong_thuc; mỗi phép có đầu vào, điều kiện và ngoại lệ. | D10: Không gộp công thức và yêu cầu quyền thành một phép toán.
A11: Kịch bản đang chọn | B11: 0 Giữ nguyên; 1 Thực hiện giả định; 2 Chỉ thu sớm được 50%; 3 NCC từ chối; 4 Bán tồn chậm; 5 Ba bất lợi kết hợp; 6 Khách trả chậm. | C11: Một selector ở F01_UC4!B5; tất cả dùng cùng một ledger và một đường tiền. | D11: B6 đọc nhãn; B28:B34 là giả định hiệu lực tính từ selector và thông số.
A12: Nhóm khách hàng | B12: Gợi ý chọn từ UC01 theo vốn đang giữ, trễ bao lâu, quan hệ và mức tập trung; người dùng chọn ID. | C12: Không tự siết khách mới/vãng lai hoặc nới khách lớn. Nhãn quan hệ là ngữ cảnh, không phải sự chấp thuận. | D12: B7 customer_id. Có thể lọc từng event_id ở backend; workbook áp theo khách và tỷ lệ chung.
A13: Nhóm nhà cung cấp | B13: Chỉ dịch khoản Trả NCC thuộc supplier_id; giữ lương, thuế và nghĩa vụ tài chính. | C13: NCC thiết yếu cần bật xác nhận giả định mô phỏng. Không dùng công cụ what-if để sửa hợp đồng. | D13: B13 supplier_id; B17 chỉ xác nhận được phép thử, không xác nhận đối tác đã đồng ý.
A14: Nhóm hàng tồn kho | B14: Bán lô phải thuộc F01, không cầm cố và có giả định thị trường. | C14: Mặc định L27 không cầm cố; lô phụ liệu đơn hủy L06 chưa rõ cầm cố nên không chọn sẵn để tạo tiền. | D14: B18 lot_id; B24 xác nhận giả định; nếu đổi sang L06 mà chưa có dữ liệu thì trạng thái chặn.
A15: Điều kiện lịch xác nhận | B15: Mặc định không đổi lịch thu được xác nhận ở UC02. | C15: B12=1 cho phép thử thay lịch xác nhận; phải nói rõ giả định này trong kết quả. | D15: Không lấy paid_date tương lai làm chứng cứ có tại ngày chốt.
... A63: U4-T14 | B63: Sai firm/snapshot, thiếu quyền, lời giải thích không có fact hoặc ghi audit lỗi. | C63: Chặn đúng điểm; không thực thi hoặc phát hành ngoài quyền; Decimal và kiểm chứng cùng run. | D63: Ca nghiệm thu backend; không tuyên bố đã có ứng dụng.

Sheet Nguong
A2: Ngưỡng SMEs, biến điều tiết và quy tắc áp dụng
A4: Khóa cấu hình | B4: Giá trị nguồn | C4: Đơn vị | D4: Áp dụng | E4: Nguồn | F4: Giới hạn
A5: cash.mo.lower_ratio | B5: 0.041798621 | C5: tỷ lệ DT năm | D5: L ngành (P25 Tiền/DT) | E5: B6_MillerOrr!C17 | F5: 20 DN FOB, 60 năm–DN, 2023–2025
A6: cash.mo.lower_min_owner | B6: 0 | C6: VND | D6: Sàn do chủ DN đặt | E6: ThamSo!P25 | F6: Giá trị mặc định nguồn
A7: cash.mo.sigma_annual_ratio | B7: 0.047874988 | C7: tỷ lệ | D7: σ năm ngành / DT | E7: B6_MillerOrr!C18 | F7: 40 biến động năm 2024–2025
A8: cash.mo.sigma_daily_ratio | B8: =B7/SQRT(B12) -> 0.0025058914 | C8: tỷ lệ | D8: σ ngày ngành / DT | E8: B6_MillerOrr!C20 | F8: Dự phòng ngành; không dùng nếu đủ lịch sử DN
A9: cash.mo.min_daily_obs | B9: 90 | C9: ngày | D9: Số quan sát ngày tối thiểu | E9: ThamSo!P26 | F9: Dùng lịch sử trong tối đa 3 năm
A10: cash.mo.transaction_cost | B10: 1000000 | C10: VND/lần | D10: F: chi phí chuyển đổi | E10: ThamSo!P22 | F10: demo_assumption
A11: cash.mo.rate_annual | B11: 0.0475 | C11: tỷ lệ/năm | D11: r năm: chi phí cơ hội | E11: ThamSo!P23 | F11: demo_assumption; không là lãi suất vay
A12: cash.mo.days_per_year | B12: 365 | C12: ngày | D12: Quy đổi về ngày | E12: ThamSo!P24
A13: cash.mo.annual_change_obs | B13: 40 | C13: quan sát | D13: Số quan sát biến động ngành | E13: B6_MillerOrr!C19
A14: wc.dso.reference.fob | B14: 43.247052 | C14: ngày | D14: Phải thu – tham chiếu (P50) | E14: verified_reference: FiinTrade 2023–2025, 20 DN may FOB
A15: wc.dso.watch.fob | B15: 58.207139 | C15: ngày | D15: Phải thu – R-AR-1 → Có nguy cơ | E15: verified_reference: FiinTrade 2023–2025, 20 DN may FOB
A16: wc.dso.severe.fob | B16: 66.263266 | C16: ngày | D16: Phải thu – R-AR-2 → Thiếu trầm trọng | E16: verified_reference: FiinTrade 2023–2025, 20 DN may FOB
A17: wc.dio.reference.fob | B17: 69.751755 | C17: ngày | D17: Tồn kho – tham chiếu (P50) | E17: verified_reference: FiinTrade 2023–2025, 20 DN may FOB
A18: wc.dio.watch.fob | B18: 86.118055 | C18: ngày | D18: Tồn kho – R-INV-1 → Có nguy cơ | E18: verified_reference: FiinTrade 2023–2025, 20 DN may FOB
A19: wc.dio.severe.fob | B19: 137.96515 | C19: ngày | D19: Tồn kho – R-INV-2 → Thiếu trầm trọng | E19: verified_reference: FiinTrade 2023–2025, 20 DN may FOB
A20: wc.dpo.high_info.fob | B20: 68.309204 | C20: ngày | D20: Phải trả – R-AP-INFO | E20: verified_reference: FiinTrade 2023–2025, 20 DN may FOB
A21: wc.dpo.low.fob | B21: 14.892653 | C21: ngày | D21: Phải trả – R-AP-1 | E21: verified_reference: FiinTrade 2023–2025, 20 DN may FOB
A22: liq.cash_buffer.thin.fob | B22: 0.083007995 | C22: % doanh thu | D22: Phải trả – R-AP-1 (điều kiện kèm) | E22: verified_reference: FiinTrade 2023–2025, 20 DN may FOB
A23: wc.materiality_share | B23: 0.05 | C23: tỷ lệ TSNH | D23: R-MAT → W2 | E23: owner_policy (mặc định demo) | F23: Chủ DN duyệt; độ nhạy ở B5
A24: wc.severe_forces_w2 | B24: 1 | C24: cờ | D24: R-AR-2 / R-INV-2 → W2 | E24: owner_policy
A25: scope.reference_start | B25: 2023 | C25: năm | D25: Đầu cửa sổ chuẩn ngành | E25: ThamSo!P19 | F25: Chỉ FOB
A26: scope.reference_end | B26: 2025 | C26: năm | D26: Cuối cửa sổ chuẩn ngành | E26: ThamSo!P20 | F26: 20 DN, 60 năm–DN
A27: wc.factor.size | B27: 1 | C27: hệ số | D27: Mọi ngưỡng | E27: verified_reference | F27: Không khác biệt có ý nghĩa → 1
A28: wc.factor.season | B28: 1 | C28: hệ số | D28: Ngưỡng DSO, DIO | E28: demo_assumption | F28: Chưa hiệu chỉnh
A29: ar.invoice.overdue_watch_rho | B29: 0.5 | C29: lần | D29: Cấp hóa đơn: ngày quá hạn / kỳ hạn | E29: demo_assumption | F29: Không hiệu chỉnh được từ BCTC
A30: ar.invoice.overdue_severe_rho | B30: 1 | C30: lần | D30: Cấp hóa đơn | E30: demo_assumption
A31: inv.lot.slow_days.nvl_hh | B31: 60 | C31: ngày | D31: Cấp lô: NVL, hàng hóa | E31: demo_assumption
A32: inv.lot.slow_days.btp_tp | B32: 30 | C32: ngày | D32: Cấp lô: BTP, thành phẩm | E32: demo_assumption
A34: Nguồn chuẩn: Nguong_SMEs_FOB_2023_2025 (1).xlsx; Nguong_SRS config_version fob.threshold.v3. Số liệu nguồn được giữ đủ độ chính xác; F01 là dữ liệu tạo sinh riêng.
A38: Chỉ tiêu | B38: P10 ngành | C38: P25 ngành | D38: P50 ngành | E38: P75 ngành | F38: P90 ngành | G38: Trung vị nhỏ–vừa FOB | H38: Trung vị FOB | I38: p-value | J38: Hệ số quy mô
A39: DSO | B39: 25.769231 | C39: 34.408949 | D39: 43.247052 | E39: 58.207139 | F39: 66.263266 | G39: 36.135937 | H39: 43.247052 | I39: 0.17146021 | J39: =IF(I39<0.05,MIN(3,MAX(0.1,G39/H39)),1) -> 1
A40: DIO | B40: 33.857892 | C40: 57.276635 | D40: 69.751755 | E40: 86.118055 | F40: 137.96515 | G40: 75.804937 | H40: 69.751755 | I40: 0.28749542 | J40: =IF(I40<0.05,MIN(3,MAX(0.1,G40/H40)),1) -> 1
A41: DPO | B41: 14.892653 | C41: 19.375703 | D41: 34.262287 | E41: 68.309204 | F41: 88.215245 | G41: 29.967555 | H41: 34.262287 | I41: 0.59485342 | J41: =IF(I41<0.05,MIN(3,MAX(0.1,G41/H41)),1) -> 1
A42: Cash | B42: 0.044512172 | C42: 0.083007995 | D42: 0.11883177 | E42: 0.18340151 | F42: 0.29840026 | G42: 0.11797957 | H42: 0.11883177 | I42: 0.4474117 | J42: =IF(I42<0.05,MIN(3,MAX(0.1,G42/H42)),1) -> 1
A45: Ngưỡng FOB tính lại | B45: Giá trị | C45: Cách đọc
A46: DSO theo dõi | B46: =E39*J39*B28 -> 58.207139 | C46: P75 DSO FOB × hệ số quy mô × mùa vụ
A47: DSO nghiêm trọng | B47: =F39*J39*B28 -> 66.263266 | C47: P90 DSO FOB × hệ số quy mô × mùa vụ
A48: DIO theo dõi | B48: =E40*J40*B28 -> 86.118055 | C48: P75 DIO FOB × hệ số quy mô × mùa vụ
...

Sheet F01_UC1
A2: F01 Chẩn đoán tại 30/06/2026
A4: Chỉ tiêu | B4: Giá trị | C4: Cách tính / giới hạn | D4: Đơn vị
A5: Doanh thu | B5: =D_F01!B9 -> 69627509083 | C5: Rev = financials.revenue_vnd | D5: VND
A6: Giá vốn | B6: =D_F01!B10 -> 5.7094557e+10 | C6: COGS = financials.cogs_vnd | D6: VND
A7: Số ngày kỳ | B7: =D_F01!B8 -> 181 | C7: Ngày cuối − ngày đầu +1 | D7: Ngày
A8: Phải thu | B8: =SUM(D_sales!N5:N121) -> 24915591245 | C8: AR = tổng dư hóa đơn bán mở | D8: VND
A9: Tồn sở hữu | B9: =SUM(D_inventory!P5:P40) -> 2.5064351e+10 | C9: INV = tổng giá trị lô thuộc F01 | D9: VND
A10: Phải trả | B10: =SUM(D_purchases!O5:O139) -> 8393038071 | C10: AP = tổng dư hóa đơn mua mở | D10: VND
A11: Tổng mua kỳ | B11: =SUM(D_purchases!G5:G139) -> 42021300381 | C11: PUR; không bằng giá vốn do có lao động và chi phí sản xuất | D11: VND
A12: DSO | B12: =B8/B5*B7 -> 64.769257 | C12: AR / Rev × N | D12: Ngày
A13: DIO | B13: =B9/B6*B7 -> 79.458494 | C13: INV / COGS × N | D13: Ngày
A14: DPO | B14: =B10/B6*B7 -> 26.607438 | C14: AP / COGS × N | D14: Ngày
A15: CCC | B15: =B12+B13-B14 -> 117.62031 | C15: DSO + DIO − DPO | D15: Ngày
A16: Vốn thương mại ròng | B16: =B8+B9-B10 -> 4.1586904e+10 | C16: AR + INV − AP; không phải tiền mặt | D16: VND
A17: Phải thu quá hạn | B17: =SUMIFS(D_sales!N5:N121,D_sales!O5:O121,">0") -> 9778180962 | C17: Chỉ phần đã đến hạn chưa trả | D17: VND
A18: Phải trả quá hạn | B18: =SUMIFS(D_purchases!O5:O139,D_purchases!P5:P139,">0") -> 979364994 | C18: Không tự suy NCC ngừng cung ứng | D18: VND
A19: Tồn lâu hoặc đơn hủy | B19: =SUMPRODUCT(D_inventory!P5:P40,D_inventory!S5:S40) -> 5.4412576e+09 | C19: Hợp của hai cờ; không cộng trùng | D19: VND
A20: Tồn thuộc khách hàng | B20: =SUM(D_inventory!O5:O40)-B9 -> 0 | C20: Loại khỏi INV, TWC và TSNH | D20: VND
A21: Tài sản ngắn hạn | B21: =D_F01!B11+D_F01!B13+D_F01!B14+B8+B9 -> 5.9381868e+10 | C21: Tiền + ĐTNH + tài sản khác + AR + INV | D21: VND
A22: Mức AR | B22: =IF(B12>Nguong!B47,2,IF(B12>Nguong!B46,1,0)) -> 1 | C22: So ngưỡng FOB 2023–2025, chưa làm tròn | D22: 0/1/2
A23: Mức INV | B23: =IF(B13>Nguong!B49,2,IF(B13>Nguong!B48,1,0)) -> 0 | C23: So ngưỡng FOB 2023–2025 | D23: 0/1/2
A24: Doanh thu năm tham chiếu | B24: =D_F01!B21 -> 133127509083 | C24: Doanh thu TTM tạo sinh đã đủ; không quy đổi kỳ ngắn | D24: VND
A25: Tỷ lệ tiền trên TTM | B25: =(D_F01!B11+D_F01!B13)/B24 -> 0.048088678 | C25: (Tiền + ĐTNH) / doanh thu TTM | D25: Tỷ lệ
A26: Tín hiệu AP | B26: =IF(AND(B14<Nguong!B50,B25<Nguong!B52),1,0) -> 0 | C26: DPO thấp đồng thời tiền mỏng | D26: 0/1
A27: Vốn AR vượt ngưỡng | B27: =MAX(0,B12-Nguong!B46)*B5/B7 -> 2.5243312e+09 | C27: MAX(DSO − DSOWatch;0) × Rev/N | D27: VND
A28: Vốn tồn vượt ngưỡng | B28: =MAX(0,B13-Nguong!B48)*B6/B7 -> 0 | C28: MAX(DIO − DIOWatch;0) × COGS/N | D28: VND
A29: Tỷ lệ trọng yếu | B29: =MAX(B27,B28)/B21 -> 0.042510134 | C29: MAX(vốn AR vượt; vốn tồn vượt) / TSNH | D29: Tỷ lệ
A30: Phân lớp W | B30: =IF(OR(AND(Nguong!B24=1,MAX(B22,B23)=2),AND(MAX(B22,B23)>=1,B29>=Nguong!B23)),"W2",IF(OR(MAX(B22,B23)>=1,B26=1),"W1","W0")) -> W1 | C30: W0 An toàn / W1 Có nguy cơ / W2 Thiếu trầm trọng; giả định đủ dữ liệu | D30: Enum
A31: Vốn vượt tổng | B31: =B27+B28 -> 2.5243312e+09 | C31: Không cộng vào dòng thu hay mức thiếu UC02 | D31: VND
A32: Lô sở hữu lưu lâu nhất | B32: =_xlfn.MAXIFS(D_inventory!N5:N40,D_inventory!E5:E40,"F01") -> 238 | C32: Lưu kho có thể trước đầu kỳ | D32: Ngày
A33: Mô hình / trạng thái | B33: FOB / provisional | C33: Số dư cuối kỳ 181 ngày khác bình quân năm của ngành | D33: Nhãn
A40: Khách | B40: Tên | C40: Phải thu | D40: Tỷ trọng AR | E40: Góp DSO | F40: Quá hạn tổng | G40: 1–30 ngày | H40: 31–60 ngày | I40: >60 ngày | J40: MaxDPD | K40: Trễ có dấu 180d | L40: Trễ dương 180d | M40: Số hóa đơn đã thu | N40: Kỳ hạn hợp đồng | O40: Quan hệ demo
A41: BYR-F01-002 | B41: =D_F01!B38 -> Khách mua FOB Lớn K1 | C41: =SUMIFS(D_sales!$N$5:$N$121,D_sales!$C$5:$C$121,A41) -> 13893078293 | D41: =IF($B$8>0,C41/$B$8,0) -> 0.5576058 | E41: =C41/$B$5*$B$7 -> 36.115714 | F41: =SUMIFS(D_sales!$N$5:$N$121,D_sales!$C$5:$C$121,A41,D_sales!$O$5:$O$121,">0") -> 4187759307 | G41: =SUMIFS(D_sales!$N$5:$N$121,D_sales!$C$5:$C$121,A41,D_sales!$O$5:$O$121,">0",D_sales!$O$5:$O$121,"<=30") -> 4187759307 | H41: =SUMIFS(D_sales!$N$5:$N$121,D_sales!$C$5:$C$121,A41,D_sales!$O$5:$O$121,">30",D_sales!$O$5:$O$121,"<=60") -> 0 | I41: =SUMIFS(D_sales!$N$5:$N$121,D_sales!$C$5:$C$121,A41,D_sales!$O$5:$O$121,">60",D_sales!$O$5:$O$121,"<=9999") -> 0 | J41: =_xlfn.MAXIFS(D_sales!$O$5:$O$121,D_sales!$C$5:$C$121,A41) -> 21 | K41: =IF(SUMIFS(D_sales!$T$5:$T$121,D_sales!$C$5:$C$121,A41)=0,"n.a.",SUMIFS(D_sales!$Z$5:$Z$121,D_sales!$C$5:$C$121,A41)/SUMIFS(D_sales!$T$5:$T$121,D_sales!$C$5:$C$121,A41)) -> 19.157777 | L41: =IF(SUMIFS(D_sales!$T$5:$T$121,D_sales!$C$5:$C$121,A41)=0,"n.a.",SUMIFS(D_sales!$S$5:$S$121,D_sales!$C$5:$C$121,A41)/SUMIFS(D_sales!$T$5:$T$121,D_sales!$C$5:$C$121,A41)) -> 19.157777 | M41: =COUNTIFS(D_sales!$C$5:$C$121,A41,D_sales!$R$5:$R$121,1) -> 16 | N41: =IF(SUMIFS(D_sales!$T$5:$T$121,D_sales!$C$5:$C$121,A41)=0,"n.a.",SUMIFS(D_sales!$AA$5:$AA$121,D_sales!$C$5:$C$121,A41)/SUMIFS(D_sales!$T$5:$T$121,D_sales!$C$5:$C$121,A41)) -> 45 | O41: =IF(D_F01!$B$7-_xlfn.MINIFS(D_sales!$G$5:$G$121,D_sales!$C$5:$C$121,A41)+1<=60,"Mới",IF(AND(COUNTIF(D_sales!$C$5:$C$121,A41)>=12,6>=4),"Thường xuyên","Vãng lai")) -> Thường xuyên
A42: BYR-F01-001 | B42: =D_F01!B39 -> Khách mua FOB K2 | C42: =SUMIFS(D_sales!$N$5:$N$121,D_sales!$C$5:$C$121,A42) -> 4870640111 | D42: =IF($B$8>0,C42/$B$8,0) -> 0.19548563 | E42: =C42/$B$5*$B$7 -> 12.661459 | F42: =SUMIFS(D_sales!$N$5:$N$121,D_sales!$C$5:$C$121,A42,D_sales!$O$5:$O$121,">0") -> 1998889941 | G42: =SUMIFS(D_sales!$N$5:$N$121,D_sales!$C$5:$C$121,A42,D_sales!$O$5:$O$121,">0",D_sales!$O$5:$O$121,"<=30") -> 1998889941 | H42: =SUMIFS(D_sales!$N$5:$N$121,D_sales!$C$5:$C$121,A42,D_sales!$O$5:$O$121,">30",D_sales!$O$5:$O$121,"<=60") -> 0 | I42: =SUMIFS(D_sales!$N$5:$N$121,D_sales!$C$5:$C$121,A42,D_sales!$O$5:$O$121,">60",D_sales!$O$5:$O$121,"<=9999") -> 0 | J42: =_xlfn.MAXIFS(D_sales!$O$5:$O$121,D_sales!$C$5:$C$121,A42) -> 7 | K42: =IF(SUMIFS(D_sales!$T$5:$T$121,D_sales!$C$5:$C$121,A42)=0,"n.a.",SUMIFS(D_sales!$Z$5:$Z$121,D_sales!$C$5:$C$121,A42)/SUMIFS(D_sales!$T$5:$T$121,D_sales!$C$5:$C$121,A42)) -> -1.1383316 | L42: =IF(SUMIFS(D_sales!$T$5:$T$121,D_sales!$C$5:$C$121,A42)=0,"n.a.",SUMIFS(D_sales!$S$5:$S$121,D_sales!$C$5:$C$121,A42)/SUMIFS(D_sales!$T$5:$T$121,D_sales!$C$5:$C$121,A42)) -> 1.1151265 | M42: =COUNTIFS(D_sales!$C$5:$C$121,A42,D_sales!$R$5:$R$121,1) -> 24 | N42: =IF(SUMIFS(D_sales!$T$5:$T$121,D_sales!$C$5:$C$121,A42)=0,"n.a.",SUMIFS(D_sales!$AA$5:$AA$121,D_sales!$C$5:$C$121,A42)/SUMIFS(D_sales!$T$5:$T$121,D_sales!$C$5:$C$121,A42)) -> 30 | O42: =IF(D_F01!$B$7-_xlfn.MINIFS(D_sales!$G$5:$G$121,D_sales!$C$5:$C$121,A42)+1<=60,"Mới",IF(AND(COUNTIF(D_sales!$C$5:$C$121,A42)>=12,6>=4),"Thường xuyên","Vãng lai")) -> Thường xuyên
A43: BYR-F01-005 | B43: =D_F01!B40 -> Nhà mua hàng FOB K5 | C43: =SUMIFS(D_sales!$N$5:$N$121,D_sales!$C$5:$C$121,A43) -> 2247943156 | D43: =IF($B$8>0,C43/$B$8,0) -> 0.090222348 | E43: =C43/$B$5*$B$7 -> 5.8436345 | F43: =SUMIFS(D_sales!$N$5:$N$121,D_sales!$C$5:$C$121,A43,D_sales!$O$5:$O$121,">0") -> 1323908589 | G43: =SUMIFS(D_sales!$N$5:$N$121,D_sales!$C$5:$C$121,A43,D_sales!$O$5:$O$121,">0",D_sales!$O$5:$O$121,"<=30") -> 0 | H43: =SUMIFS(D_sales!$N$5:$N$121,D_sales!$C$5:$C$121,A43,D_sales!$O$5:$O$121,">30",D_sales!$O$5:$O$121,"<=60") -> 0 | I43: =SUMIFS(D_sales!$N$5:$N$121,D_sales!$C$5:$C$121,A43,D_sales!$O$5:$O$121,">60",D_sales!$O$5:$O$121,"<=9999") -> 1323908589 | J43: =_xlfn.MAXIFS(D_sales!$O$5:$O$121,D_sales!$C$5:$C$121,A43) -> 77 | K43: =IF(SUMIFS(D_sales!$T$5:$T$121,D_sales!$C$5:$C$121,A43)=0,"n.a.",SUMIFS(D_sales!$Z$5:$Z$121,D_sales!$C$5:$C$121,A43)/SUMIFS(D_sales!$T$5:$T$121,D_sales!$C$5:$C$121,A43)) -> 5.3203879 | L43: =IF(SUMIFS(D_sales!$T$5:$T$121,D_sales!$C$5:$C$121,A43)=0,"n.a.",SUMIFS(D_sales!$S$5:$S$121,D_sales!$C$5:$C$121,A43)/SUMIFS(D_sales!$T$5:$T$121,D_sales!$C$5:$C$121,A43)) -> 5.3203879 | M43: =COUNTIFS(D_sales!$C$5:$C$121,A43,D_sales!$R$5:$R$121,1) -> 15 | N43: =IF(SUMIFS(D_sales!$T$5:$T$121,D_sales!$C$5:$C$121,A43)=0,"n.a.",SUMIFS(D_sales!$AA$5:$AA$121,D_sales!$C$5:$C$121,A43)/SUMIFS(D_sales!$T$5:$T$121,D_sales!$C$5:$C$121,A43)) -> 30 | O43: =IF(D_F01!$B$7-_xlfn.MINIFS(D_sales!$G$5:$G$121,D_sales!$C$5:$C$121,A43)+1<=60,"Mới",IF(AND(COUNTIF(D_sales!$C$5:$C$121,A43)>=12,6>=4),"Thường xuyên","Vãng lai")) -> Thường xuyên
A44: BYR-F01-006 | B44: =D_F01!B41 -> Thương hiệu thời trang theo mùa K6 | C44: =SUMIFS(D_sales!$N$5:$N$121,D_sales!$C$5:$C$121,A44) -> 2599202710 | D44: =IF($B$8>0,C44/$B$8,0) -> 0.10432033 | E44: =C44/$B$5*$B$7 -> 6.7567503 | F44: =SUMIFS(D_sales!$N$5:$N$121,D_sales!$C$5:$C$121,A44,D_sales!$O$5:$O$121,">0") -> 1909998793 | G44: =SUMIFS(D_sales!$N$5:$N$121,D_sales!$C$5:$C$121,A44,D_sales!$O$5:$O$121,">0",D_sales!$O$5:$O$121,"<=30") -> 1909998793 | H44: =SUMIFS(D_sales!$N$5:$N$121,D_sales!$C$5:$C$121,A44,D_sales!$O$5:$O$121,">30",D_sales!$O$5:$O$121,"<=60") -> 0 | I44: =SUMIFS(D_sales!$N$5:$N$121,D_sales!$C$5:$C$121,A44,D_sales!$O$5:$O$121,">60",D_sales!$O$5:$O$121,"<=9999") -> 0 | J44: =_xlfn.MAXIFS(D_sales!$O$5:$O$121,D_sales!$C$5:$C$121,A44) -> 3 | K44: =IF(SUMIFS(D_sales!$T$5:$T$121,D_sales!$C$5:$C$121,A44)=0,"n.a.",SUMIFS(D_sales!$Z$5:$Z$121,D_sales!$C$5:$C$121,A44)/SUMIFS(D_sales!$T$5:$T$121,D_sales!$C$5:$C$121,A44)) -> 0.59609935 | L44: =IF(SUMIFS(D_sales!$T$5:$T$121,D_sales!$C$5:$C$121,A44)=0,"n.a.",SUMIFS(D_sales!$S$5:$S$121,D_sales!$C$5:$C$121,A44)/SUMIFS(D_sales!$T$5:$T$121,D_sales!$C$5:$C$121,A44)) -> 1.510146 | M44: =COUNTIFS(D_sales!$C$5:$C$121,A44,D_sales!$R$5:$R$121,1) -> 8 | N44: =IF(SUMIFS(D_sales!$T$5:$T$121,D_sales!$C$5:$C$121,A44)=0,"n.a.",SUMIFS(D_sales!$AA$5:$AA$121,D_sales!$C$5:$C$121,A44)/SUMIFS(D_sales!$T$5:$T$121,D_sales!$C$5:$C$121,A44)) -> 36.389243 | O44: =IF(D_F01!$B$7-_xlfn.MINIFS(D_sales!$G$5:$G$121,D_sales!$C$5:$C$121,A44)+1<=60,"Mới",IF(AND(COUNTIF(D_sales!$C$5:$C$121,A44)>=12,5>=4),"Thường xuyên","Vãng lai")) -> Vãng lai
A45: BYR-F01-003 | B45: =D_F01!B42 -> Thương hiệu nội địa K3 | C45: =SUMIFS(D_sales!$N$5:$N$121,D_sales!$C$5:$C$121,A45) -> 617202404 | D45: =IF($B$8>0,C45/$B$8,0) -> 0.024771734 | E45: =C45/$B$5*$B$7 -> 1.6044468 | F45: =SUMIFS(D_sales!$N$5:$N$121,D_sales!$C$5:$C$121,A45,D_sales!$O$5:$O$121,">0") -> 0 | G45: =SUMIFS(D_sales!$N$5:$N$121,D_sales!$C$5:$C$121,A45,D_sales!$O$5:$O$121,">0",D_sales!$O$5:$O$121,"<=30") -> 0 | H45: =SUMIFS(D_sales!$N$5:$N$121,D_sales!$C$5:$C$121,A45,D_sales!$O$5:$O$121,">30",D_sales!$O$5:$O$121,"<=60") -> 0 | I45: =SUMIFS(D_sales!$N$5:$N$121,D_sales!$C$5:$C$121,A45,D_sales!$O$5:$O$121,">60",D_sales!$O$5:$O$121,"<=9999") -> 0 | J45: =_xlfn.MAXIFS(D_sales!$O$5:$O$121,D_sales!$C$5:$C$121,A45) -> 0 | K45: =IF(SUMIFS(D_sales!$T$5:$T$121,D_sales!$C$5:$C$121,A45)=0,"n.a.",SUMIFS(D_sales!$Z$5:$Z$121,D_sales!$C$5:$C$121,A45)/SUMIFS(D_sales!$T$5:$T$121,D_sales!$C$5:$C$121,A45)) -> 1.8759103 | L45: =IF(SUMIFS(D_sales!$T$5:$T$121,D_sales!$C$5:$C$121,A45)=0,"n.a.",SUMIFS(D_sales!$S$5:$S$121,D_sales!$C$5:$C$121,A45)/SUMIFS(D_sales!$T$5:$T$121,D_sales!$C$5:$C$121,A45)) -> 2.0202039 | M45: =COUNTIFS(D_sales!$C$5:$C$121,A45,D_sales!$R$5:$R$121,1) -> 13 | N45: =IF(SUMIFS(D_sales!$T$5:$T$121,D_sales!$C$5:$C$121,A45)=0,"n.a.",SUMIFS(D_sales!$AA$5:$AA$121,D_sales!$C$5:$C$121,A45)/SUMIFS(D_sales!$T$5:$T$121,D_sales!$C$5:$C$121,A45)) -> 30 | O45: =IF(D_F01!$B$7-_xlfn.MINIFS(D_sales!$G$5:$G$121,D_sales!$C$5:$C$121,A45)+1<=60,"Mới",IF(AND(COUNTIF(D_sales!$C$5:$C$121,A45)>=12,5>=4),"Thường xuyên","Vãng lai")) -> Thường xuyên
A46: BYR-F01-007 | B46: =D_F01!B43 -> Đại lý vãng lai K7 | C46: =SUMIFS(D_sales!$N$5:$N$121,D_sales!$C$5:$C$121,A46) -> 0 | D46: =IF($B$8>0,C46/$B$8,0) -> 0 | E46: =C46/$B$5*$B$7 -> 0 | F46: =SUMIFS(D_sales!$N$5:$N$121,D_sales!$C$5:$C$121,A46,D_sales!$O$5:$O$121,">0") -> 0 | G46: =SUMIFS(D_sales!$N$5:$N$121,D_sales!$C$5:$C$121,A46,D_sales!$O$5:$O$121,">0",D_sales!$O$5:$O$121,"<=30") -> 0 | H46: =SUMIFS(D_sales!$N$5:$N$121,D_sales!$C$5:$C$121,A46,D_sales!$O$5:$O$121,">30",D_sales!$O$5:$O$121,"<=60") -> 0 | I46: =SUMIFS(D_sales!$N$5:$N$121,D_sales!$C$5:$C$121,A46,D_sales!$O$5:$O$121,">60",D_sales!$O$5:$O$121,"<=9999") -> 0 | J46: =_xlfn.MAXIFS(D_sales!$O$5:$O$121,D_sales!$C$5:$C$121,A46) -> 0 | K46: =IF(SUMIFS(D_sales!$T$5:$T$121,D_sales!$C$5:$C$121,A46)=0,"n.a.",SUMIFS(D_sales!$Z$5:$Z$121,D_sales!$C$5:$C$121,A46)/SUMIFS(D_sales!$T$5:$T$121,D_sales!$C$5:$C$121,A46)) -> 1.19485 | L46: =IF(SUMIFS(D_sales!$T$5:$T$121,D_sales!$C$5:$C$121,A46)=0,"n.a.",SUMIFS(D_sales!$S$5:$S$121,D_sales!$C$5:$C$121,A46)/SUMIFS(D_sales!$T$5:$T$121,D_sales!$C$5:$C$121,A46)) -> 2.4512708 | M46: =COUNTIFS(D_sales!$C$5:$C$121,A46,D_sales!$R$5:$R$121,1) -> 3 | N46: =IF(SUMIFS(D_sales!$T$5:$T$121,D_sales!$C$5:$C$121,A46)=0,"n.a.",SUMIFS(D_sales!$AA$5:$AA$121,D_sales!$C$5:$C$121,A46)/SUMIFS(D_sales!$T$5:$T$121,D_sales!$C$5:$C$121,A46)) -> 30 | O46: =IF(D_F01!$B$7-_xlfn.MINIFS(D_sales!$G$5:$G$121,D_sales!$C$5:$C$121,A46)+1<=60,"Mới",IF(AND(COUNTIF(D_sales!$C$5:$C$121,A46)>=12,3>=4),"Thường xuyên","Vãng lai")) -> Vãng lai
A47: BYR-F01-004 | B47: =D_F01!B44 -> Khách mới K4 | C47: =SUMIFS(D_sales!$N$5:$N$121,D_sales!$C$5:$C$121,A47) -> 604815984 | D47: =IF($B$8>0,C47/$B$8,0) -> 0.024274599 | E47: =C47/$B$5*$B$7 -> 1.5722477 | F47: =SUMIFS(D_sales!$N$5:$N$121,D_sales!$C$5:$C$121,A47,D_sales!$O$5:$O$121,">0") -> 274915745 | G47: =SUMIFS(D_sales!$N$5:$N$121,D_sales!$C$5:$C$121,A47,D_sales!$O$5:$O$121,">0",D_sales!$O$5:$O$121,"<=30") -> 274915745 | H47: =SUMIFS(D_sales!$N$5:$N$121,D_sales!$C$5:$C$121,A47,D_sales!$O$5:$O$121,">30",D_sales!$O$5:$O$121,"<=60") -> 0 | I47: =SUMIFS(D_sales!$N$5:$N$121,D_sales!$C$5:$C$121,A47,D_sales!$O$5:$O$121,">60",D_sales!$O$5:$O$121,"<=9999") -> 0 | J47: =_xlfn.MAXIFS(D_sales!$O$5:$O$121,D_sales!$C$5:$C$121,A47) -> 29 | K47: =IF(SUMIFS(D_sales!$T$5:$T$121,D_sales!$C$5:$C$121,A47)=0,"n.a.",SUMIFS(D_sales!$Z$5:$Z$121,D_sales!$C$5:$C$121,A47)/SUMIFS(D_sales!$T$5:$T$121,D_sales!$C$5:$C$121,A47)) -> n.a. | L47: =IF(SUMIFS(D_sales!$T$5:$T$121,D_sales!$C$5:$C$121,A47)=0,"n.a.",SUMIFS(D_sales!$S$5:$S$121,D_sales!$C$5:$C$121,A47)/SUMIFS(D_sales!$T$5:$T$121,D_sales!$C$5:$C$121,A47)) -> n.a. | M47: =COUNTIFS(D_sales!$C$5:$C$121,A47,D_sales!$R$5:$R$121,1) -> 0 | N47: =IF(SUMIFS(D_sales!$T$5:$T$121,D_sales!$C$5:$C$121,A47)=0,"n.a.",SUMIFS(D_sales!$AA$5:$AA$121,D_sales!$C$5:$C$121,A47)/SUMIFS(D_sales!$T$5:$T$121,D_sales!$C$5:$C$121,A47)) -> n.a. | O47: =IF(D_F01!$B$7-_xlfn.MINIFS(D_sales!$G$5:$G$121,D_sales!$C$5:$C$121,A47)+1<=60,"Mới",IF(AND(COUNTIF(D_sales!$C$5:$C$121,A47)>=12,2>=4),"Thường xuyên","Vãng lai")) -> Mới
A48: BYR-F01-008 | B48: =D_F01!B45 -> Cửa hàng nhỏ K8 | C48: =SUMIFS(D_sales!$N$5:$N$121,D_sales!$C$5:$C$121,A48) -> 82708587 | D48: =IF($B$8>0,C48/$B$8,0) -> 0.0033195514 | E48: =C48/$B$5*$B$7 -> 0.21500488 | F48: =SUMIFS(D_sales!$N$5:$N$121,D_sales!$C$5:$C$121,A48,D_sales!$O$5:$O$121,">0") -> 82708587 | G48: =SUMIFS(D_sales!$N$5:$N$121,D_sales!$C$5:$C$121,A48,D_sales!$O$5:$O$121,">0",D_sales!$O$5:$O$121,"<=30") -> 0 | H48: =SUMIFS(D_sales!$N$5:$N$121,D_sales!$C$5:$C$121,A48,D_sales!$O$5:$O$121,">30",D_sales!$O$5:$O$121,"<=60") -> 0 | I48: =SUMIFS(D_sales!$N$5:$N$121,D_sales!$C$5:$C$121,A48,D_sales!$O$5:$O$121,">60",D_sales!$O$5:$O$121,"<=9999") -> 82708587 | J48: =_xlfn.MAXIFS(D_sales!$O$5:$O$121,D_sales!$C$5:$C$121,A48) -> 92 | K48: =IF(SUMIFS(D_sales!$T$5:$T$121,D_sales!$C$5:$C$121,A48)=0,"n.a.",SUMIFS(D_sales!$Z$5:$Z$121,D_sales!$C$5:$C$121,A48)/SUMIFS(D_sales!$T$5:$T$121,D_sales!$C$5:$C$121,A48)) -> 0 | L48: =IF(SUMIFS(D_sales!$T$5:$T$121,D_sales!$C$5:$C$121,A48)=0,"n.a.",SUMIFS(D_sales!$S$5:$S$121,D_sales!$C$5:$C$121,A48)/SUMIFS(D_sales!$T$5:$T$121,D_sales!$C$5:$C$121,A48)) -> 0 | M48: =COUNTIFS(D_sales!$C$5:$C$121,A48,D_sales!$R$5:$R$121,1) -> 3 | N48: =IF(SUMIFS(D_sales!$T$5:$T$121,D_sales!$C$5:$C$121,A48)=0,"n.a.",SUMIFS(D_sales!$AA$5:$AA$121,D_sales!$C$5:$C$121,A48)/SUMIFS(D_sales!$T$5:$T$121,D_sales!$C$5:$C$121,A48)) -> 30 | O48: =IF(D_F01!$B$7-_xlfn.MINIFS(D_sales!$G$5:$G$121,D_sales!$C$5:$C$121,A48)+1<=60,"Mới",IF(AND(COUNTIF(D_sales!$C$5:$C$121,A48)>=12,2>=4),"Thường xuyên","Vãng lai")) -> Vãng lai
...

Sheet F01_UC2
A2: F01 Dự báo tiền từ 01/07 đến 29/09/2026
A4: Chỉ tiêu | B4: Giá trị | C4: Ý nghĩa
A5: Kịch bản | B5: =CHOOSE(D_F01!B19,"Base","Optimistic","Conservative","Stress7","Continuing") -> Base | C5: Một selector tại D_F01!B19
A6: Ngày đầu | B6: =D_F01!B7+1 -> 46204 | C6: AsOf+1
A7: Ngày cuối | B7: =D_F01!B7+7*D_F01!B18 -> 46294 | C7: H13=91 ngày; không phải N181
A8: Tiền đầu dự báo | B8: =D_F01!B11-D_F01!B12 -> 4401925973 | C8: Tiền khả dụng giả lập tại ngày chốt
A9: L – giới hạn dưới | B9: =D_F01!B15 -> 5.5645463e+09 | C9: Tiền < L: thiếu; không xét thiếu chỉ vì thấp hơn Z
A10: Z – mức tiền mục tiêu | B10: =D_F01!B16 -> 6.8559659e+09 | C10: Mức hồi sau điều chỉnh; không tự ghi thêm vào thu dự báo
A11: H – giới hạn trên | B11: =D_F01!B17 -> 9.4388051e+09 | C11: Tiền > H: thừa; tiền trong [L;H] tiếp tục theo dõi
A12: MinCash | B12: =MIN(G70:G160) -> 4140480437 | C12: Số dư cuối ngày thấp nhất
A13: Ngày MinCash | B13: =INDEX(A70:A160,MATCH(B12,G70:G160,0)) -> 46205 | C13: Nếu bằng nhau lấy ngày đầu
A14: PeakBuffer | B14: =MAX(H70:H160) -> 2.7154855e+09 | C14: Không cộng gap lặp qua ngày
A15: PeakZero | B15: =MAX(I70:I160) -> 0 | C15: Không cộng với PeakBuffer
A16: MinCum | B16: =MIN(0,MIN(D70:D160)) -> -261445536 | C16: Lũy kế thu trừ chi, chưa có Cash0
A17: NeedTarget | B17: =IF(COUNTIF(G70:G160,"<"&B9)>0,MAX(0,B10-B16),B8) -> 7.1174114e+09 | C17: Tiền đầu kỳ cần để nâng đáy lên Z khi có ngày dưới L; không thiếu thì giữ Cash0
A18: NeedZero | B18: =MAX(0,-B16) -> 261445536 | C18: Tổng tiền đầu kỳ cần để không âm
A19: Additional | B19: =MAX(0,B17-B8) -> 2.7154855e+09 | C19: NeedTarget trừ tiền đang có, chặn dưới 0
A20: Ngày đầu thiếu | B20: =IF(COUNTIF(G70:G160,"<"&B9)=0,"n.a.",_xlfn.MINIFS(A70:A160,G70:G160,"<"&B9)) -> 46204 | C20: Ngày đầu trong dự báo; xem M43 để biết thiếu đã có tại ngày chốt
A21: Ngày đầu âm | B21: =IF(COUNTIF(G70:G160,"<0")=0,"n.a.",_xlfn.MINIFS(A70:A160,G70:G160,"<0")) -> n.a. | C21: Tách riêng ngày đầu dưới dự trữ
A22: Cảnh báo toàn kỳ | B22: =CHOOSE(MAX(K70:K160)+1,"Không cảnh báo","Vàng","Cam","Đỏ") -> Đỏ | C22: Mức nặng nhất theo ngày của kịch bản đang chọn
A23: TH để định tuyến | B23: =IF(D_F01!B19<>1,"Chọn Base để định tuyến",IF(MIN(G70:G160)<B9,"TH01",IF(MAX(G70:G160)>B11,"TH02","Trong vùng L–H"))) -> TH01 | C23: Base: có ngày dưới L → TH01; nếu không thì có ngày trên H → TH02; còn lại trong vùng
A24: Ô ma trận | B24: =IF(OR(D_F01!B19<>1,B23="Trong vùng L–H"),"—","M"&(VALUE(RIGHT(F01_UC1!B30,1))*2+IF(B23="TH01",1,2))) -> M3 | C24: Ma trận M1–M6, 3 mức W × 2 trạng thái tiền; trong vùng không gán ô
A25: Trạng thái | B25: provisional | C25: Dữ liệu hư cấu, net/noVAT, lịch chi quá hạn là giả định
A26: Chế độ | B26: =D_F01!B20 -> run_off | C26: Run-off không có toàn bộ hoạt động mới; continuing có thêm cả thu và chi
A28: Tuần | B28: Ngày đầu | C28: Ngày cuối | D28: Thu | E28: Chi | F28: Cuối tuần | G28: Thấp nhất tuần | H28: Ngày thấp nhất | I28: Mức cuối tuần | J28: Mức xấu nhất | L28: Khối | M28: Ngày đầu | N28: Ngày cuối | O28: MinDaily | P28: Trạng thái | Q28: Mức xấu nhất | R28: Số ngày | S28: Giới hạn
A29: 1 | B29: =$B$6+0 -> 46204 | C29: =B29+6 -> 46210 | D29: =SUMIFS($B$70:$B$160,$A$70:$A$160,">="&B29,$A$70:$A$160,"<="&C29) -> 3251880497 | E29: =SUMIFS($C$70:$C$160,$A$70:$A$160,">="&B29,$A$70:$A$160,"<="&C29) -> 3138231714 | F29: =INDEX($G$70:$G$160,MATCH(C29,$A$70:$A$160,0)) -> 4515574756 | G29: =_xlfn.MINIFS($G$70:$G$160,$A$70:$A$160,">="&B29,$A$70:$A$160,"<="&C29) -> 4140480437 | H29: =_xlfn.MINIFS($A$70:$A$160,$A$70:$A$160,">="&B29,$A$70:$A$160,"<="&C29,$G$70:$G$160,G29) -> 46205 | I29: =INDEX($K$70:$K$160,MATCH(C29,$A$70:$A$160,0)) -> 3 | J29: =_xlfn.MAXIFS($K$70:$K$160,$A$70:$A$160,">="&B29,$A$70:$A$160,"<="&C29) -> 3 | L29: =1 -> 1 | M29: =$B$6+0 -> 46204 | N29: =MIN($B$7,M29+13) -> 46217 | O29: =_xlfn.MINIFS($G$70:$G$160,$A$70:$A$160,">="&M29,$A$70:$A$160,"<="&N29) -> 4140480437 | P29: =IF(O29<$B$9,"Thiếu",IF(O29>$B$11,"Thừa","Trong vùng L–H")) -> Thiếu | Q29: =_xlfn.MAXIFS($K$70:$K$160,$A$70:$A$160,">="&M29,$A$70:$A$160,"<="&N29) -> 3 | R29: =N29-M29+1 -> 14 | S29: =IF(R29=7,"Khối cuối 7 ngày","Khối 14 ngày") -> Khối 14 ngày
A30: 2 | B30: =$B$6+7 -> 46211 | C30: =B30+6 -> 46217 | D30: =SUMIFS($B$70:$B$160,$A$70:$A$160,">="&B30,$A$70:$A$160,"<="&C30) -> 7371181354 | E30: =SUMIFS($C$70:$C$160,$A$70:$A$160,">="&B30,$A$70:$A$160,"<="&C30) -> 830190311 | F30: =INDEX($G$70:$G$160,MATCH(C30,$A$70:$A$160,0)) -> 11056565799 | G30: =_xlfn.MINIFS($G$70:$G$160,$A$70:$A$160,">="&B30,$A$70:$A$160,"<="&C30) -> 5314587071 | H30: =_xlfn.MINIFS($A$70:$A$160,$A$70:$A$160,">="&B30,$A$70:$A$160,"<="&C30,$G$70:$G$160,G30) -> 46211 | I30: =INDEX($K$70:$K$160,MATCH(C30,$A$70:$A$160,0)) -> 0 | J30: =_xlfn.MAXIFS($K$70:$K$160,$A$70:$A$160,">="&B30,$A$70:$A$160,"<="&C30) -> 3 | L30: =2 -> 2 | M30: =$B$6+14 -> 46218 | N30: =MIN($B$7,M30+13) -> 46231 | O30: =_xlfn.MINIFS($G$70:$G$160,$A$70:$A$160,">="&M30,$A$70:$A$160,"<="&N30) -> 11150672753 | P30: =IF(O30<$B$9,"Thiếu",IF(O30>$B$11,"Thừa","Trong vùng L–H")) -> Thừa | Q30: =_xlfn.MAXIFS($K$70:$K$160,$A$70:$A$160,">="&M30,$A$70:$A$160,"<="&N30) -> 0 | R30: =N30-M30+1 -> 14 | S30: =IF(R30=7,"Khối cuối 7 ngày","Khối 14 ngày") -> Khối 14 ngày
A31: 3 | B31: =$B$6+14 -> 46218 | C31: =B31+6 -> 46224 | D31: =SUMIFS($B$70:$B$160,$A$70:$A$160,">="&B31,$A$70:$A$160,"<="&C31) -> 3653992400 | E31: =SUMIFS($C$70:$C$160,$A$70:$A$160,">="&B31,$A$70:$A$160,"<="&C31) -> 2302640567 | F31: =INDEX($G$70:$G$160,MATCH(C31,$A$70:$A$160,0)) -> 12407917632 | G31: =_xlfn.MINIFS($G$70:$G$160,$A$70:$A$160,">="&B31,$A$70:$A$160,"<="&C31) -> 11150672753 | H31: =_xlfn.MINIFS($A$70:$A$160,$A$70:$A$160,">="&B31,$A$70:$A$160,"<="&C31,$G$70:$G$160,G31) -> 46218 | I31: =INDEX($K$70:$K$160,MATCH(C31,$A$70:$A$160,0)) -> 0 | J31: =_xlfn.MAXIFS($K$70:$K$160,$A$70:$A$160,">="&B31,$A$70:$A$160,"<="&C31) -> 0 | L31: =3 -> 3 | M31: =$B$6+28 -> 46232 | N31: =MIN($B$7,M31+13) -> 46245 | O31: =_xlfn.MINIFS($G$70:$G$160,$A$70:$A$160,">="&M31,$A$70:$A$160,"<="&N31) -> 12461774647 | P31: =IF(O31<$B$9,"Thiếu",IF(O31>$B$11,"Thừa","Trong vùng L–H")) -> Thừa | Q31: =_xlfn.MAXIFS($K$70:$K$160,$A$70:$A$160,">="&M31,$A$70:$A$160,"<="&N31) -> 0 | R31: =N31-M31+1 -> 14 | S31: =IF(R31=7,"Khối cuối 7 ngày","Khối 14 ngày") -> Khối 14 ngày
A32: 4 | B32: =$B$6+21 -> 46225 | C32: =B32+6 -> 46231 | D32: =SUMIFS($B$70:$B$160,$A$70:$A$160,">="&B32,$A$70:$A$160,"<="&C32) -> 3339440235 | E32: =SUMIFS($C$70:$C$160,$A$70:$A$160,">="&B32,$A$70:$A$160,"<="&C32) -> 3225945927 | F32: =INDEX($G$70:$G$160,MATCH(C32,$A$70:$A$160,0)) -> 12521411940 | G32: =_xlfn.MINIFS($G$70:$G$160,$A$70:$A$160,">="&B32,$A$70:$A$160,"<="&C32) -> 11937730444 | H32: =_xlfn.MINIFS($A$70:$A$160,$A$70:$A$160,">="&B32,$A$70:$A$160,"<="&C32,$G$70:$G$160,G32) -> 46226 | I32: =INDEX($K$70:$K$160,MATCH(C32,$A$70:$A$160,0)) -> 0 | J32: =_xlfn.MAXIFS($K$70:$K$160,$A$70:$A$160,">="&B32,$A$70:$A$160,"<="&C32) -> 0 | L32: =4 -> 4 | M32: =$B$6+42 -> 46246 | N32: =MIN($B$7,M32+13) -> 46259 | O32: =_xlfn.MINIFS($G$70:$G$160,$A$70:$A$160,">="&M32,$A$70:$A$160,"<="&N32) -> 15514035449 | P32: =IF(O32<$B$9,"Thiếu",IF(O32>$B$11,"Thừa","Trong vùng L–H")) -> Thừa | Q32: =_xlfn.MAXIFS($K$70:$K$160,$A$70:$A$160,">="&M32,$A$70:$A$160,"<="&N32) -> 0 | R32: =N32-M32+1 -> 14 | S32: =IF(R32=7,"Khối cuối 7 ngày","Khối 14 ngày") -> Khối 14 ngày
